Workbook

Sheet 2.1meta
A1: CUADRO DE EJECUCION Y PROYECCIÓN DE GASTOS DE LA GG 2.1 - EJERCICIO 2021 AL 17 DE SETIEMBRE 2021
A2: UE: 003 G.A AREQUIPA
A4: Meta | B4: E.G. | C4: Descripción Específica Gasto | D4: PIM (1) | E4: Certificado | F4: Compromiso Anual | H4: Saldo Presupuestal al 17.09.2021 | I4: Proyección Planillas Activas | U4: Proyeccion de plazas vacantes | W4: PAGO FACTURAS EPS | X4: BENEFICIOS | Y4: TOTAL PROYECCIÓN | Z4: TOTAL EJECUCION +PROYECCION (2) | AA4: Saldo disponible ( 1-2)
G5: TOTAL EJECUCION | I5: Enero | J5: Febrero | K5: Marzo | L5: Abril | M5: Mayo | N5: Junio | O5: Julio | P5: Agosto | Q5: Setiembre | R5: Octubre | S5: Noviembre | T5: Diciembre | U5: 276 | V5: 728
A6: 0002 | D6: =SUBTOTAL(9,D7:D21) -> 0 | E6: =SUBTOTAL(9,E7:E21) -> 0 | F6: =SUBTOTAL(9,F7:F21) -> 0 | G6: 0 | H6: =D6-G6 -> 0 | I6: =SUBTOTAL(9,I7:I21) -> 0 | J6: =SUBTOTAL(9,J7:J21) -> 0 | K6: =SUBTOTAL(9,K7:K21) -> 0 | L6: =SUBTOTAL(9,L7:L21) -> 0 | M6: =SUBTOTAL(9,M7:M21) -> 0 | N6: =SUBTOTAL(9,N7:N21) -> 0 | O6: =SUBTOTAL(9,O7:O21) -> 0 | P6: =SUBTOTAL(9,P7:P21) -> 0 | ... X6: =SUBTOTAL(9,X7:X21) -> 0 | Y6: =SUM(I6:X6) -> 0 | Z6: =+G6+Y6 -> 0 | AA6: =+D6-Z6 -> 0
A7: 0002 | B7: 2.1.1.1.1.2 | C7: PERSONAL ADMINISTRATIVO NOMBRADO (REGIMEN PUBLICO) | G7: 0 | H7: =D7-G7 -> 0 | Y7: =SUM(I7:X7) -> 0 | Z7: =+G7+Y7 -> 0 | AA7: =+D7-Z7 -> 0
A8: 0002 | B8: 2.1.1.1.1.4 | C8: PERSONAL CON CONTRATO A PLAZO INDETERMINADO (REGIMEN | G8: 0 | H8: =D8-G8 -> 0 | Y8: =SUM(I8:X8) -> 0 | Z8: =+G8+Y8 -> 0 | AA8: =+D8-Z8 -> 0
A9: 0002 | B9: 2.1.1.1.1.5 | C9: PERSONAL CON CONTRATO A PLAZO FIJO (REGIMEN LABORAL | G9: 0 | H9: =D9-G9 -> 0 | Y9: =SUM(I9:X9) -> 0 | Z9: =+G9+Y9 -> 0 | AA9: =+D9-Z9 -> 0
A10: 0002 | B10: 2.1.1.1.2.1 | C10: ASIGNACION A FONDOS PARA PERSONAL | G10: 0 | H10: =D10-G10 -> 0 | Y10: =SUM(I10:X10) -> 0 | Z10: =+G10+Y10 -> 0 | AA10: =+D10-Z10 -> 0
A11: 0002 | B11: 2.1.1.4.1.1 | C11: PERSONAL NOMBRADO | G11: 0 | H11: =D11-G11 -> 0 | Y11: =SUM(I11:X11) -> 0 | Z11: =+G11+Y11 -> 0 | AA11: =+D11-Z11 -> 0
A12: 0002 | B12: 2.1.1.4.2.1 | C12: BONO POR FUNCION JURISDICCIONAL Y FISCAL | G12: 0 | H12: =D12-G12 -> 0 | Y12: =SUM(I12:X12) -> 0 | Z12: =+G12+Y12 -> 0 | AA12: =+D12-Z12 -> 0
A13: 0002 | B13: 2.1.1.4.2.2 | C13: ASIGNACION POR GASTOS OPERATIVOS | G13: 0 | H13: =D13-G13 -> 0 | Y13: =SUM(I13:X13) -> 0 | Z13: =+G13+Y13 -> 0 | AA13: =+D13-Z13 -> 0
A14: 0002 | B14: 2.1.1.9.1.1 | C14: GRATIFICACIONES | G14: 0 | H14: =D14-G14 -> 0 | Y14: =SUM(I14:X14) -> 0 | Z14: =+G14+Y14 -> 0 | AA14: =+D14-Z14 -> 0
A15: 0002 | B15: 2.1.1.9.1.2 | C15: AGUINALDOS | G15: 0 | H15: =D15-G15 -> 0 | Y15: =SUM(I15:X15) -> 0 | Z15: =+G15+Y15 -> 0 | AA15: =+D15-Z15 -> 0
A16: 0002 | B16: 2.1.1.9.1.3 | C16: BONIFICACION POR ESCOLARIDAD | G16: 0 | H16: =D16-G16 -> 0 | Y16: =SUM(I16:X16) -> 0 | Z16: =+G16+Y16 -> 0 | AA16: =+D16-Z16 -> 0
A17: 0002 | B17: 2.1.1.9.2.1 | C17: COMPENSACION POR TIEMPO DE SERVICIOS (CTS) | G17: 0 | H17: =D17-G17 -> 0 | Y17: =SUM(I17:X17) -> 0 | Z17: =+G17+Y17 -> 0 | AA17: =+D17-Z17 -> 0
A18: 0002 | B18: 2.1.1.9.3.99 | C18: OTRAS OCASIONALES | G18: 0 | H18: =D18-G18 -> 0 | Y18: =SUM(I18:X18) -> 0 | Z18: =+G18+Y18 -> 0 | AA18: =+D18-Z18 -> 0
... A21: 0002 | B21: 2.1.3.1.1.5 | C21: CONTRIBUCIONES A ESSALUD | G21: 0 | H21: =D21-G21 -> 0 | Y21: =SUM(I21:X21) -> 0 | Z21: =+G21+Y21 -> 0 | AA21: =+D21-Z21 -> 0
A22: 0003 | D22: =SUBTOTAL(9,D23:D38) -> 0 | E22: =SUBTOTAL(9,E23:E38) -> 0 | F22: =SUBTOTAL(9,F23:F38) -> 0 | G22: 0 | H22: =D22-G22 -> 0 | I22: =SUBTOTAL(9,I23:I38) -> 0 | J22: =SUBTOTAL(9,J23:J38) -> 0 | K22: =SUBTOTAL(9,K23:K38) -> 0 | L22: =SUBTOTAL(9,L23:L38) -> 0 | M22: =SUBTOTAL(9,M23:M38) -> 0 | N22: =SUBTOTAL(9,N23:N38) -> 0 | O22: =SUBTOTAL(9,O23:O38) -> 0 | P22: =SUBTOTAL(9,P23:P38) -> 0 | ... X22: =SUBTOTAL(9,X23:X38) -> 0 | Y22: =SUM(I22:X22) -> 0 | Z22: =+G22+Y22 -> 0 | AA22: =+D22-Z22 -> 0
A23: 0003 | B23: 2.1.1.1.1.2 | C23: PERSONAL ADMINISTRATIVO NOMBRADO (REGIMEN PUBLICO) | G23: 0 | H23: =D23-G23 -> 0 | Y23: =SUM(I23:X23) -> 0 | Z23: =+G23+Y23 -> 0 | AA23: =+D23-Z23 -> 0
A24: 0003 | B24: 2.1.1.1.1.4 | C24: PERSONAL CON CONTRATO A PLAZO INDETERMINADO (REGIMEN | G24: 0 | H24: =D24-G24 -> 0 | Y24: =SUM(I24:X24) -> 0 | Z24: =+G24+Y24 -> 0 | AA24: =+D24-Z24 -> 0
A25: 0003 | B25: 2.1.1.1.1.5 | C25: PERSONAL CON CONTRATO A PLAZO FIJO (REGIMEN LABORAL | G25: 0 | H25: =D25-G25 -> 0 | Y25: =SUM(I25:X25) -> 0 | Z25: =+G25+Y25 -> 0 | AA25: =+D25-Z25 -> 0
A26: 0003 | B26: 2.1.1.1.2.1 | C26: ASIGNACION A FONDOS PARA PERSONAL | G26: 0 | H26: =D26-G26 -> 0 | Y26: =SUM(I26:X26) -> 0 | Z26: =+G26+Y26 -> 0 | AA26: =+D26-Z26 -> 0
A27: 0003 | B27: 2.1.1.4.1.1 | C27: PERSONAL NOMBRADO | G27: 0 | H27: =D27-G27 -> 0 | Y27: =SUM(I27:X27) -> 0 | Z27: =+G27+Y27 -> 0 | AA27: =+D27-Z27 -> 0
A28: 0003 | B28: 2.1.1.4.2.1 | C28: BONO POR FUNCION JURISDICCIONAL Y FISCAL | G28: 0 | H28: =D28-G28 -> 0 | Y28: =SUM(I28:X28) -> 0 | Z28: =+G28+Y28 -> 0 | AA28: =+D28-Z28 -> 0
A29: 0003 | B29: 2.1.1.4.2.2 | C29: ASIGNACION POR GASTOS OPERATIVOS | G29: 0 | H29: =D29-G29 -> 0 | Y29: =SUM(I29:X29) -> 0 | Z29: =+G29+Y29 -> 0 | AA29: =+D29-Z29 -> 0
A30: 0003 | B30: 2.1.1.9.1.1 | C30: GRATIFICACIONES | G30: 0 | H30: =D30-G30 -> 0 | Y30: =SUM(I30:X30) -> 0 | Z30: =+G30+Y30 -> 0 | AA30: =+D30-Z30 -> 0
A31: 0003 | B31: 2.1.1.9.1.2 | C31: AGUINALDOS | G31: 0 | H31: =D31-G31 -> 0 | Y31: =SUM(I31:X31) -> 0 | Z31: =+G31+Y31 -> 0 | AA31: =+D31-Z31 -> 0
A32: 0003 | B32: 2.1.1.9.1.3 | C32: BONIFICACION POR ESCOLARIDAD | G32: 0 | H32: =D32-G32 -> 0 | Y32: =SUM(I32:X32) -> 0 | Z32: =+G32+Y32 -> 0 | AA32: =+D32-Z32 -> 0
A33: 0003 | B33: 2.1.1.9.2.1 | C33: COMPENSACION POR TIEMPO DE SERVICIOS (CTS) | G33: 0 | H33: =D33-G33 -> 0 | Y33: =SUM(I33:X33) -> 0 | Z33: =+G33+Y33 -> 0 | AA33: =+D33-Z33 -> 0
A34: 0003 | B34: 2.1.1.9.3.3 | C34: COMPENSACION VACACIONAL (VACACIONES TRUNCAS) | G34: 0 | H34: =D34-G34 -> 0 | Y34: =SUM(I34:X34) -> 0 | Z34: =+G34+Y34 -> 0 | AA34: =+D34-Z34 -> 0
... A38: 0003 | B38: 2.1.3.1.1.5 | C38: CONTRIBUCIONES A ESSALUD | G38: 0 | H38: =D38-G38 -> 0 | Y38: =SUM(I38:X38) -> 0 | Z38: =+G38+Y38 -> 0 | AA38: =+D38-Z38 -> 0
A39: 0004 | D39: =SUBTOTAL(9,D40:D48) -> 0 | E39: =SUBTOTAL(9,E40:E48) -> 0 | F39: =SUBTOTAL(9,F40:F48) -> 0 | G39: 0 | H39: =D39-G39 -> 0 | I39: =SUBTOTAL(9,I40:I48) -> 0 | J39: =SUBTOTAL(9,J40:J48) -> 0 | K39: =SUBTOTAL(9,K40:K48) -> 0 | L39: =SUBTOTAL(9,L40:L48) -> 0 | M39: =SUBTOTAL(9,M40:M48) -> 0 | N39: =SUBTOTAL(9,N40:N48) -> 0 | O39: =SUBTOTAL(9,O40:O48) -> 0 | P39: =SUBTOTAL(9,P40:P48) -> 0 | ... X39: =SUBTOTAL(9,X40:X48) -> 0 | Y39: =SUM(I39:X39) -> 0 | Z39: =+G39+Y39 -> 0 | AA39: =+D39-Z39 -> 0
A40: 0004 | B40: 2.1.1.1.1.4 | C40: PERSONAL CON CONTRATO A PLAZO INDETERMINADO (REGIMEN | G40: 0 | H40: =D40-G40 -> 0 | Y40: =SUM(I40:X40) -> 0 | Z40: =+G40+Y40 -> 0 | AA40: =+D40-Z40 -> 0
A41: 0004 | B41: 2.1.1.1.1.5 | C41: PERSONAL CON CONTRATO A PLAZO FIJO (REGIMEN LABORAL | G41: 0 | H41: =D41-G41 -> 0 | Y41: =SUM(I41:X41) -> 0 | Z41: =+G41+Y41 -> 0 | AA41: =+D41-Z41 -> 0
A42: 0004 | B42: 2.1.1.3.1.2 | C42: PERSONAL CONTRATADO | G42: 0 | H42: =D42-G42 -> 0 | Y42: =SUM(I42:X42) -> 0 | Z42: =+G42+Y42 -> 0 | AA42: =+D42-Z42 -> 0
A43: 0004 | B43: 2.1.1.9.1.1 | C43: GRATIFICACIONES | G43: 0 | H43: =D43-G43 -> 0 | Y43: =SUM(I43:X43) -> 0 | Z43: =+G43+Y43 -> 0 | AA43: =+D43-Z43 -> 0
A44: 0004 | B44: 2.1.1.9.1.3 | C44: BONIFICACION POR ESCOLARIDAD | G44: 0 | H44: =D44-G44 -> 0 | Y44: =SUM(I44:X44) -> 0 | Z44: =+G44+Y44 -> 0 | AA44: =+D44-Z44 -> 0
A45: 0004 | B45: 2.1.1.9.2.1 | C45: COMPENSACION POR TIEMPO DE SERVICIOS (CTS) | G45: 0 | H45: =D45-G45 -> 0 | Y45: =SUM(I45:X45) -> 0 | Z45: =+G45+Y45 -> 0 | AA45: =+D45-Z45 -> 0
A46: 0004 | B46: 2.1.1.9.3.99 | C46: OTRAS OCASIONALES | G46: 0 | H46: =D46-G46 -> 0 | Y46: =SUM(I46:X46) -> 0 | Z46: =+G46+Y46 -> 0 | AA46: =+D46-Z46 -> 0
...

Sheet CATEGORIA PRESUPUESTAL
A1: EJECUTORA: 0003 MINISTERIO PUBLICO - GERENCIA ADMINISTRATIVA DE AREQUIPA (1419)
A3: Cat pptal/ Detalle Específica de Gasto | C3: PIM | D3: Certificado | E3: Compromiso Anual | F3: T O T A L | G3: Saldo Presupuestal al 17.09.2021 | H3: Proyección Planillas Activa | T3: Proyeccion de plazas vacantes | V3: PAGO FACTURAS EPS | W3: BENEFICIOS | X3: TOTAL PROYECCION | Y3: TOTAL EJECUCION +PROYECCION | Z3: SALDO DISPONIBLE
H4: 01 ENERO | I4: 02 FEBRERO | J4: 03 MARZO | K4: 04 ABRIL | L4: 05 MAYO | M4: 06 JUNIO | N4: 07 JULIO | O4: 08 AGOSTO | P4: 09 SETIEMBRE | Q4: 10 OCTUBRE | R4: 11 OCTUBRE | S4: 12 OCTUBRE | T4: 276 | U4: 728
A5: 0086 MEJORA DE LOS SERVICIOS DEL SISTEMA DE JUSTICIA PENAL | C5: =SUBTOTAL(9,C6:C22) -> 0 | D5: =SUBTOTAL(9,D6:D22) -> 0 | E5: =SUBTOTAL(9,E6:E22) -> 0 | F5: =SUBTOTAL(9,F6:F22) -> 0 | G5: =C5-F5 -> 0 | H5: =SUBTOTAL(9,H6:H22) -> 0 | I5: =SUBTOTAL(9,I6:I22) -> 0 | J5: =SUBTOTAL(9,J6:J22) -> 0 | K5: =SUBTOTAL(9,K6:K22) -> 0 | L5: =SUBTOTAL(9,L6:L22) -> 0 | M5: =SUBTOTAL(9,M6:M22) -> 0 | N5: =SUBTOTAL(9,N6:N22) -> 0 | O5: =SUBTOTAL(9,O6:O22) -> 0 | ... Z5: =SUBTOTAL(9,Z6:Z22) -> 0
A6: 2.1.1.1.1.2 | B6: PERSONAL ADMINISTRATIVO NOMBRADO (REGIMEN PUBLICO) | C6: ='2.1meta'!D7+'2.1meta'!D23 -> 0 | D6: ='2.1meta'!E7+'2.1meta'!E23 -> 0 | E6: ='2.1meta'!F7+'2.1meta'!F23 -> 0 | F6: 0 | G6: =C6-F6 -> 0 | H6: ='2.1meta'!I7+'2.1meta'!I23 -> 0 | I6: ='2.1meta'!J7+'2.1meta'!J23 -> 0 | J6: ='2.1meta'!K7+'2.1meta'!K23 -> 0 | K6: ='2.1meta'!L7+'2.1meta'!L23 -> 0 | L6: ='2.1meta'!M7+'2.1meta'!M23 -> 0 | M6: ='2.1meta'!N7+'2.1meta'!N23 -> 0 | N6: ='2.1meta'!O7+'2.1meta'!O23 -> 0 | O6: ='2.1meta'!P7+'2.1meta'!P23 -> 0 | ... W6: ='2.1meta'!X7+'2.1meta'!X23 -> 0 | X6: =SUM(H6:W6) -> 0 | Y6: =F6+X6 -> 0 | Z6: =C6-Y6 -> 0
A7: 2.1.1.1.1.4 | B7: PERSONAL CON CONTRATO A PLAZO INDETERMINADO (REGIMEN LABORAL PRIVADO) | C7: ='2.1meta'!D8+'2.1meta'!D24+'2.1meta'!D40+'2.1meta'!D79+'2.1meta'!D92+'2.1meta'!D104+'2.1meta'!D145 -> 0 | D7: ='2.1meta'!E8+'2.1meta'!E24+'2.1meta'!E40+'2.1meta'!E79+'2.1meta'!E92+'2.1meta'!E104+'2.1meta'!E145 -> 0 | E7: ='2.1meta'!F8+'2.1meta'!F24+'2.1meta'!F40+'2.1meta'!F79+'2.1meta'!F92+'2.1meta'!F104+'2.1meta'!F145 -> 0 | F7: 0 | G7: =C7-F7 -> 0 | H7: ='2.1meta'!I8+'2.1meta'!I24+'2.1meta'!I40+'2.1meta'!I79+'2.1meta'!I92+'2.1meta'!I104+'2.1meta'!I145 -> 0 | I7: ='2.1meta'!J8+'2.1meta'!J24+'2.1meta'!J40+'2.1meta'!J79+'2.1meta'!J92+'2.1meta'!J104+'2.1meta'!J145 -> 0 | J7: ='2.1meta'!K8+'2.1meta'!K24+'2.1meta'!K40+'2.1meta'!K79+'2.1meta'!K92+'2.1meta'!K104+'2.1meta'!K145 -> 0 | K7: ='2.1meta'!L8+'2.1meta'!L24+'2.1meta'!L40+'2.1meta'!L79+'2.1meta'!L92+'2.1meta'!L104+'2.1meta'!L145 -> 0 | L7: ='2.1meta'!M8+'2.1meta'!M24+'2.1meta'!M40+'2.1meta'!M79+'2.1meta'!M92+'2.1meta'!M104+'2.1meta'!M145 -> 0 | M7: ='2.1meta'!N8+'2.1meta'!N24+'2.1meta'!N40+'2.1meta'!N79+'2.1meta'!N92+'2.1meta'!N104+'2.1meta'!N145 -> 0 | N7: ='2.1meta'!O8+'2.1meta'!O24+'2.1meta'!O40+'2.1meta'!O79+'2.1meta'!O92+'2.1meta'!O104+'2.1meta'!O145 -> 0 | O7: ='2.1meta'!P8+'2.1meta'!P24+'2.1meta'!P40+'2.1meta'!P79+'2.1meta'!P92+'2.1meta'!P104+'2.1meta'!P145 -> 0 | ... W7: ='2.1meta'!X8+'2.1meta'!X24+'2.1meta'!X40+'2.1meta'!X79+'2.1meta'!X92+'2.1meta'!X104+'2.1meta'!X145 -> 0 | X7: =SUM(H7:W7) -> 0 | Y7: =F7+X7 -> 0 | Z7: =C7-Y7 -> 0
A8: 2.1.1.1.1.5 | B8: PERSONAL CON CONTRATO A PLAZO FIJO (REGIMEN LABORAL PRIVADO) | C8: ='2.1meta'!D9+'2.1meta'!D25+'2.1meta'!D41+'2.1meta'!D93 -> 0 | D8: ='2.1meta'!E9+'2.1meta'!E25+'2.1meta'!E41+'2.1meta'!E93 -> 0 | E8: ='2.1meta'!F9+'2.1meta'!F25+'2.1meta'!F41+'2.1meta'!F93 -> 0 | F8: 0 | G8: =C8-F8 -> 0 | H8: ='2.1meta'!I9+'2.1meta'!I25+'2.1meta'!I41+'2.1meta'!I93 -> 0 | I8: ='2.1meta'!J9+'2.1meta'!J25+'2.1meta'!J41+'2.1meta'!J93 -> 0 | J8: ='2.1meta'!K9+'2.1meta'!K25+'2.1meta'!K41+'2.1meta'!K93 -> 0 | K8: ='2.1meta'!L9+'2.1meta'!L25+'2.1meta'!L41+'2.1meta'!L93 -> 0 | L8: ='2.1meta'!M9+'2.1meta'!M25+'2.1meta'!M41+'2.1meta'!M93 -> 0 | M8: ='2.1meta'!N9+'2.1meta'!N25+'2.1meta'!N41+'2.1meta'!N93 -> 0 | N8: ='2.1meta'!O9+'2.1meta'!O25+'2.1meta'!O41+'2.1meta'!O93 -> 0 | O8: ='2.1meta'!P9+'2.1meta'!P25+'2.1meta'!P41+'2.1meta'!P93 -> 0 | ... W8: ='2.1meta'!X9+'2.1meta'!X25+'2.1meta'!X41+'2.1meta'!X93 -> 0 | X8: =SUM(H8:W8) -> 0 | Y8: =F8+X8 -> 0 | Z8: =C8-Y8 -> 0
A9: 2.1.1.1.2.1 | B9: ASIGNACION A FONDOS PARA PERSONAL | C9: ='2.1meta'!D10+'2.1meta'!D26 -> 0 | D9: ='2.1meta'!E10+'2.1meta'!E26 -> 0 | E9: ='2.1meta'!F10+'2.1meta'!F26 -> 0 | F9: 0 | G9: =C9-F9 -> 0 | H9: ='2.1meta'!I10+'2.1meta'!I26 -> 0 | I9: ='2.1meta'!J10+'2.1meta'!J26 -> 0 | J9: ='2.1meta'!K10+'2.1meta'!K26 -> 0 | K9: ='2.1meta'!L10+'2.1meta'!L26 -> 0 | L9: ='2.1meta'!M10+'2.1meta'!M26 -> 0 | M9: ='2.1meta'!N10+'2.1meta'!N26 -> 0 | N9: ='2.1meta'!O10+'2.1meta'!O26 -> 0 | O9: ='2.1meta'!P10+'2.1meta'!P26 -> 0 | ... W9: ='2.1meta'!X10+'2.1meta'!X26 -> 0 | X9: =SUM(H9:W9) -> 0 | Y9: =F9+X9 -> 0 | Z9: =C9-Y9 -> 0
A10: 2.1.1.3.1.2 | B10: PERSONAL CONTRATADO | C10: ='2.1meta'!D42 -> 0 | D10: ='2.1meta'!E42 -> 0 | E10: ='2.1meta'!F42 -> 0 | F10: 0 | G10: =C10-F10 -> 0 | H10: ='2.1meta'!I42 -> 0 | I10: ='2.1meta'!J42 -> 0 | J10: ='2.1meta'!K42 -> 0 | K10: ='2.1meta'!L42 -> 0 | L10: ='2.1meta'!M42 -> 0 | M10: ='2.1meta'!N42 -> 0 | N10: ='2.1meta'!O42 -> 0 | O10: ='2.1meta'!P42 -> 0 | ... W10: ='2.1meta'!X42 -> 0 | X10: =SUM(H10:W10) -> 0 | Y10: =F10+X10 -> 0 | Z10: =C10-Y10 -> 0
A11: 2.1.1.4.1.1 | B11: PERSONAL NOMBRADO | C11: ='2.1meta'!D11+'2.1meta'!D27+'2.1meta'!D80+'2.1meta'!D94+'2.1meta'!D105+'2.1meta'!D115+'2.1meta'!D122+'2.1meta'!D146 -> 0 | D11: ='2.1meta'!E11+'2.1meta'!E27+'2.1meta'!E80+'2.1meta'!E94+'2.1meta'!E105+'2.1meta'!E115+'2.1meta'!E122+'2.1meta'!E146 -> 0 | E11: ='2.1meta'!F11+'2.1meta'!F27+'2.1meta'!F80+'2.1meta'!F94+'2.1meta'!F105+'2.1meta'!F115+'2.1meta'!F122+'2.1meta'!F146 -> 0 | F11: 0 | G11: =C11-F11 -> 0 | H11: ='2.1meta'!I11+'2.1meta'!I27+'2.1meta'!I80+'2.1meta'!I94+'2.1meta'!I105+'2.1meta'!I115+'2.1meta'!I122+'2.1meta'!I146 -> 0 | I11: ='2.1meta'!J11+'2.1meta'!J27+'2.1meta'!J80+'2.1meta'!J94+'2.1meta'!J105+'2.1meta'!J115+'2.1meta'!J122+'2.1meta'!J146 -> 0 | J11: ='2.1meta'!K11+'2.1meta'!K27+'2.1meta'!K80+'2.1meta'!K94+'2.1meta'!K105+'2.1meta'!K115+'2.1meta'!K122+'2.1meta'!K146 -> 0 | K11: ='2.1meta'!L11+'2.1meta'!L27+'2.1meta'!L80+'2.1meta'!L94+'2.1meta'!L105+'2.1meta'!L115+'2.1meta'!L122+'2.1meta'!L146 -> 0 | L11: ='2.1meta'!M11+'2.1meta'!M27+'2.1meta'!M80+'2.1meta'!M94+'2.1meta'!M105+'2.1meta'!M115+'2.1meta'!M122+'2.1meta'!M146 -> 0 | M11: ='2.1meta'!N11+'2.1meta'!N27+'2.1meta'!N80+'2.1meta'!N94+'2.1meta'!N105+'2.1meta'!N115+'2.1meta'!N122+'2.1meta'!N146 -> 0 | N11: ='2.1meta'!O11+'2.1meta'!O27+'2.1meta'!O80+'2.1meta'!O94+'2.1meta'!O105+'2.1meta'!O115+'2.1meta'!O122+'2.1meta'!O146 -> 0 | O11: ='2.1meta'!P11+'2.1meta'!P27+'2.1meta'!P80+'2.1meta'!P94+'2.1meta'!P105+'2.1meta'!P115+'2.1meta'!P122+'2.1meta'!P146 -> 0 | ... W11: ='2.1meta'!X11+'2.1meta'!X27+'2.1meta'!X80+'2.1meta'!X94+'2.1meta'!X105+'2.1meta'!X115+'2.1meta'!X122+'2.1meta'!X146 -> 0 | X11: =SUM(H11:W11) -> 0 | Y11: =F11+X11 -> 0 | Z11: =C11-Y11 -> 0
A12: 2.1.1.4.2.1 | B12: BONO POR FUNCION JURISDICCIONAL Y FISCAL | C12: ='2.1meta'!D12+'2.1meta'!D28+'2.1meta'!D81+'2.1meta'!D95+'2.1meta'!D106+'2.1meta'!D116+'2.1meta'!D123+'2.1meta'!D147 -> 0 | D12: ='2.1meta'!E12+'2.1meta'!E28+'2.1meta'!E81+'2.1meta'!E95+'2.1meta'!E106+'2.1meta'!E116+'2.1meta'!E123+'2.1meta'!E147 -> 0 | E12: ='2.1meta'!F12+'2.1meta'!F28+'2.1meta'!F81+'2.1meta'!F95+'2.1meta'!F106+'2.1meta'!F116+'2.1meta'!F123+'2.1meta'!F147 -> 0 | F12: 0 | G12: =C12-F12 -> 0 | H12: ='2.1meta'!I12+'2.1meta'!I28+'2.1meta'!I81+'2.1meta'!I95+'2.1meta'!I106+'2.1meta'!I116+'2.1meta'!I123+'2.1meta'!I147 -> 0 | I12: ='2.1meta'!J12+'2.1meta'!J28+'2.1meta'!J81+'2.1meta'!J95+'2.1meta'!J106+'2.1meta'!J116+'2.1meta'!J123+'2.1meta'!J147 -> 0 | J12: ='2.1meta'!K12+'2.1meta'!K28+'2.1meta'!K81+'2.1meta'!K95+'2.1meta'!K106+'2.1meta'!K116+'2.1meta'!K123+'2.1meta'!K147 -> 0 | K12: ='2.1meta'!L12+'2.1meta'!L28+'2.1meta'!L81+'2.1meta'!L95+'2.1meta'!L106+'2.1meta'!L116+'2.1meta'!L123+'2.1meta'!L147 -> 0 | L12: ='2.1meta'!M12+'2.1meta'!M28+'2.1meta'!M81+'2.1meta'!M95+'2.1meta'!M106+'2.1meta'!M116+'2.1meta'!M123+'2.1meta'!M147 -> 0 | M12: ='2.1meta'!N12+'2.1meta'!N28+'2.1meta'!N81+'2.1meta'!N95+'2.1meta'!N106+'2.1meta'!N116+'2.1meta'!N123+'2.1meta'!N147 -> 0 | N12: ='2.1meta'!O12+'2.1meta'!O28+'2.1meta'!O81+'2.1meta'!O95+'2.1meta'!O106+'2.1meta'!O116+'2.1meta'!O123+'2.1meta'!O147 -> 0 | O12: ='2.1meta'!P12+'2.1meta'!P28+'2.1meta'!P81+'2.1meta'!P95+'2.1meta'!P106+'2.1meta'!P116+'2.1meta'!P123+'2.1meta'!P147 -> 0 | ... W12: ='2.1meta'!X12+'2.1meta'!X28+'2.1meta'!X81+'2.1meta'!X95+'2.1meta'!X106+'2.1meta'!X116+'2.1meta'!X123+'2.1meta'!X147 -> 0 | X12: =SUM(H12:W12) -> 0 | Y12: =F12+X12 -> 0 | Z12: =C12-Y12 -> 0
A13: 2.1.1.4.2.2 | B13: ASIGNACION POR GASTOS OPERATIVOS | C13: ='2.1meta'!D13+'2.1meta'!D29+'2.1meta'!D82+'2.1meta'!D96+'2.1meta'!D107+'2.1meta'!D117+'2.1meta'!D124+'2.1meta'!D148 -> 0 | D13: ='2.1meta'!E13+'2.1meta'!E29+'2.1meta'!E82+'2.1meta'!E96+'2.1meta'!E107+'2.1meta'!E117+'2.1meta'!E124+'2.1meta'!E148 -> 0 | E13: ='2.1meta'!F13+'2.1meta'!F29+'2.1meta'!F82+'2.1meta'!F96+'2.1meta'!F107+'2.1meta'!F117+'2.1meta'!F124+'2.1meta'!F148 -> 0 | F13: 0 | G13: =C13-F13 -> 0 | H13: ='2.1meta'!I13+'2.1meta'!I29+'2.1meta'!I82+'2.1meta'!I96+'2.1meta'!I107+'2.1meta'!I117+'2.1meta'!I124+'2.1meta'!I148 -> 0 | I13: ='2.1meta'!J13+'2.1meta'!J29+'2.1meta'!J82+'2.1meta'!J96+'2.1meta'!J107+'2.1meta'!J117+'2.1meta'!J124+'2.1meta'!J148 -> 0 | J13: ='2.1meta'!K13+'2.1meta'!K29+'2.1meta'!K82+'2.1meta'!K96+'2.1meta'!K107+'2.1meta'!K117+'2.1meta'!K124+'2.1meta'!K148 -> 0 | K13: ='2.1meta'!L13+'2.1meta'!L29+'2.1meta'!L82+'2.1meta'!L96+'2.1meta'!L107+'2.1meta'!L117+'2.1meta'!L124+'2.1meta'!L148 -> 0 | L13: ='2.1meta'!M13+'2.1meta'!M29+'2.1meta'!M82+'2.1meta'!M96+'2.1meta'!M107+'2.1meta'!M117+'2.1meta'!M124+'2.1meta'!M148 -> 0 | M13: ='2.1meta'!N13+'2.1meta'!N29+'2.1meta'!N82+'2.1meta'!N96+'2.1meta'!N107+'2.1meta'!N117+'2.1meta'!N124+'2.1meta'!N148 -> 0 | N13: ='2.1meta'!O13+'2.1meta'!O29+'2.1meta'!O82+'2.1meta'!O96+'2.1meta'!O107+'2.1meta'!O117+'2.1meta'!O124+'2.1meta'!O148 -> 0 | O13: ='2.1meta'!P13+'2.1meta'!P29+'2.1meta'!P82+'2.1meta'!P96+'2.1meta'!P107+'2.1meta'!P117+'2.1meta'!P124+'2.1meta'!P148 -> 0 | ... W13: ='2.1meta'!X13+'2.1meta'!X29+'2.1meta'!X82+'2.1meta'!X96+'2.1meta'!X107+'2.1meta'!X117+'2.1meta'!X124+'2.1meta'!X148 -> 0 | X13: =SUM(H13:W13) -> 0 | Y13: =F13+X13 -> 0 | Z13: =C13-Y13 -> 0
A14: 2.1.1.9.1.1 | B14: GRATIFICACIONES | C14: ='2.1meta'!D14+'2.1meta'!D30+'2.1meta'!D43+'2.1meta'!D83+'2.1meta'!D97+'2.1meta'!D108+'2.1meta'!D149 -> 0 | D14: ='2.1meta'!E14+'2.1meta'!E30+'2.1meta'!E43+'2.1meta'!E83+'2.1meta'!E97+'2.1meta'!E108+'2.1meta'!E149 -> 0 | E14: ='2.1meta'!F14+'2.1meta'!F30+'2.1meta'!F43+'2.1meta'!F83+'2.1meta'!F97+'2.1meta'!F108+'2.1meta'!F149 -> 0 | F14: 0 | G14: =C14-F14 -> 0 | H14: ='2.1meta'!I14+'2.1meta'!I30+'2.1meta'!I43+'2.1meta'!I83+'2.1meta'!I97+'2.1meta'!I108+'2.1meta'!I149 -> 0 | I14: ='2.1meta'!J14+'2.1meta'!J30+'2.1meta'!J43+'2.1meta'!J83+'2.1meta'!J97+'2.1meta'!J108+'2.1meta'!J149 -> 0 | J14: ='2.1meta'!K14+'2.1meta'!K30+'2.1meta'!K43+'2.1meta'!K83+'2.1meta'!K97+'2.1meta'!K108+'2.1meta'!K149 -> 0 | K14: ='2.1meta'!L14+'2.1meta'!L30+'2.1meta'!L43+'2.1meta'!L83+'2.1meta'!L97+'2.1meta'!L108+'2.1meta'!L149 -> 0 | L14: ='2.1meta'!M14+'2.1meta'!M30+'2.1meta'!M43+'2.1meta'!M83+'2.1meta'!M97+'2.1meta'!M108+'2.1meta'!M149 -> 0 | M14: ='2.1meta'!N14+'2.1meta'!N30+'2.1meta'!N43+'2.1meta'!N83+'2.1meta'!N97+'2.1meta'!N108+'2.1meta'!N149 -> 0 | N14: ='2.1meta'!O14+'2.1meta'!O30+'2.1meta'!O43+'2.1meta'!O83+'2.1meta'!O97+'2.1meta'!O108+'2.1meta'!O149 -> 0 | O14: ='2.1meta'!P14+'2.1meta'!P30+'2.1meta'!P43+'2.1meta'!P83+'2.1meta'!P97+'2.1meta'!P108+'2.1meta'!P149 -> 0 | ... W14: ='2.1meta'!X14+'2.1meta'!X30+'2.1meta'!X43+'2.1meta'!X83+'2.1meta'!X97+'2.1meta'!X108+'2.1meta'!X149 -> 0 | X14: =SUM(H14:W14) -> 0 | Y14: =F14+X14 -> 0 | Z14: =C14-Y14 -> 0
A15: 2.1.1.9.1.2 | B15: AGUINALDOS | C15: ='2.1meta'!D15+'2.1meta'!D31+'2.1meta'!D84+'2.1meta'!D98+'2.1meta'!D109+'2.1meta'!D118+'2.1meta'!D125+'2.1meta'!D150 -> 0 | D15: ='2.1meta'!E15+'2.1meta'!E31+'2.1meta'!E84+'2.1meta'!E98+'2.1meta'!E109+'2.1meta'!E118+'2.1meta'!E125+'2.1meta'!E150 -> 0 | E15: ='2.1meta'!F15+'2.1meta'!F31+'2.1meta'!F84+'2.1meta'!F98+'2.1meta'!F109+'2.1meta'!F118+'2.1meta'!F125+'2.1meta'!F150 -> 0 | F15: 0 | G15: =C15-F15 -> 0 | H15: ='2.1meta'!I15+'2.1meta'!I31+'2.1meta'!I84+'2.1meta'!I98+'2.1meta'!I109+'2.1meta'!I118+'2.1meta'!I125+'2.1meta'!I150 -> 0 | I15: ='2.1meta'!J15+'2.1meta'!J31+'2.1meta'!J84+'2.1meta'!J98+'2.1meta'!J109+'2.1meta'!J118+'2.1meta'!J125+'2.1meta'!J150 -> 0 | J15: ='2.1meta'!K15+'2.1meta'!K31+'2.1meta'!K84+'2.1meta'!K98+'2.1meta'!K109+'2.1meta'!K118+'2.1meta'!K125+'2.1meta'!K150 -> 0 | K15: ='2.1meta'!L15+'2.1meta'!L31+'2.1meta'!L84+'2.1meta'!L98+'2.1meta'!L109+'2.1meta'!L118+'2.1meta'!L125+'2.1meta'!L150 -> 0 | L15: ='2.1meta'!M15+'2.1meta'!M31+'2.1meta'!M84+'2.1meta'!M98+'2.1meta'!M109+'2.1meta'!M118+'2.1meta'!M125+'2.1meta'!M150 -> 0 | M15: ='2.1meta'!N15+'2.1meta'!N31+'2.1meta'!N84+'2.1meta'!N98+'2.1meta'!N109+'2.1meta'!N118+'2.1meta'!N125+'2.1meta'!N150 -> 0 | N15: ='2.1meta'!O15+'2.1meta'!O31+'2.1meta'!O84+'2.1meta'!O98+'2.1meta'!O109+'2.1meta'!O118+'2.1meta'!O125+'2.1meta'!O150 -> 0 | O15: ='2.1meta'!P15+'2.1meta'!P31+'2.1meta'!P84+'2.1meta'!P98+'2.1meta'!P109+'2.1meta'!P118+'2.1meta'!P125+'2.1meta'!P150 -> 0 | ... W15: ='2.1meta'!X15+'2.1meta'!X31+'2.1meta'!X84+'2.1meta'!X98+'2.1meta'!X109+'2.1meta'!X118+'2.1meta'!X125+'2.1meta'!X150 -> 0 | X15: =SUM(H15:W15) -> 0 | Y15: =F15+X15 -> 0 | Z15: =C15-Y15 -> 0
A16: 2.1.1.9.1.3 | B16: BONIFICACION POR ESCOLARIDAD | C16: ='2.1meta'!D16+'2.1meta'!D32+'2.1meta'!D44+'2.1meta'!D85+'2.1meta'!D99+'2.1meta'!D110+'2.1meta'!D119+'2.1meta'!D126+'2.1meta'!D151 -> 0 | D16: ='2.1meta'!E16+'2.1meta'!E32+'2.1meta'!E44+'2.1meta'!E85+'2.1meta'!E99+'2.1meta'!E110+'2.1meta'!E119+'2.1meta'!E126+'2.1meta'!E151 -> 0 | E16: ='2.1meta'!F16+'2.1meta'!F32+'2.1meta'!F44+'2.1meta'!F85+'2.1meta'!F99+'2.1meta'!F110+'2.1meta'!F119+'2.1meta'!F126+'2.1meta'!F151 -> 0 | F16: 0 | G16: =C16-F16 -> 0 | H16: ='2.1meta'!I16+'2.1meta'!I32+'2.1meta'!I44+'2.1meta'!I85+'2.1meta'!I99+'2.1meta'!I110+'2.1meta'!I119+'2.1meta'!I126+'2.1meta'!I151 -> 0 | I16: ='2.1meta'!J16+'2.1meta'!J32+'2.1meta'!J44+'2.1meta'!J85+'2.1meta'!J99+'2.1meta'!J110+'2.1meta'!J119+'2.1meta'!J126+'2.1meta'!J151 -> 0 | J16: ='2.1meta'!K16+'2.1meta'!K32+'2.1meta'!K44+'2.1meta'!K85+'2.1meta'!K99+'2.1meta'!K110+'2.1meta'!K119+'2.1meta'!K126+'2.1meta'!K151 -> 0 | K16: ='2.1meta'!L16+'2.1meta'!L32+'2.1meta'!L44+'2.1meta'!L85+'2.1meta'!L99+'2.1meta'!L110+'2.1meta'!L119+'2.1meta'!L126+'2.1meta'!L151 -> 0 | L16: ='2.1meta'!M16+'2.1meta'!M32+'2.1meta'!M44+'2.1meta'!M85+'2.1meta'!M99+'2.1meta'!M110+'2.1meta'!M119+'2.1meta'!M126+'2.1meta'!M151 -> 0 | M16: ='2.1meta'!N16+'2.1meta'!N32+'2.1meta'!N44+'2.1meta'!N85+'2.1meta'!N99+'2.1meta'!N110+'2.1meta'!N119+'2.1meta'!N126+'2.1meta'!N151 -> 0 | N16: ='2.1meta'!O16+'2.1meta'!O32+'2.1meta'!O44+'2.1meta'!O85+'2.1meta'!O99+'2.1meta'!O110+'2.1meta'!O119+'2.1meta'!O126+'2.1meta'!O151 -> 0 | O16: ='2.1meta'!P16+'2.1meta'!P32+'2.1meta'!P44+'2.1meta'!P85+'2.1meta'!P99+'2.1meta'!P110+'2.1meta'!P119+'2.1meta'!P126+'2.1meta'!P151 -> 0 | ... W16: ='2.1meta'!X16+'2.1meta'!X32+'2.1meta'!X44+'2.1meta'!X85+'2.1meta'!X99+'2.1meta'!X110+'2.1meta'!X119+'2.1meta'!X126+'2.1meta'!X151 -> 0 | X16: =SUM(H16:W16) -> 0 | Y16: =F16+X16 -> 0 | Z16: =C16-Y16 -> 0
A17: 2.1.1.9.2.1 | B17: COMPENSACION POR TIEMPO DE SERVICIOS (CTS) | C17: ='2.1meta'!D17+'2.1meta'!D33+'2.1meta'!D45+'2.1meta'!D86+'2.1meta'!D100+'2.1meta'!D111+'2.1meta'!D152 -> 0 | D17: ='2.1meta'!E17+'2.1meta'!E33+'2.1meta'!E45+'2.1meta'!E86+'2.1meta'!E100+'2.1meta'!E111+'2.1meta'!E152 -> 0 | E17: ='2.1meta'!F17+'2.1meta'!F33+'2.1meta'!F45+'2.1meta'!F86+'2.1meta'!F100+'2.1meta'!F111+'2.1meta'!F152 -> 0 | F17: 0 | G17: =C17-F17 -> 0 | H17: ='2.1meta'!I17+'2.1meta'!I33+'2.1meta'!I45+'2.1meta'!I86+'2.1meta'!I100+'2.1meta'!I111+'2.1meta'!I152 -> 0 | I17: ='2.1meta'!J17+'2.1meta'!J33+'2.1meta'!J45+'2.1meta'!J86+'2.1meta'!J100+'2.1meta'!J111+'2.1meta'!J152 -> 0 | J17: ='2.1meta'!K17+'2.1meta'!K33+'2.1meta'!K45+'2.1meta'!K86+'2.1meta'!K100+'2.1meta'!K111+'2.1meta'!K152 -> 0 | K17: ='2.1meta'!L17+'2.1meta'!L33+'2.1meta'!L45+'2.1meta'!L86+'2.1meta'!L100+'2.1meta'!L111+'2.1meta'!L152 -> 0 | L17: ='2.1meta'!M17+'2.1meta'!M33+'2.1meta'!M45+'2.1meta'!M86+'2.1meta'!M100+'2.1meta'!M111+'2.1meta'!M152 -> 0 | M17: ='2.1meta'!N17+'2.1meta'!N33+'2.1meta'!N45+'2.1meta'!N86+'2.1meta'!N100+'2.1meta'!N111+'2.1meta'!N152 -> 0 | N17: ='2.1meta'!O17+'2.1meta'!O33+'2.1meta'!O45+'2.1meta'!O86+'2.1meta'!O100+'2.1meta'!O111+'2.1meta'!O152 -> 0 | O17: ='2.1meta'!P17+'2.1meta'!P33+'2.1meta'!P45+'2.1meta'!P86+'2.1meta'!P100+'2.1meta'!P111+'2.1meta'!P152 -> 0 | ... W17: ='2.1meta'!X17+'2.1meta'!X33+'2.1meta'!X45+'2.1meta'!X86+'2.1meta'!X100+'2.1meta'!X111+'2.1meta'!X152 -> 0 | X17: =SUM(H17:W17) -> 0 | Y17: =F17+X17 -> 0 | Z17: =C17-Y17 -> 0
A18: 2.1.1.9.3.3 | B18: COMPENSACION VACACIONAL (VACACIONES TRUNCAS) | C18: ='2.1meta'!D34 -> 0 | D18: ='2.1meta'!E34 -> 0 | E18: ='2.1meta'!F34 -> 0 | F18: 0 | G18: =C18-F18 -> 0 | H18: ='2.1meta'!I34 -> 0 | I18: ='2.1meta'!J34 -> 0 | J18: ='2.1meta'!K34 -> 0 | K18: ='2.1meta'!L34 -> 0 | L18: ='2.1meta'!M34 -> 0 | M18: ='2.1meta'!N34 -> 0 | N18: ='2.1meta'!O34 -> 0 | O18: ='2.1meta'!P34 -> 0 | ... W18: ='2.1meta'!X34 -> 0 | X18: =SUM(H18:W18) -> 0 | Y18: =F18+X18 -> 0 | Z18: =C18-Y18 -> 0
A19: 2.1.1.9.3.99 | B19: OTRAS OCASIONALES | C19: ='2.1meta'!D18+'2.1meta'!D35+'2.1meta'!D46+'2.1meta'!D87+'2.1meta'!D101+'2.1meta'!D112+'2.1meta'!D153 -> 0 | D19: ='2.1meta'!E18+'2.1meta'!E35+'2.1meta'!E46+'2.1meta'!E87+'2.1meta'!E101+'2.1meta'!E112+'2.1meta'!E153 -> 0 | E19: ='2.1meta'!F18+'2.1meta'!F35+'2.1meta'!F46+'2.1meta'!F87+'2.1meta'!F101+'2.1meta'!F112+'2.1meta'!F153 -> 0 | F19: 0 | G19: =C19-F19 -> 0 | H19: ='2.1meta'!I18+'2.1meta'!I35+'2.1meta'!I46+'2.1meta'!I87+'2.1meta'!I101+'2.1meta'!I112+'2.1meta'!I153 -> 0 | I19: ='2.1meta'!J18+'2.1meta'!J35+'2.1meta'!J46+'2.1meta'!J87+'2.1meta'!J101+'2.1meta'!J112+'2.1meta'!J153 -> 0 | J19: ='2.1meta'!K18+'2.1meta'!K35+'2.1meta'!K46+'2.1meta'!K87+'2.1meta'!K101+'2.1meta'!K112+'2.1meta'!K153 -> 0 | K19: ='2.1meta'!L18+'2.1meta'!L35+'2.1meta'!L46+'2.1meta'!L87+'2.1meta'!L101+'2.1meta'!L112+'2.1meta'!L153 -> 0 | L19: ='2.1meta'!M18+'2.1meta'!M35+'2.1meta'!M46+'2.1meta'!M87+'2.1meta'!M101+'2.1meta'!M112+'2.1meta'!M153 -> 0 | M19: ='2.1meta'!N18+'2.1meta'!N35+'2.1meta'!N46+'2.1meta'!N87+'2.1meta'!N101+'2.1meta'!N112+'2.1meta'!N153 -> 0 | N19: ='2.1meta'!O18+'2.1meta'!O35+'2.1meta'!O46+'2.1meta'!O87+'2.1meta'!O101+'2.1meta'!O112+'2.1meta'!O153 -> 0 | O19: ='2.1meta'!P18+'2.1meta'!P35+'2.1meta'!P46+'2.1meta'!P87+'2.1meta'!P101+'2.1meta'!P112+'2.1meta'!P153 -> 0 | ... W19: ='2.1meta'!X18+'2.1meta'!X35+'2.1meta'!X46+'2.1meta'!X87+'2.1meta'!X101+'2.1meta'!X112+'2.1meta'!X153 -> 0 | X19: =SUM(H19:W19) -> 0 | Y19: =F19+X19 -> 0 | Z19: =C19-Y19 -> 0
A20: 2.1.3.1.1.1 | B20: APORTES A LOS FONDOS DE SALUD | C20: ='2.1meta'!D19+'2.1meta'!D36+'2.1meta'!D47+'2.1meta'!D88+'2.1meta'!D127+'2.1meta'!D154 -> 0 | D20: ='2.1meta'!E19+'2.1meta'!E36+'2.1meta'!E47+'2.1meta'!E88+'2.1meta'!E127+'2.1meta'!E154 -> 0 | E20: ='2.1meta'!F19+'2.1meta'!F36+'2.1meta'!F47+'2.1meta'!F88+'2.1meta'!F127+'2.1meta'!F154 -> 0 | F20: 0 | G20: =C20-F20 -> 0 | H20: ='2.1meta'!I19+'2.1meta'!I36+'2.1meta'!I47+'2.1meta'!I88+'2.1meta'!I127+'2.1meta'!I154 -> 0 | I20: ='2.1meta'!J19+'2.1meta'!J36+'2.1meta'!J47+'2.1meta'!J88+'2.1meta'!J127+'2.1meta'!J154 -> 0 | J20: ='2.1meta'!K19+'2.1meta'!K36+'2.1meta'!K47+'2.1meta'!K88+'2.1meta'!K127+'2.1meta'!K154 -> 0 | K20: ='2.1meta'!L19+'2.1meta'!L36+'2.1meta'!L47+'2.1meta'!L88+'2.1meta'!L127+'2.1meta'!L154 -> 0 | L20: ='2.1meta'!M19+'2.1meta'!M36+'2.1meta'!M47+'2.1meta'!M88+'2.1meta'!M127+'2.1meta'!M154 -> 0 | M20: ='2.1meta'!N19+'2.1meta'!N36+'2.1meta'!N47+'2.1meta'!N88+'2.1meta'!N127+'2.1meta'!N154 -> 0 | N20: ='2.1meta'!O19+'2.1meta'!O36+'2.1meta'!O47+'2.1meta'!O88+'2.1meta'!O127+'2.1meta'!O154 -> 0 | O20: ='2.1meta'!P19+'2.1meta'!P36+'2.1meta'!P47+'2.1meta'!P88+'2.1meta'!P127+'2.1meta'!P154 -> 0 | ... W20: ='2.1meta'!X19+'2.1meta'!X36+'2.1meta'!X47+'2.1meta'!X88+'2.1meta'!X127+'2.1meta'!X154 -> 0 | X20: =SUM(H20:W20) -> 0 | Y20: =F20+X20 -> 0 | Z20: =C20-Y20 -> 0
A21: 2.1.3.1.1.3 | B21: APORTES A LOS FONDOS DE PENSIONES | C21: ='2.1meta'!D20+'2.1meta'!D37+'2.1meta'!D89 -> 0 | D21: ='2.1meta'!E20+'2.1meta'!E37+'2.1meta'!E89 -> 0 | E21: ='2.1meta'!F20+'2.1meta'!F37+'2.1meta'!F89 -> 0 | F21: 0 | G21: =C21-F21 -> 0 | H21: ='2.1meta'!I20+'2.1meta'!I37+'2.1meta'!I89 -> 0 | I21: ='2.1meta'!J20+'2.1meta'!J37+'2.1meta'!J89 -> 0 | J21: ='2.1meta'!K20+'2.1meta'!K37+'2.1meta'!K89 -> 0 | K21: ='2.1meta'!L20+'2.1meta'!L37+'2.1meta'!L89 -> 0 | L21: ='2.1meta'!M20+'2.1meta'!M37+'2.1meta'!M89 -> 0 | M21: ='2.1meta'!N20+'2.1meta'!N37+'2.1meta'!N89 -> 0 | N21: ='2.1meta'!O20+'2.1meta'!O37+'2.1meta'!O89 -> 0 | O21: ='2.1meta'!P20+'2.1meta'!P37+'2.1meta'!P89 -> 0 | ... W21: ='2.1meta'!X20+'2.1meta'!X37+'2.1meta'!X89 -> 0 | X21: =SUM(H21:W21) -> 0 | Y21: =F21+X21 -> 0 | Z21: =C21-Y21 -> 0
A22: 2.1.3.1.1.5 | B22: CONTRIBUCIONES A ESSALUD | C22: ='2.1meta'!D21+'2.1meta'!D38+'2.1meta'!D48+'2.1meta'!D90+'2.1meta'!D102+'2.1meta'!D113+'2.1meta'!D120+'2.1meta'!D128+'2.1meta'!D155 -> 0 | D22: ='2.1meta'!E21+'2.1meta'!E38+'2.1meta'!E48+'2.1meta'!E90+'2.1meta'!E102+'2.1meta'!E113+'2.1meta'!E120+'2.1meta'!E128+'2.1meta'!E155 -> 0 | E22: ='2.1meta'!F21+'2.1meta'!F38+'2.1meta'!F48+'2.1meta'!F90+'2.1meta'!F102+'2.1meta'!F113+'2.1meta'!F120+'2.1meta'!F128+'2.1meta'!F155 -> 0 | F22: 0 | G22: =C22-F22 -> 0 | H22: ='2.1meta'!I21+'2.1meta'!I38+'2.1meta'!I48+'2.1meta'!I90+'2.1meta'!I102+'2.1meta'!I113+'2.1meta'!I120+'2.1meta'!I128+'2.1meta'!I155 -> 0 | I22: ='2.1meta'!J21+'2.1meta'!J38+'2.1meta'!J48+'2.1meta'!J90+'2.1meta'!J102+'2.1meta'!J113+'2.1meta'!J120+'2.1meta'!J128+'2.1meta'!J155 -> 0 | J22: ='2.1meta'!K21+'2.1meta'!K38+'2.1meta'!K48+'2.1meta'!K90+'2.1meta'!K102+'2.1meta'!K113+'2.1meta'!K120+'2.1meta'!K128+'2.1meta'!K155 -> 0 | K22: ='2.1meta'!L21+'2.1meta'!L38+'2.1meta'!L48+'2.1meta'!L90+'2.1meta'!L102+'2.1meta'!L113+'2.1meta'!L120+'2.1meta'!L128+'2.1meta'!L155 -> 0 | L22: ='2.1meta'!M21+'2.1meta'!M38+'2.1meta'!M48+'2.1meta'!M90+'2.1meta'!M102+'2.1meta'!M113+'2.1meta'!M120+'2.1meta'!M128+'2.1meta'!M155 -> 0 | M22: ='2.1meta'!N21+'2.1meta'!N38+'2.1meta'!N48+'2.1meta'!N90+'2.1meta'!N102+'2.1meta'!N113+'2.1meta'!N120+'2.1meta'!N128+'2.1meta'!N155 -> 0 | N22: ='2.1meta'!O21+'2.1meta'!O38+'2.1meta'!O48+'2.1meta'!O90+'2.1meta'!O102+'2.1meta'!O113+'2.1meta'!O120+'2.1meta'!O128+'2.1meta'!O155 -> 0 | O22: ='2.1meta'!P21+'2.1meta'!P38+'2.1meta'!P48+'2.1meta'!P90+'2.1meta'!P102+'2.1meta'!P113+'2.1meta'!P120+'2.1meta'!P128+'2.1meta'!P155 -> 0 | ... W22: ='2.1meta'!X21+'2.1meta'!X38+'2.1meta'!X48+'2.1meta'!X90+'2.1meta'!X102+'2.1meta'!X113+'2.1meta'!X120+'2.1meta'!X128+'2.1meta'!X155 -> 0 | X22: =SUM(H22:W22) -> 0 | Y22: =F22+X22 -> 0 | Z22: =C22-Y22 -> 0
A23: 1002 PRODUCTOS ESPECIFICOS PARA REDUCCION DE LA VIOLENCIA CONTRA LA MUJER | C23: =SUBTOTAL(9,C24:C37) -> 0 | F23: =SUBTOTAL(9,F24:F37) -> 0 | G23: =C23-F23 -> 0 | H23: =SUBTOTAL(9,H24:H37) -> 0 | I23: =SUBTOTAL(9,I24:I37) -> 0 | J23: =SUBTOTAL(9,J24:J37) -> 0 | K23: =SUBTOTAL(9,K24:K37) -> 0 | L23: =SUBTOTAL(9,L24:L37) -> 0 | M23: =SUBTOTAL(9,M24:M37) -> 0 | N23: =SUBTOTAL(9,N24:N37) -> 0 | O23: =SUBTOTAL(9,O24:O37) -> 0 | ... Z23: =SUBTOTAL(9,Z24:Z37) -> 0
A24: 2.1.1.1.1.2 | B24: PERSONAL ADMINISTRATIVO NOMBRADO (REGIMEN PUBLICO) | C24: ='2.1meta'!D130 -> 0 | D24: ='2.1meta'!E130 -> 0 | E24: ='2.1meta'!F130 -> 0 | F24: 0 | G24: =C24-F24 -> 0 | H24: ='2.1meta'!I130 -> 0 | I24: ='2.1meta'!J130 -> 0 | J24: ='2.1meta'!K130 -> 0 | K24: ='2.1meta'!L130 -> 0 | L24: ='2.1meta'!M130 -> 0 | M24: ='2.1meta'!N130 -> 0 | N24: ='2.1meta'!O130 -> 0 | O24: ='2.1meta'!P130 -> 0 | ... W24: ='2.1meta'!X130 -> 0 | X24: =SUM(H24:W24) -> 0 | Y24: =F24+X24 -> 0 | Z24: =C24-Y24 -> 0
A25: 2.1.1.1.1.4 | B25: PERSONAL CON CONTRATO A PLAZO INDETERMINADO (REGIMEN LABORAL PRIVADO) | C25: ='2.1meta'!D131 -> 0 | D25: ='2.1meta'!E131 -> 0 | E25: ='2.1meta'!F131 -> 0 | F25: 0 | G25: =C25-F25 -> 0 | H25: ='2.1meta'!I131 -> 0 | I25: ='2.1meta'!J131 -> 0 | J25: ='2.1meta'!K131 -> 0 | K25: ='2.1meta'!L131 -> 0 | L25: ='2.1meta'!M131 -> 0 | M25: ='2.1meta'!N131 -> 0 | N25: ='2.1meta'!O131 -> 0 | O25: ='2.1meta'!P131 -> 0 | ... W25: ='2.1meta'!X131 -> 0 | X25: =SUM(H25:W25) -> 0 | Y25: =F25+X25 -> 0 | Z25: =C25-Y25 -> 0
A26: 2.1.1.1.1.5 | B26: PERSONAL CON CONTRATO A PLAZO FIJO (REGIMEN LABORAL PRIVADO) | C26: ='2.1meta'!D132 -> 0 | D26: ='2.1meta'!E132 -> 0 | E26: ='2.1meta'!F132 -> 0 | F26: 0 | G26: =C26-F26 -> 0 | H26: ='2.1meta'!I132 -> 0 | I26: ='2.1meta'!J132 -> 0 | J26: ='2.1meta'!K132 -> 0 | K26: ='2.1meta'!L132 -> 0 | L26: ='2.1meta'!M132 -> 0 | M26: ='2.1meta'!N132 -> 0 | N26: ='2.1meta'!O132 -> 0 | O26: ='2.1meta'!P132 -> 0 | ... W26: ='2.1meta'!X132 -> 0 | X26: =SUM(H26:W26) -> 0 | Y26: =F26+X26 -> 0 | Z26: =C26-Y26 -> 0
A27: 2.1.1.1.2.1 | B27: ASIGNACION A FONDOS PARA PERSONAL | C27: ='2.1meta'!D133 -> 0 | D27: ='2.1meta'!E133 -> 0 | E27: ='2.1meta'!F133 -> 0 | F27: 0 | G27: =C27-F27 -> 0 | H27: ='2.1meta'!I133 -> 0 | I27: ='2.1meta'!J133 -> 0 | J27: ='2.1meta'!K133 -> 0 | K27: ='2.1meta'!L133 -> 0 | L27: ='2.1meta'!M133 -> 0 | M27: ='2.1meta'!N133 -> 0 | N27: ='2.1meta'!O133 -> 0 | O27: ='2.1meta'!P133 -> 0 | ... W27: ='2.1meta'!X133 -> 0 | X27: =SUM(H27:W27) -> 0 | Y27: =F27+X27 -> 0 | Z27: =C27-Y27 -> 0
A28: 2.1.1.4.1.1 | B28: PERSONAL NOMBRADO | C28: ='2.1meta'!D134 -> 0 | D28: ='2.1meta'!E134 -> 0 | E28: ='2.1meta'!F134 -> 0 | F28: 0 | G28: =C28-F28 -> 0 | H28: ='2.1meta'!I134 -> 0 | I28: ='2.1meta'!J134 -> 0 | J28: ='2.1meta'!K134 -> 0 | K28: ='2.1meta'!L134 -> 0 | L28: ='2.1meta'!M134 -> 0 | M28: ='2.1meta'!N134 -> 0 | N28: ='2.1meta'!O134 -> 0 | O28: ='2.1meta'!P134 -> 0 | ... W28: ='2.1meta'!X134 -> 0 | X28: =SUM(H28:W28) -> 0 | Y28: =F28+X28 -> 0 | Z28: =C28-Y28 -> 0
A29: 2.1.1.4.2.1 | B29: BONO POR FUNCION JURISDICCIONAL Y FISCAL | C29: ='2.1meta'!D135 -> 0 | D29: ='2.1meta'!E135 -> 0 | E29: ='2.1meta'!F135 -> 0 | F29: 0 | G29: =C29-F29 -> 0 | H29: ='2.1meta'!I135 -> 0 | I29: ='2.1meta'!J135 -> 0 | J29: ='2.1meta'!K135 -> 0 | K29: ='2.1meta'!L135 -> 0 | L29: ='2.1meta'!M135 -> 0 | M29: ='2.1meta'!N135 -> 0 | N29: ='2.1meta'!O135 -> 0 | O29: ='2.1meta'!P135 -> 0 | ... W29: ='2.1meta'!X135 -> 0 | X29: =SUM(H29:W29) -> 0 | Y29: =F29+X29 -> 0 | Z29: =C29-Y29 -> 0
A30: 2.1.1.4.2.2 | B30: ASIGNACION POR GASTOS OPERATIVOS | C30: ='2.1meta'!D136 -> 0 | D30: ='2.1meta'!E136 -> 0 | E30: ='2.1meta'!F136 -> 0 | F30: 0 | G30: =C30-F30 -> 0 | H30: ='2.1meta'!I136 -> 0 | I30: ='2.1meta'!J136 -> 0 | J30: ='2.1meta'!K136 -> 0 | K30: ='2.1meta'!L136 -> 0 | L30: ='2.1meta'!M136 -> 0 | M30: ='2.1meta'!N136 -> 0 | N30: ='2.1meta'!O136 -> 0 | O30: ='2.1meta'!P136 -> 0 | ... W30: ='2.1meta'!X136 -> 0 | X30: =SUM(H30:W30) -> 0 | Y30: =F30+X30 -> 0 | Z30: =C30-Y30 -> 0
A31: 2.1.1.9.1.1 | B31: GRATIFICACIONES | C31: ='2.1meta'!D137 -> 0 | D31: ='2.1meta'!E137 -> 0 | E31: ='2.1meta'!F137 -> 0 | F31: 0 | G31: =C31-F31 -> 0 | H31: ='2.1meta'!I137 -> 0 | I31: ='2.1meta'!J137 -> 0 | J31: ='2.1meta'!K137 -> 0 | K31: ='2.1meta'!L137 -> 0 | L31: ='2.1meta'!M137 -> 0 | M31: ='2.1meta'!N137 -> 0 | N31: ='2.1meta'!O137 -> 0 | O31: ='2.1meta'!P137 -> 0 | ... W31: ='2.1meta'!X137 -> 0 | X31: =SUM(H31:W31) -> 0 | Y31: =F31+X31 -> 0 | Z31: =C31-Y31 -> 0
A32: 2.1.1.9.1.2 | B32: AGUINALDOS | C32: ='2.1meta'!D138 -> 0 | D32: ='2.1meta'!E138 -> 0 | E32: ='2.1meta'!F138 -> 0 | F32: 0 | G32: =C32-F32 -> 0 | H32: ='2.1meta'!I138 -> 0 | I32: ='2.1meta'!J138 -> 0 | J32: ='2.1meta'!K138 -> 0 | K32: ='2.1meta'!L138 -> 0 | L32: ='2.1meta'!M138 -> 0 | M32: ='2.1meta'!N138 -> 0 | N32: ='2.1meta'!O138 -> 0 | O32: ='2.1meta'!P138 -> 0 | ... W32: ='2.1meta'!X138 -> 0 | X32: =SUM(H32:W32) -> 0 | Y32: =F32+X32 -> 0 | Z32: =C32-Y32 -> 0
A33: 2.1.1.9.1.3 | B33: BONIFICACION POR ESCOLARIDAD | C33: ='2.1meta'!D139 -> 0 | D33: ='2.1meta'!E139 -> 0 | E33: ='2.1meta'!F139 -> 0 | F33: 0 | G33: =C33-F33 -> 0 | H33: ='2.1meta'!I139 -> 0 | I33: ='2.1meta'!J139 -> 0 | J33: ='2.1meta'!K139 -> 0 | K33: ='2.1meta'!L139 -> 0 | L33: ='2.1meta'!M139 -> 0 | M33: ='2.1meta'!N139 -> 0 | N33: ='2.1meta'!O139 -> 0 | O33: ='2.1meta'!P139 -> 0 | ... W33: ='2.1meta'!X139 -> 0 | X33: =SUM(H33:W33) -> 0 | Y33: =F33+X33 -> 0 | Z33: =C33-Y33 -> 0
A34: 2.1.1.9.2.1 | B34: COMPENSACION POR TIEMPO DE SERVICIOS (CTS) | C34: ='2.1meta'!D140 -> 0 | D34: ='2.1meta'!E140 -> 0 | E34: ='2.1meta'!F140 -> 0 | F34: 0 | G34: =C34-F34 -> 0 | H34: ='2.1meta'!I140 -> 0 | I34: ='2.1meta'!J140 -> 0 | J34: ='2.1meta'!K140 -> 0 | K34: ='2.1meta'!L140 -> 0 | L34: ='2.1meta'!M140 -> 0 | M34: ='2.1meta'!N140 -> 0 | N34: ='2.1meta'!O140 -> 0 | O34: ='2.1meta'!P140 -> 0 | ... W34: ='2.1meta'!X140 -> 0 | X34: =SUM(H34:W34) -> 0 | Y34: =F34+X34 -> 0 | Z34: =C34-Y34 -> 0
A35: 2.1.1.9.3.99 | B35: OTRAS OCASIONALES | C35: ='2.1meta'!D141 -> 0 | D35: ='2.1meta'!E141 -> 0 | E35: ='2.1meta'!F141 -> 0 | F35: 0 | G35: =C35-F35 -> 0 | H35: ='2.1meta'!I141 -> 0 | I35: ='2.1meta'!J141 -> 0 | J35: ='2.1meta'!K141 -> 0 | K35: ='2.1meta'!L141 -> 0 | L35: ='2.1meta'!M141 -> 0 | M35: ='2.1meta'!N141 -> 0 | N35: ='2.1meta'!O141 -> 0 | O35: ='2.1meta'!P141 -> 0 | ... W35: ='2.1meta'!X141 -> 0 | X35: =SUM(H35:W35) -> 0 | Y35: =F35+X35 -> 0 | Z35: =C35-Y35 -> 0
... A37: 2.1.3.1.1.5 | B37: CONTRIBUCIONES A ESSALUD | C37: ='2.1meta'!D143 -> 0 | D37: ='2.1meta'!E143 -> 0 | E37: ='2.1meta'!F143 -> 0 | F37: 0 | G37: =C37-F37 -> 0 | H37: ='2.1meta'!I143 -> 0 | I37: ='2.1meta'!J143 -> 0 | J37: ='2.1meta'!K143 -> 0 | K37: ='2.1meta'!L143 -> 0 | L37: ='2.1meta'!M143 -> 0 | M37: ='2.1meta'!N143 -> 0 | N37: ='2.1meta'!O143 -> 0 | O37: ='2.1meta'!P143 -> 0 | ... W37: ='2.1meta'!X143 -> 0 | X37: =SUM(H37:W37) -> 0 | Y37: =F37+X37 -> 0 | Z37: =C37-Y37 -> 0
A38: 9001 ACCIONES CENTRALES | C38: =SUBTOTAL(9,C39:C50) -> 0 | F38: =SUBTOTAL(9,F39:F50) -> 0 | G38: =C38-F38 -> 0 | H38: =SUBTOTAL(9,H39:H50) -> 0 | I38: =SUBTOTAL(9,I39:I50) -> 0 | J38: =SUBTOTAL(9,J39:J50) -> 0 | K38: =SUBTOTAL(9,K39:K50) -> 0 | L38: =SUBTOTAL(9,L39:L50) -> 0 | M38: =SUBTOTAL(9,M39:M50) -> 0 | N38: =SUBTOTAL(9,N39:N50) -> 0 | O38: =SUBTOTAL(9,O39:O50) -> 0 | ... S38: =SUBTOTAL(9,S39:S50) -> 0 | X38: =SUBTOTAL(9,X39:X50) -> 0 | Y38: =SUBTOTAL(9,Y39:Y50) -> 0 | Z38: =SUBTOTAL(9,Z39:Z50) -> 0
A39: 2.1.1.1.1.2 | B39: PERSONAL ADMINISTRATIVO NOMBRADO (REGIMEN PUBLICO) | C39: ='2.1meta'!D50 -> 0 | D39: ='2.1meta'!E50 -> 0 | E39: ='2.1meta'!F50 -> 0 | F39: 0 | G39: =C39-F39 -> 0 | H39: ='2.1meta'!I50 -> 0 | I39: ='2.1meta'!J50 -> 0 | J39: ='2.1meta'!K50 -> 0 | K39: ='2.1meta'!L50 -> 0 | L39: ='2.1meta'!M50 -> 0 | M39: ='2.1meta'!N50 -> 0 | N39: ='2.1meta'!O50 -> 0 | O39: ='2.1meta'!P50 -> 0 | ... W39: ='2.1meta'!X50 -> 0 | X39: =SUM(H39:W39) -> 0 | Y39: =F39+X39 -> 0 | Z39: =C39-Y39 -> 0
A40: 2.1.1.1.1.4 | B40: PERSONAL CON CONTRATO A PLAZO INDETERMINADO (REGIMEN LABORAL PRIVADO) | C40: ='2.1meta'!D51 -> 0 | D40: ='2.1meta'!E51 -> 0 | E40: ='2.1meta'!F51 -> 0 | F40: 0 | G40: =C40-F40 -> 0 | H40: ='2.1meta'!I51 -> 0 | I40: ='2.1meta'!J51 -> 0 | J40: ='2.1meta'!K51 -> 0 | K40: ='2.1meta'!L51 -> 0 | L40: ='2.1meta'!M51 -> 0 | M40: ='2.1meta'!N51 -> 0 | N40: ='2.1meta'!O51 -> 0 | O40: ='2.1meta'!P51 -> 0 | ... W40: ='2.1meta'!X51 -> 0 | X40: =SUM(H40:W40) -> 0 | Y40: =F40+X40 -> 0 | Z40: =C40-Y40 -> 0
A41: 2.1.1.1.1.5 | B41: PERSONAL CON CONTRATO A PLAZO FIJO (REGIMEN LABORAL PRIVADO) | C41: ='2.1meta'!D52 -> 0 | D41: ='2.1meta'!E52 -> 0 | E41: ='2.1meta'!F52 -> 0 | F41: 0 | G41: =C41-F41 -> 0 | H41: ='2.1meta'!I52 -> 0 | I41: ='2.1meta'!J52 -> 0 | J41: ='2.1meta'!K52 -> 0 | K41: ='2.1meta'!L52 -> 0 | L41: ='2.1meta'!M52 -> 0 | M41: ='2.1meta'!N52 -> 0 | N41: ='2.1meta'!O52 -> 0 | O41: ='2.1meta'!P52 -> 0 | ... W41: ='2.1meta'!X52 -> 0 | X41: =SUM(H41:W41) -> 0 | Y41: =F41+X41 -> 0 | Z41: =C41-Y41 -> 0
A42: 2.1.1.1.2.1 | B42: ASIGNACION A FONDOS PARA PERSONAL | C42: ='2.1meta'!D53 -> 0 | D42: ='2.1meta'!E53 -> 0 | E42: ='2.1meta'!F53 -> 0 | F42: 0 | G42: =C42-F42 -> 0 | H42: ='2.1meta'!I53 -> 0 | I42: ='2.1meta'!J53 -> 0 | J42: ='2.1meta'!K53 -> 0 | K42: ='2.1meta'!L53 -> 0 | L42: ='2.1meta'!M53 -> 0 | M42: ='2.1meta'!N53 -> 0 | N42: ='2.1meta'!O53 -> 0 | O42: ='2.1meta'!P53 -> 0 | ... W42: ='2.1meta'!X53 -> 0 | X42: =SUM(H42:W42) -> 0 | Y42: =F42+X42 -> 0 | Z42: =C42-Y42 -> 0
...

Sheet ESPECIFICA DE GASTO
A1: EJECUTORA: 0003 MINISTERIO PUBLICO - GERENCIA ADMINISTRATIVA DE AREQUIPA (1419)
A3: Cat pptal/ Detalle Específica de Gasto | C3: PIM | D3: Certificado | E3: Compromiso Anual | F3: T O T A L | G3: Saldo Presupuestal al 17.09.2021 | H3: Proyección Planillas Activa | T3: Proyeccion de plazas vacantes | V3: PAGO FACTURAS EPS | W3: BENEFICIOS | X3: TOTAL PROYECCION | Y3: TOTAL EJECUCION +PROYECCION | Z3: SALDO DISPONIBLE
H4: 01 ENERO | I4: 02 FEBRERO | J4: 03 MARZO | K4: 04 ABRIL | L4: 05 MAYO | M4: 06 JUNIO | N4: 07 JULIO | O4: 08 AGOSTO | P4: 09 SETIEMBRE | Q4: 10 OCTUBRE | R4: 11 OCTUBRE | S4: 12 OCTUBRE | T4: 276 | U4: 728
A5: 2.1.1.1.1.2 | B5: PERSONAL ADMINISTRATIVO NOMBRADO (REGIMEN PUBLICO) | C5: ='2.1meta'!D7+'2.1meta'!D23+'2.1meta'!D50+'2.1meta'!D63+'2.1meta'!D130 -> 0 | D5: ='2.1meta'!E7+'2.1meta'!E23+'2.1meta'!E50+'2.1meta'!E63+'2.1meta'!E130 -> 0 | E5: ='2.1meta'!F7+'2.1meta'!F23+'2.1meta'!F50+'2.1meta'!F63+'2.1meta'!F130 -> 0 | F5: 0 | G5: =C5-F5 -> 0 | H5: ='2.1meta'!I7+'2.1meta'!I23+'2.1meta'!I50+'2.1meta'!I63+'2.1meta'!I130 -> 0 | I5: ='2.1meta'!J7+'2.1meta'!J23+'2.1meta'!J50+'2.1meta'!J63+'2.1meta'!J130 -> 0 | J5: ='2.1meta'!K7+'2.1meta'!K23+'2.1meta'!K50+'2.1meta'!K63+'2.1meta'!K130 -> 0 | K5: ='2.1meta'!L7+'2.1meta'!L23+'2.1meta'!L50+'2.1meta'!L63+'2.1meta'!L130 -> 0 | L5: ='2.1meta'!M7+'2.1meta'!M23+'2.1meta'!M50+'2.1meta'!M63+'2.1meta'!M130 -> 0 | M5: ='2.1meta'!N7+'2.1meta'!N23+'2.1meta'!N50+'2.1meta'!N63+'2.1meta'!N130 -> 0 | N5: ='2.1meta'!O7+'2.1meta'!O23+'2.1meta'!O50+'2.1meta'!O63+'2.1meta'!O130 -> 0 | O5: ='2.1meta'!P7+'2.1meta'!P23+'2.1meta'!P50+'2.1meta'!P63+'2.1meta'!P130 -> 0 | ... W5: ='2.1meta'!X7+'2.1meta'!X23+'2.1meta'!X50+'2.1meta'!X63+'2.1meta'!X130 -> 0 | X5: =SUM(H5:W5) -> 0 | Y5: =F5+X5 -> 0 | Z5: =C5-Y5 -> 0
A6: 2.1.1.1.1.4 | B6: PERSONAL CON CONTRATO A PLAZO INDETERMINADO (REGIMEN LABORAL PRIVADO) | C6: ='2.1meta'!D8+'2.1meta'!D24+'2.1meta'!D40+'2.1meta'!D51+'2.1meta'!D64+'2.1meta'!D79+'2.1meta'!D92+'2.1meta'!D104+'2.1meta'!D131+'2.1meta'!D145 -> 0 | D6: ='2.1meta'!E8+'2.1meta'!E24+'2.1meta'!E40+'2.1meta'!E51+'2.1meta'!E64+'2.1meta'!E79+'2.1meta'!E92+'2.1meta'!E104+'2.1meta'!E131+'2.1meta'!E145 -> 0 | E6: ='2.1meta'!F8+'2.1meta'!F24+'2.1meta'!F40+'2.1meta'!F51+'2.1meta'!F64+'2.1meta'!F79+'2.1meta'!F92+'2.1meta'!F104+'2.1meta'!F131+'2.1meta'!F145 -> 0 | F6: 0 | G6: =C6-F6 -> 0 | H6: ='2.1meta'!I8+'2.1meta'!I24+'2.1meta'!I40+'2.1meta'!I51+'2.1meta'!I64+'2.1meta'!I79+'2.1meta'!I92+'2.1meta'!I104+'2.1meta'!I131+'2.1meta'!I145 -> 0 | I6: ='2.1meta'!J8+'2.1meta'!J24+'2.1meta'!J40+'2.1meta'!J51+'2.1meta'!J64+'2.1meta'!J79+'2.1meta'!J92+'2.1meta'!J104+'2.1meta'!J131+'2.1meta'!J145 -> 0 | J6: ='2.1meta'!K8+'2.1meta'!K24+'2.1meta'!K40+'2.1meta'!K51+'2.1meta'!K64+'2.1meta'!K79+'2.1meta'!K92+'2.1meta'!K104+'2.1meta'!K131+'2.1meta'!K145 -> 0 | K6: ='2.1meta'!L8+'2.1meta'!L24+'2.1meta'!L40+'2.1meta'!L51+'2.1meta'!L64+'2.1meta'!L79+'2.1meta'!L92+'2.1meta'!L104+'2.1meta'!L131+'2.1meta'!L145 -> 0 | L6: ='2.1meta'!M8+'2.1meta'!M24+'2.1meta'!M40+'2.1meta'!M51+'2.1meta'!M64+'2.1meta'!M79+'2.1meta'!M92+'2.1meta'!M104+'2.1meta'!M131+'2.1meta'!M145 -> 0 | M6: ='2.1meta'!N8+'2.1meta'!N24+'2.1meta'!N40+'2.1meta'!N51+'2.1meta'!N64+'2.1meta'!N79+'2.1meta'!N92+'2.1meta'!N104+'2.1meta'!N131+'2.1meta'!N145 -> 0 | N6: ='2.1meta'!O8+'2.1meta'!O24+'2.1meta'!O40+'2.1meta'!O51+'2.1meta'!O64+'2.1meta'!O79+'2.1meta'!O92+'2.1meta'!O104+'2.1meta'!O131+'2.1meta'!O145 -> 0 | O6: ='2.1meta'!P8+'2.1meta'!P24+'2.1meta'!P40+'2.1meta'!P51+'2.1meta'!P64+'2.1meta'!P79+'2.1meta'!P92+'2.1meta'!P104+'2.1meta'!P131+'2.1meta'!P145 -> 0 | ... W6: ='2.1meta'!X8+'2.1meta'!X24+'2.1meta'!X40+'2.1meta'!X51+'2.1meta'!X64+'2.1meta'!X79+'2.1meta'!X92+'2.1meta'!X104+'2.1meta'!X131+'2.1meta'!X145 -> 0 | X6: =SUM(H6:W6) -> 0 | Y6: =F6+X6 -> 0 | Z6: =C6-Y6 -> 0
A7: 2.1.1.1.1.5 | B7: PERSONAL CON CONTRATO A PLAZO FIJO (REGIMEN LABORAL PRIVADO) | C7: ='2.1meta'!D9+'2.1meta'!D25+'2.1meta'!D41+'2.1meta'!D52+'2.1meta'!D65+'2.1meta'!D93+'2.1meta'!D132+'2.1meta'!D157 -> 0 | D7: ='2.1meta'!E9+'2.1meta'!E25+'2.1meta'!E41+'2.1meta'!E52+'2.1meta'!E65+'2.1meta'!E93+'2.1meta'!E132+'2.1meta'!E157 -> 0 | E7: ='2.1meta'!F9+'2.1meta'!F25+'2.1meta'!F41+'2.1meta'!F52+'2.1meta'!F65+'2.1meta'!F93+'2.1meta'!F132+'2.1meta'!F157 -> 0 | F7: 0 | G7: =C7-F7 -> 0 | H7: ='2.1meta'!I9+'2.1meta'!I25+'2.1meta'!I41+'2.1meta'!I52+'2.1meta'!I65+'2.1meta'!I93+'2.1meta'!I132+'2.1meta'!I157 -> 0 | I7: ='2.1meta'!J9+'2.1meta'!J25+'2.1meta'!J41+'2.1meta'!J52+'2.1meta'!J65+'2.1meta'!J93+'2.1meta'!J132+'2.1meta'!J157 -> 0 | J7: ='2.1meta'!K9+'2.1meta'!K25+'2.1meta'!K41+'2.1meta'!K52+'2.1meta'!K65+'2.1meta'!K93+'2.1meta'!K132+'2.1meta'!K157 -> 0 | K7: ='2.1meta'!L9+'2.1meta'!L25+'2.1meta'!L41+'2.1meta'!L52+'2.1meta'!L65+'2.1meta'!L93+'2.1meta'!L132+'2.1meta'!L157 -> 0 | L7: ='2.1meta'!M9+'2.1meta'!M25+'2.1meta'!M41+'2.1meta'!M52+'2.1meta'!M65+'2.1meta'!M93+'2.1meta'!M132+'2.1meta'!M157 -> 0 | M7: ='2.1meta'!N9+'2.1meta'!N25+'2.1meta'!N41+'2.1meta'!N52+'2.1meta'!N65+'2.1meta'!N93+'2.1meta'!N132+'2.1meta'!N157 -> 0 | N7: ='2.1meta'!O9+'2.1meta'!O25+'2.1meta'!O41+'2.1meta'!O52+'2.1meta'!O65+'2.1meta'!O93+'2.1meta'!O132+'2.1meta'!O157 -> 0 | O7: ='2.1meta'!P9+'2.1meta'!P25+'2.1meta'!P41+'2.1meta'!P52+'2.1meta'!P65+'2.1meta'!P93+'2.1meta'!P132+'2.1meta'!P157 -> 0 | ... W7: ='2.1meta'!X9+'2.1meta'!X25+'2.1meta'!X41+'2.1meta'!X52+'2.1meta'!X65+'2.1meta'!X93+'2.1meta'!X132+'2.1meta'!X157 -> 0 | X7: =SUM(H7:W7) -> 0 | Y7: =F7+X7 -> 0 | Z7: =C7-Y7 -> 0
A8: 2.1.1.1.2.1 | B8: ASIGNACION A FONDOS PARA PERSONAL | C8: ='2.1meta'!D10+'2.1meta'!D26+'2.1meta'!D53+'2.1meta'!D66+'2.1meta'!D133 -> 0 | D8: ='2.1meta'!E10+'2.1meta'!E26+'2.1meta'!E53+'2.1meta'!E66+'2.1meta'!E133 -> 0 | E8: ='2.1meta'!F10+'2.1meta'!F26+'2.1meta'!F53+'2.1meta'!F66+'2.1meta'!F133 -> 0 | F8: 0 | G8: =C8-F8 -> 0 | H8: ='2.1meta'!I10+'2.1meta'!I26+'2.1meta'!I53+'2.1meta'!I66+'2.1meta'!I133 -> 0 | I8: ='2.1meta'!J10+'2.1meta'!J26+'2.1meta'!J53+'2.1meta'!J66+'2.1meta'!J133 -> 0 | J8: ='2.1meta'!K10+'2.1meta'!K26+'2.1meta'!K53+'2.1meta'!K66+'2.1meta'!K133 -> 0 | K8: ='2.1meta'!L10+'2.1meta'!L26+'2.1meta'!L53+'2.1meta'!L66+'2.1meta'!L133 -> 0 | L8: ='2.1meta'!M10+'2.1meta'!M26+'2.1meta'!M53+'2.1meta'!M66+'2.1meta'!M133 -> 0 | M8: ='2.1meta'!N10+'2.1meta'!N26+'2.1meta'!N53+'2.1meta'!N66+'2.1meta'!N133 -> 0 | N8: ='2.1meta'!O10+'2.1meta'!O26+'2.1meta'!O53+'2.1meta'!O66+'2.1meta'!O133 -> 0 | O8: ='2.1meta'!P10+'2.1meta'!P26+'2.1meta'!P53+'2.1meta'!P66+'2.1meta'!P133 -> 0 | ... W8: ='2.1meta'!X10+'2.1meta'!X26+'2.1meta'!X53+'2.1meta'!X66+'2.1meta'!X133 -> 0 | X8: =SUM(H8:W8) -> 0 | Y8: =F8+X8 -> 0 | Z8: =C8-Y8 -> 0
A9: 2.1.1. 3.1. 2 | B9: PERSONAL CONTRATADO | C9: ='2.1meta'!D42 -> 0 | D9: ='2.1meta'!E42 -> 0 | E9: ='2.1meta'!F42 -> 0 | F9: 0 | G9: =C9-F9 -> 0 | H9: ='2.1meta'!I42 -> 0 | I9: ='2.1meta'!J42 -> 0 | J9: ='2.1meta'!K42 -> 0 | K9: ='2.1meta'!L42 -> 0 | L9: ='2.1meta'!M42 -> 0 | M9: ='2.1meta'!N42 -> 0 | N9: ='2.1meta'!O42 -> 0 | O9: ='2.1meta'!P42 -> 0 | ... W9: ='2.1meta'!X42 -> 0 | X9: =SUM(H9:W9) -> 0 | Y9: =F9+X9 -> 0 | Z9: =C9-Y9 -> 0
A10: 2.1.1.4.1.1 | B10: PERSONAL NOMBRADO | C10: ='2.1meta'!D11+'2.1meta'!D27+'2.1meta'!D67+'2.1meta'!D80+'2.1meta'!D94+'2.1meta'!D105+'2.1meta'!D115+'2.1meta'!D122+'2.1meta'!D134+'2.1meta'!D146+'2.1meta'!D158 -> 0 | D10: ='2.1meta'!E11+'2.1meta'!E27+'2.1meta'!E67+'2.1meta'!E80+'2.1meta'!E94+'2.1meta'!E105+'2.1meta'!E115+'2.1meta'!E122+'2.1meta'!E134+'2.1meta'!E146+'2.1meta'!E158 -> 0 | E10: ='2.1meta'!F11+'2.1meta'!F27+'2.1meta'!F67+'2.1meta'!F80+'2.1meta'!F94+'2.1meta'!F105+'2.1meta'!F115+'2.1meta'!F122+'2.1meta'!F134+'2.1meta'!F146+'2.1meta'!F158 -> 0 | F10: 0 | G10: =C10-F10 -> 0 | H10: ='2.1meta'!I11+'2.1meta'!I27+'2.1meta'!I67+'2.1meta'!I80+'2.1meta'!I94+'2.1meta'!I105+'2.1meta'!I115+'2.1meta'!I122+'2.1meta'!I134+'2.1meta'!I146+'2.1meta'!I158 -> 0 | I10: ='2.1meta'!J11+'2.1meta'!J27+'2.1meta'!J67+'2.1meta'!J80+'2.1meta'!J94+'2.1meta'!J105+'2.1meta'!J115+'2.1meta'!J122+'2.1meta'!J134+'2.1meta'!J146+'2.1meta'!J158 -> 0 | J10: ='2.1meta'!K11+'2.1meta'!K27+'2.1meta'!K67+'2.1meta'!K80+'2.1meta'!K94+'2.1meta'!K105+'2.1meta'!K115+'2.1meta'!K122+'2.1meta'!K134+'2.1meta'!K146+'2.1meta'!K158 -> 0 | K10: ='2.1meta'!L11+'2.1meta'!L27+'2.1meta'!L67+'2.1meta'!L80+'2.1meta'!L94+'2.1meta'!L105+'2.1meta'!L115+'2.1meta'!L122+'2.1meta'!L134+'2.1meta'!L146+'2.1meta'!L158 -> 0 | L10: ='2.1meta'!M11+'2.1meta'!M27+'2.1meta'!M67+'2.1meta'!M80+'2.1meta'!M94+'2.1meta'!M105+'2.1meta'!M115+'2.1meta'!M122+'2.1meta'!M134+'2.1meta'!M146+'2.1meta'!M158 -> 0 | M10: ='2.1meta'!N11+'2.1meta'!N27+'2.1meta'!N67+'2.1meta'!N80+'2.1meta'!N94+'2.1meta'!N105+'2.1meta'!N115+'2.1meta'!N122+'2.1meta'!N134+'2.1meta'!N146+'2.1meta'!N158 -> 0 | N10: ='2.1meta'!O11+'2.1meta'!O27+'2.1meta'!O67+'2.1meta'!O80+'2.1meta'!O94+'2.1meta'!O105+'2.1meta'!O115+'2.1meta'!O122+'2.1meta'!O134+'2.1meta'!O146+'2.1meta'!O158 -> 0 | O10: ='2.1meta'!P11+'2.1meta'!P27+'2.1meta'!P67+'2.1meta'!P80+'2.1meta'!P94+'2.1meta'!P105+'2.1meta'!P115+'2.1meta'!P122+'2.1meta'!P134+'2.1meta'!P146+'2.1meta'!P158 -> 0 | ... W10: ='2.1meta'!X11+'2.1meta'!X27+'2.1meta'!X67+'2.1meta'!X80+'2.1meta'!X94+'2.1meta'!X105+'2.1meta'!X115+'2.1meta'!X122+'2.1meta'!X134+'2.1meta'!X146+'2.1meta'!X158 -> 0 | X10: =SUM(H10:W10) -> 0 | Y10: =F10+X10 -> 0 | Z10: =C10-Y10 -> 0
A11: 2.1.1.4.2.1 | B11: BONO POR FUNCION JURISDICCIONAL Y FISCAL | C11: ='2.1meta'!D12+'2.1meta'!D28+'2.1meta'!D68+'2.1meta'!D81+'2.1meta'!D95+'2.1meta'!D106+'2.1meta'!D116+'2.1meta'!D123+'2.1meta'!D135+'2.1meta'!D147+'2.1meta'!D159 -> 0 | D11: ='2.1meta'!E12+'2.1meta'!E28+'2.1meta'!E68+'2.1meta'!E81+'2.1meta'!E95+'2.1meta'!E106+'2.1meta'!E116+'2.1meta'!E123+'2.1meta'!E135+'2.1meta'!E147+'2.1meta'!E159 -> 0 | E11: ='2.1meta'!F12+'2.1meta'!F28+'2.1meta'!F68+'2.1meta'!F81+'2.1meta'!F95+'2.1meta'!F106+'2.1meta'!F116+'2.1meta'!F123+'2.1meta'!F135+'2.1meta'!F147+'2.1meta'!F159 -> 0 | F11: 0 | G11: =C11-F11 -> 0 | H11: ='2.1meta'!I12+'2.1meta'!I28+'2.1meta'!I68+'2.1meta'!I81+'2.1meta'!I95+'2.1meta'!I106+'2.1meta'!I116+'2.1meta'!I123+'2.1meta'!I135+'2.1meta'!I147+'2.1meta'!I159 -> 0 | I11: ='2.1meta'!J12+'2.1meta'!J28+'2.1meta'!J68+'2.1meta'!J81+'2.1meta'!J95+'2.1meta'!J106+'2.1meta'!J116+'2.1meta'!J123+'2.1meta'!J135+'2.1meta'!J147+'2.1meta'!J159 -> 0 | J11: ='2.1meta'!K12+'2.1meta'!K28+'2.1meta'!K68+'2.1meta'!K81+'2.1meta'!K95+'2.1meta'!K106+'2.1meta'!K116+'2.1meta'!K123+'2.1meta'!K135+'2.1meta'!K147+'2.1meta'!K159 -> 0 | K11: ='2.1meta'!L12+'2.1meta'!L28+'2.1meta'!L68+'2.1meta'!L81+'2.1meta'!L95+'2.1meta'!L106+'2.1meta'!L116+'2.1meta'!L123+'2.1meta'!L135+'2.1meta'!L147+'2.1meta'!L159 -> 0 | L11: ='2.1meta'!M12+'2.1meta'!M28+'2.1meta'!M68+'2.1meta'!M81+'2.1meta'!M95+'2.1meta'!M106+'2.1meta'!M116+'2.1meta'!M123+'2.1meta'!M135+'2.1meta'!M147+'2.1meta'!M159 -> 0 | M11: ='2.1meta'!N12+'2.1meta'!N28+'2.1meta'!N68+'2.1meta'!N81+'2.1meta'!N95+'2.1meta'!N106+'2.1meta'!N116+'2.1meta'!N123+'2.1meta'!N135+'2.1meta'!N147+'2.1meta'!N159 -> 0 | N11: ='2.1meta'!O12+'2.1meta'!O28+'2.1meta'!O68+'2.1meta'!O81+'2.1meta'!O95+'2.1meta'!O106+'2.1meta'!O116+'2.1meta'!O123+'2.1meta'!O135+'2.1meta'!O147+'2.1meta'!O159 -> 0 | O11: ='2.1meta'!P12+'2.1meta'!P28+'2.1meta'!P68+'2.1meta'!P81+'2.1meta'!P95+'2.1meta'!P106+'2.1meta'!P116+'2.1meta'!P123+'2.1meta'!P135+'2.1meta'!P147+'2.1meta'!P159 -> 0 | ... W11: ='2.1meta'!X12+'2.1meta'!X28+'2.1meta'!X68+'2.1meta'!X81+'2.1meta'!X95+'2.1meta'!X106+'2.1meta'!X116+'2.1meta'!X123+'2.1meta'!X135+'2.1meta'!X147+'2.1meta'!X159 -> 0 | X11: =SUM(H11:W11) -> 0 | Y11: =F11+X11 -> 0 | Z11: =C11-Y11 -> 0
A12: 2.1.1.4.2.2 | B12: ASIGNACION POR GASTOS OPERATIVOS | C12: ='2.1meta'!D13+'2.1meta'!D29+'2.1meta'!D69+'2.1meta'!D82+'2.1meta'!D96+'2.1meta'!D107+'2.1meta'!D117+'2.1meta'!D124+'2.1meta'!D136+'2.1meta'!D148+'2.1meta'!D160 -> 0 | D12: ='2.1meta'!E13+'2.1meta'!E29+'2.1meta'!E69+'2.1meta'!E82+'2.1meta'!E96+'2.1meta'!E107+'2.1meta'!E117+'2.1meta'!E124+'2.1meta'!E136+'2.1meta'!E148+'2.1meta'!E160 -> 0 | E12: ='2.1meta'!F13+'2.1meta'!F29+'2.1meta'!F69+'2.1meta'!F82+'2.1meta'!F96+'2.1meta'!F107+'2.1meta'!F117+'2.1meta'!F124+'2.1meta'!F136+'2.1meta'!F148+'2.1meta'!F160 -> 0 | F12: 0 | G12: =C12-F12 -> 0 | H12: ='2.1meta'!I13+'2.1meta'!I29+'2.1meta'!I69+'2.1meta'!I82+'2.1meta'!I96+'2.1meta'!I107+'2.1meta'!I117+'2.1meta'!I124+'2.1meta'!I136+'2.1meta'!I148+'2.1meta'!I160 -> 0 | I12: ='2.1meta'!J13+'2.1meta'!J29+'2.1meta'!J69+'2.1meta'!J82+'2.1meta'!J96+'2.1meta'!J107+'2.1meta'!J117+'2.1meta'!J124+'2.1meta'!J136+'2.1meta'!J148+'2.1meta'!J160 -> 0 | J12: ='2.1meta'!K13+'2.1meta'!K29+'2.1meta'!K69+'2.1meta'!K82+'2.1meta'!K96+'2.1meta'!K107+'2.1meta'!K117+'2.1meta'!K124+'2.1meta'!K136+'2.1meta'!K148+'2.1meta'!K160 -> 0 | K12: ='2.1meta'!L13+'2.1meta'!L29+'2.1meta'!L69+'2.1meta'!L82+'2.1meta'!L96+'2.1meta'!L107+'2.1meta'!L117+'2.1meta'!L124+'2.1meta'!L136+'2.1meta'!L148+'2.1meta'!L160 -> 0 | L12: ='2.1meta'!M13+'2.1meta'!M29+'2.1meta'!M69+'2.1meta'!M82+'2.1meta'!M96+'2.1meta'!M107+'2.1meta'!M117+'2.1meta'!M124+'2.1meta'!M136+'2.1meta'!M148+'2.1meta'!M160 -> 0 | M12: ='2.1meta'!N13+'2.1meta'!N29+'2.1meta'!N69+'2.1meta'!N82+'2.1meta'!N96+'2.1meta'!N107+'2.1meta'!N117+'2.1meta'!N124+'2.1meta'!N136+'2.1meta'!N148+'2.1meta'!N160 -> 0 | N12: ='2.1meta'!O13+'2.1meta'!O29+'2.1meta'!O69+'2.1meta'!O82+'2.1meta'!O96+'2.1meta'!O107+'2.1meta'!O117+'2.1meta'!O124+'2.1meta'!O136+'2.1meta'!O148+'2.1meta'!O160 -> 0 | O12: ='2.1meta'!P13+'2.1meta'!P29+'2.1meta'!P69+'2.1meta'!P82+'2.1meta'!P96+'2.1meta'!P107+'2.1meta'!P117+'2.1meta'!P124+'2.1meta'!P136+'2.1meta'!P148+'2.1meta'!P160 -> 0 | ... W12: ='2.1meta'!X13+'2.1meta'!X29+'2.1meta'!X69+'2.1meta'!X82+'2.1meta'!X96+'2.1meta'!X107+'2.1meta'!X117+'2.1meta'!X124+'2.1meta'!X136+'2.1meta'!X148+'2.1meta'!X160 -> 0 | X12: =SUM(H12:W12) -> 0 | Y12: =F12+X12 -> 0 | Z12: =C12-Y12 -> 0
A13: 2.1.1.9.1.1 | B13: GRATIFICACIONES | C13: ='2.1meta'!D14+'2.1meta'!D30+'2.1meta'!D43+'2.1meta'!D54+'2.1meta'!D70+'2.1meta'!D83+'2.1meta'!D97+'2.1meta'!D108+'2.1meta'!D137+'2.1meta'!D149+'2.1meta'!D161 -> 0 | D13: ='2.1meta'!E14+'2.1meta'!E30+'2.1meta'!E43+'2.1meta'!E54+'2.1meta'!E70+'2.1meta'!E83+'2.1meta'!E97+'2.1meta'!E108+'2.1meta'!E137+'2.1meta'!E149+'2.1meta'!E161 -> 0 | E13: ='2.1meta'!F14+'2.1meta'!F30+'2.1meta'!F43+'2.1meta'!F54+'2.1meta'!F70+'2.1meta'!F83+'2.1meta'!F97+'2.1meta'!F108+'2.1meta'!F137+'2.1meta'!F149+'2.1meta'!F161 -> 0 | F13: 0 | G13: =C13-F13 -> 0 | H13: ='2.1meta'!I14+'2.1meta'!I30+'2.1meta'!I43+'2.1meta'!I54+'2.1meta'!I70+'2.1meta'!I83+'2.1meta'!I97+'2.1meta'!I108+'2.1meta'!I137+'2.1meta'!I149+'2.1meta'!I161 -> 0 | I13: ='2.1meta'!J14+'2.1meta'!J30+'2.1meta'!J43+'2.1meta'!J54+'2.1meta'!J70+'2.1meta'!J83+'2.1meta'!J97+'2.1meta'!J108+'2.1meta'!J137+'2.1meta'!J149+'2.1meta'!J161 -> 0 | J13: ='2.1meta'!K14+'2.1meta'!K30+'2.1meta'!K43+'2.1meta'!K54+'2.1meta'!K70+'2.1meta'!K83+'2.1meta'!K97+'2.1meta'!K108+'2.1meta'!K137+'2.1meta'!K149+'2.1meta'!K161 -> 0 | K13: ='2.1meta'!L14+'2.1meta'!L30+'2.1meta'!L43+'2.1meta'!L54+'2.1meta'!L70+'2.1meta'!L83+'2.1meta'!L97+'2.1meta'!L108+'2.1meta'!L137+'2.1meta'!L149+'2.1meta'!L161 -> 0 | L13: ='2.1meta'!M14+'2.1meta'!M30+'2.1meta'!M43+'2.1meta'!M54+'2.1meta'!M70+'2.1meta'!M83+'2.1meta'!M97+'2.1meta'!M108+'2.1meta'!M137+'2.1meta'!M149+'2.1meta'!M161 -> 0 | M13: ='2.1meta'!N14+'2.1meta'!N30+'2.1meta'!N43+'2.1meta'!N54+'2.1meta'!N70+'2.1meta'!N83+'2.1meta'!N97+'2.1meta'!N108+'2.1meta'!N137+'2.1meta'!N149+'2.1meta'!N161 -> 0 | N13: ='2.1meta'!O14+'2.1meta'!O30+'2.1meta'!O43+'2.1meta'!O54+'2.1meta'!O70+'2.1meta'!O83+'2.1meta'!O97+'2.1meta'!O108+'2.1meta'!O137+'2.1meta'!O149+'2.1meta'!O161 -> 0 | O13: ='2.1meta'!P14+'2.1meta'!P30+'2.1meta'!P43+'2.1meta'!P54+'2.1meta'!P70+'2.1meta'!P83+'2.1meta'!P97+'2.1meta'!P108+'2.1meta'!P137+'2.1meta'!P149+'2.1meta'!P161 -> 0 | ... W13: ='2.1meta'!X14+'2.1meta'!X30+'2.1meta'!X43+'2.1meta'!X54+'2.1meta'!X70+'2.1meta'!X83+'2.1meta'!X97+'2.1meta'!X108+'2.1meta'!X137+'2.1meta'!X149+'2.1meta'!X161 -> 0 | X13: =SUM(H13:W13) -> 0 | Y13: =F13+X13 -> 0 | Z13: =C13-Y13 -> 0
A14: 2.1.1.9.1.2 | B14: AGUINALDOS | C14: ='2.1meta'!D15+'2.1meta'!D31+'2.1meta'!D55+'2.1meta'!D71+'2.1meta'!D84+'2.1meta'!D98+'2.1meta'!D109+'2.1meta'!D118+'2.1meta'!D125+'2.1meta'!D138+'2.1meta'!D150+'2.1meta'!D162 -> 0 | D14: ='2.1meta'!E15+'2.1meta'!E31+'2.1meta'!E55+'2.1meta'!E71+'2.1meta'!E84+'2.1meta'!E98+'2.1meta'!E109+'2.1meta'!E118+'2.1meta'!E125+'2.1meta'!E138+'2.1meta'!E150+'2.1meta'!E162 -> 0 | E14: ='2.1meta'!F15+'2.1meta'!F31+'2.1meta'!F55+'2.1meta'!F71+'2.1meta'!F84+'2.1meta'!F98+'2.1meta'!F109+'2.1meta'!F118+'2.1meta'!F125+'2.1meta'!F138+'2.1meta'!F150+'2.1meta'!F162 -> 0 | F14: 0 | G14: =C14-F14 -> 0 | H14: ='2.1meta'!I15+'2.1meta'!I31+'2.1meta'!I55+'2.1meta'!I71+'2.1meta'!I84+'2.1meta'!I98+'2.1meta'!I109+'2.1meta'!I118+'2.1meta'!I125+'2.1meta'!I138+'2.1meta'!I150+'2.1meta'!I162 -> 0 | I14: ='2.1meta'!J15+'2.1meta'!J31+'2.1meta'!J55+'2.1meta'!J71+'2.1meta'!J84+'2.1meta'!J98+'2.1meta'!J109+'2.1meta'!J118+'2.1meta'!J125+'2.1meta'!J138+'2.1meta'!J150+'2.1meta'!J162 -> 0 | J14: ='2.1meta'!K15+'2.1meta'!K31+'2.1meta'!K55+'2.1meta'!K71+'2.1meta'!K84+'2.1meta'!K98+'2.1meta'!K109+'2.1meta'!K118+'2.1meta'!K125+'2.1meta'!K138+'2.1meta'!K150+'2.1meta'!K162 -> 0 | K14: ='2.1meta'!L15+'2.1meta'!L31+'2.1meta'!L55+'2.1meta'!L71+'2.1meta'!L84+'2.1meta'!L98+'2.1meta'!L109+'2.1meta'!L118+'2.1meta'!L125+'2.1meta'!L138+'2.1meta'!L150+'2.1meta'!L162 -> 0 | L14: ='2.1meta'!M15+'2.1meta'!M31+'2.1meta'!M55+'2.1meta'!M71+'2.1meta'!M84+'2.1meta'!M98+'2.1meta'!M109+'2.1meta'!M118+'2.1meta'!M125+'2.1meta'!M138+'2.1meta'!M150+'2.1meta'!M162 -> 0 | M14: ='2.1meta'!N15+'2.1meta'!N31+'2.1meta'!N55+'2.1meta'!N71+'2.1meta'!N84+'2.1meta'!N98+'2.1meta'!N109+'2.1meta'!N118+'2.1meta'!N125+'2.1meta'!N138+'2.1meta'!N150+'2.1meta'!N162 -> 0 | N14: ='2.1meta'!O15+'2.1meta'!O31+'2.1meta'!O55+'2.1meta'!O71+'2.1meta'!O84+'2.1meta'!O98+'2.1meta'!O109+'2.1meta'!O118+'2.1meta'!O125+'2.1meta'!O138+'2.1meta'!O150+'2.1meta'!O162 -> 0 | O14: ='2.1meta'!P15+'2.1meta'!P31+'2.1meta'!P55+'2.1meta'!P71+'2.1meta'!P84+'2.1meta'!P98+'2.1meta'!P109+'2.1meta'!P118+'2.1meta'!P125+'2.1meta'!P138+'2.1meta'!P150+'2.1meta'!P162 -> 0 | ... W14: ='2.1meta'!X15+'2.1meta'!X31+'2.1meta'!X55+'2.1meta'!X71+'2.1meta'!X84+'2.1meta'!X98+'2.1meta'!X109+'2.1meta'!X118+'2.1meta'!X125+'2.1meta'!X138+'2.1meta'!X150+'2.1meta'!X162 -> 0 | X14: =SUM(H14:W14) -> 0 | Y14: =F14+X14 -> 0 | Z14: =C14-Y14 -> 0
