Workbook
Name GENERAL: '276 - SETIEMBRE 16-09-2021'!$I$2:$AT$262

Sheet 276 - SETIEMBRE 16-09-2021
B1: MESES PROYECCION | D1: 1 | E1: VACANTE | H1: N° GRATIFICACION | J1: 1 | M1: ESCOLARIDAD | O1: NO | AL1: 0.09 | AM1: 0.0675
A2: Nº | B2: CODI_EMPL_,C,8 | C2: DNI,C,8 | D2: NOMB_CORT_,C,50 | E2: FECHA DE INGRESO | F2: CARGO TITULAR | G2: TITULAR/PROV | H2: EPS,C,150 | I2: META | J2: CARGO PEA | K2: CARGO COMP | L2: NIVEL,C,55 | M2: MONTO,N,17,2 | N2: ESTADO | O2: HABERES | P2: TOTAL HABERES | Q2: CLAS. H | R2: BENEF. EXTR | S2: TOTAL BEN. EX | T2: CLAS.BE | U2: BONO FISCAL | V2: TOTAL BONO FISCAL | W2: CLAS.BF | X2: G.O | Y2: TOTAL G.O. | Z2: CLAS.G.O | AA2: 25% RETARDO | AB2: TOTAL 25% | AC2: CLAS. | AD2: AGUINALDOS | AE2: TOTAL AGUI | AF2: CLAS AGU | AG2: CAFAE | AH2: TOTAL CAFAE | AI2: CLAS. CAFAE | AJ2: ESCOLARIDAD | AK2: CLASIF | AL2: ESSALUD 9% | AM2: TOTAL ESSALUD 9% | AN2: CLS ES 9% | AO2: EPS 2.25% | AP2: TOTAL EPS 2.25% | AQ2: CLS 2.25% | AR2: FPENSI 6% | AS2: TOTAL FONDP 6% | AT2: CLS 6% | AV2: TOTAL | AW2: TOTAL + ESSSALUD
A3: 1 | P3: =ROUND(O3*$D$1,2) -> 0 | S3: =ROUND(R3*$D$1,2) -> 0 | AE3: =ROUND(AD3*$J$1,2) -> 0 | AH3: =ROUND(AG3*$D$1,2) -> 0 | AJ3: =IF($O$1="SI",400,0) -> 0 | AK3: 2.1.1.9.1.3 | AL3: =IF(H3="RIMAC EPS EMPRESA PRESTADORA DE SALUD",O3*0.0675,O3*0.09) -> 0 | AM3: =ROUND(AL3*$D$1,2) -> 0 | AN3: 2.1. 3 1. 1 5 | AO3: =IF(H3="RIMAC EPS EMPRESA PRESTADORA DE SALUD",O3*0.0225,O3*0) -> 0 | AV3: =P3+S3+V3+Y3+AB3+AE3+AH3+AJ3 -> 0 | AW3: =AV3+AM3+AP3+AS3 -> 0
A4: 2 | P4: =ROUND(O4*$D$1,2) -> 0 | V4: =ROUND(U4*$D$1,2) -> 0 | Y4: =ROUND(X4*$D$1,2) -> 0 | AE4: =ROUND(AD4*$J$1,2) -> 0 | AJ4: =IF($O$1="SI",400,0) -> 0 | AK4: 2.1.1.9.1.3 | AL4: =IF(H4="RIMAC EPS EMPRESA PRESTADORA DE SALUD",O4*0.0675,O4*0.09) -> 0 | AM4: =ROUND(AL4*$D$1,2) -> 0 | AN4: 2.1. 3 1. 1 5 | AO4: =IF(H4="RIMAC EPS EMPRESA PRESTADORA DE SALUD",O4*0.0225,O4*0) -> 0 | AP4: =ROUND(AO4*$D$1,2) -> 0 | AV4: =P4+S4+V4+Y4+AB4+AE4+AH4+AJ4 -> 0 | AW4: =AV4+AM4+AP4+AS4 -> 0
A5: 3 | P5: =ROUND(O5*$D$1,2) -> 0 | V5: =ROUND(U5*$D$1,2) -> 0 | Y5: =ROUND(X5*$D$1,2) -> 0 | AE5: =ROUND(AD5*$J$1,2) -> 0 | AJ5: =IF($O$1="SI",400,0) -> 0 | AK5: 2.1.1.9.1.3 | AL5: =IF(H5="RIMAC EPS EMPRESA PRESTADORA DE SALUD",O5*0.0675,O5*0.09) -> 0 | AM5: =ROUND(AL5*$D$1,2) -> 0 | AN5: 2.1. 3 1. 1 5 | AO5: =IF(H5="RIMAC EPS EMPRESA PRESTADORA DE SALUD",O5*0.0225,O5*0) -> 0 | AV5: =P5+S5+V5+Y5+AB5+AE5+AH5+AJ5 -> 0 | AW5: =AV5+AM5+AP5+AS5 -> 0
A6: 4 | P6: =ROUND(O6*$D$1,2) -> 0 | S6: =ROUND(R6*$D$1,2) -> 0 | AE6: =ROUND(AD6*$J$1,2) -> 0 | AH6: =ROUND(AG6*$D$1,2) -> 0 | AJ6: =IF($O$1="SI",400,0) -> 0 | AK6: 2.1.1.9.1.3 | AL6: =IF(H6="RIMAC EPS EMPRESA PRESTADORA DE SALUD",O6*0.0675,O6*0.09) -> 0 | AM6: =ROUND(AL6*$D$1,2) -> 0 | AN6: 2.1. 3 1. 1 5 | AO6: =IF(H6="RIMAC EPS EMPRESA PRESTADORA DE SALUD",O6*0.0225,O6*0) -> 0 | AV6: =P6+S6+V6+Y6+AB6+AE6+AH6+AJ6 -> 0 | AW6: =AV6+AM6+AP6+AS6 -> 0
A7: 5 | P7: =ROUND(O7*$D$1,2) -> 0 | V7: =ROUND(U7*$D$1,2) -> 0 | Y7: =ROUND(X7*$D$1,2) -> 0 | AE7: =ROUND(AD7*$J$1,2) -> 0 | AJ7: =IF($O$1="SI",400,0) -> 0 | AK7: 2.1.1.9.1.3 | AL7: =IF(H7="RIMAC EPS EMPRESA PRESTADORA DE SALUD",O7*0.0675,O7*0.09) -> 0 | AM7: =ROUND(AL7*$D$1,2) -> 0 | AN7: 2.1. 3 1. 1 5 | AO7: =IF(H7="RIMAC EPS EMPRESA PRESTADORA DE SALUD",O7*0.0225,O7*0) -> 0 | AP7: =ROUND(AO7*$D$1,2) -> 0 | AV7: =P7+S7+V7+Y7+AB7+AE7+AH7+AJ7 -> 0 | AW7: =AV7+AM7+AP7+AS7 -> 0
A8: 6 | P8: =ROUND(O8*$D$1,2) -> 0 | S8: =ROUND(R8*$D$1,2) -> 0 | AE8: =ROUND(AD8*$J$1,2) -> 0 | AH8: =ROUND(AG8*$D$1,2) -> 0 | AJ8: =IF($O$1="SI",400,0) -> 0 | AK8: 2.1.1.9.1.3 | AL8: =IF(H8="RIMAC EPS EMPRESA PRESTADORA DE SALUD",O8*0.0675,O8*0.09) -> 0 | AM8: =ROUND(AL8*$D$1,2) -> 0 | AN8: 2.1. 3 1. 1 5 | AO8: =IF(H8="RIMAC EPS EMPRESA PRESTADORA DE SALUD",O8*0.0225,O8*0) -> 0 | AV8: =P8+S8+V8+Y8+AB8+AE8+AH8+AJ8 -> 0 | AW8: =AV8+AM8+AP8+AS8 -> 0
A9: 7 | P9: =ROUND(O9*$D$1,2) -> 0 | V9: =ROUND(U9*$D$1,2) -> 0 | Y9: =ROUND(X9*$D$1,2) -> 0 | AE9: =ROUND(AD9*$J$1,2) -> 0 | AJ9: =IF($O$1="SI",400,0) -> 0 | AK9: 2.1.1.9.1.3 | AL9: =IF(H9="RIMAC EPS EMPRESA PRESTADORA DE SALUD",O9*0.0675,O9*0.09) -> 0 | AM9: =ROUND(AL9*$D$1,2) -> 0 | AN9: 2.1. 3 1. 1 5 | AO9: =IF(H9="RIMAC EPS EMPRESA PRESTADORA DE SALUD",O9*0.0225,O9*0) -> 0 | AV9: =P9+S9+V9+Y9+AB9+AE9+AH9+AJ9 -> 0 | AW9: =AV9+AM9+AP9+AS9 -> 0
A10: 8 | P10: =ROUND(O10*$D$1,2) -> 0 | V10: =ROUND(U10*$D$1,2) -> 0 | Y10: =ROUND(X10*$D$1,2) -> 0 | AE10: =ROUND(AD10*$J$1,2) -> 0 | AJ10: =IF($O$1="SI",400,0) -> 0 | AK10: 2.1.1.9.1.3 | AL10: =IF(H10="RIMAC EPS EMPRESA PRESTADORA DE SALUD",O10*0.0675,O10*0.09) -> 0 | AM10: =ROUND(AL10*$D$1,2) -> 0 | AN10: 2.1. 3 1. 1 5 | AO10: =IF(H10="RIMAC EPS EMPRESA PRESTADORA DE SALUD",O10*0.0225,O10*0) -> 0 | AV10: =P10+S10+V10+Y10+AB10+AE10+AH10+AJ10 -> 0 | AW10: =AV10+AM10+AP10+AS10 -> 0
A11: 9 | P11: =ROUND(O11*$D$1,2) -> 0 | V11: =ROUND(U11*$D$1,2) -> 0 | Y11: =ROUND(X11*$D$1,2) -> 0 | AE11: =ROUND(AD11*$J$1,2) -> 0 | AJ11: =IF($O$1="SI",400,0) -> 0 | AK11: 2.1.1.9.1.3 | AL11: =IF(H11="RIMAC EPS EMPRESA PRESTADORA DE SALUD",O11*0.0675,O11*0.09) -> 0 | AM11: =ROUND(AL11*$D$1,2) -> 0 | AN11: 2.1. 3 1. 1 5 | AO11: =IF(H11="RIMAC EPS EMPRESA PRESTADORA DE SALUD",O11*0.0225,O11*0) -> 0 | AP11: =ROUND(AO11*$D$1,2) -> 0 | AV11: =P11+S11+V11+Y11+AB11+AE11+AH11+AJ11 -> 0 | AW11: =AV11+AM11+AP11+AS11 -> 0
A12: 10 | P12: =ROUND(O12*$D$1,2) -> 0 | V12: =ROUND(U12*$D$1,2) -> 0 | Y12: =ROUND(X12*$D$1,2) -> 0 | AE12: =ROUND(AD12*$J$1,2) -> 0 | AJ12: =IF($O$1="SI",400,0) -> 0 | AK12: 2.1.1.9.1.3 | AL12: =IF(H12="RIMAC EPS EMPRESA PRESTADORA DE SALUD",O12*0.0675,O12*0.09) -> 0 | AM12: =ROUND(AL12*$D$1,2) -> 0 | AN12: 2.1. 3 1. 1 5 | AO12: =IF(H12="RIMAC EPS EMPRESA PRESTADORA DE SALUD",O12*0.0225,O12*0) -> 0 | AV12: =P12+S12+V12+Y12+AB12+AE12+AH12+AJ12 -> 0 | AW12: =AV12+AM12+AP12+AS12 -> 0
A13: 11 | P13: =ROUND(O13*$D$1,2) -> 0 | V13: =ROUND(U13*$D$1,2) -> 0 | Y13: =ROUND(X13*$D$1,2) -> 0 | AE13: =ROUND(AD13*$J$1,2) -> 0 | AJ13: =IF($O$1="SI",400,0) -> 0 | AK13: 2.1.1.9.1.3 | AL13: =IF(H13="RIMAC EPS EMPRESA PRESTADORA DE SALUD",O13*0.0675,O13*0.09) -> 0 | AM13: =ROUND(AL13*$D$1,2) -> 0 | AN13: 2.1. 3 1. 1 5 | AO13: =IF(H13="RIMAC EPS EMPRESA PRESTADORA DE SALUD",O13*0.0225,O13*0) -> 0 | AV13: =P13+S13+V13+Y13+AB13+AE13+AH13+AJ13 -> 0 | AW13: =AV13+AM13+AP13+AS13 -> 0
A14: 12 | P14: =ROUND(O14*$D$1,2) -> 0 | V14: =ROUND(U14*$D$1,2) -> 0 | Y14: =ROUND(X14*$D$1,2) -> 0 | AE14: =ROUND(AD14*$J$1,2) -> 0 | AJ14: =IF($O$1="SI",400,0) -> 0 | AK14: 2.1.1.9.1.3 | AL14: =IF(H14="RIMAC EPS EMPRESA PRESTADORA DE SALUD",O14*0.0675,O14*0.09) -> 0 | AM14: =ROUND(AL14*$D$1,2) -> 0 | AN14: 2.1. 3 1. 1 5 | AO14: =IF(H14="RIMAC EPS EMPRESA PRESTADORA DE SALUD",O14*0.0225,O14*0) -> 0 | AV14: =P14+S14+V14+Y14+AB14+AE14+AH14+AJ14 -> 0 | AW14: =AV14+AM14+AP14+AS14 -> 0
A15: 13 | P15: =ROUND(O15*$D$1,2) -> 0 | V15: =ROUND(U15*$D$1,2) -> 0 | Y15: =ROUND(X15*$D$1,2) -> 0 | AE15: =ROUND(AD15*$J$1,2) -> 0 | AJ15: =IF($O$1="SI",400,0) -> 0 | AK15: 2.1.1.9.1.3 | AL15: =IF(H15="RIMAC EPS EMPRESA PRESTADORA DE SALUD",O15*0.0675,O15*0.09) -> 0 | AM15: =ROUND(AL15*$D$1,2) -> 0 | AN15: 2.1. 3 1. 1 5 | AO15: =IF(H15="RIMAC EPS EMPRESA PRESTADORA DE SALUD",O15*0.0225,O15*0) -> 0 | AV15: =P15+S15+V15+Y15+AB15+AE15+AH15+AJ15 -> 0 | AW15: =AV15+AM15+AP15+AS15 -> 0
A16: 14 | P16: =ROUND(O16*$D$1,2) -> 0 | V16: =ROUND(U16*$D$1,2) -> 0 | Y16: =ROUND(X16*$D$1,2) -> 0 | AB16: =ROUND(AA16*$D$1,2) -> 0 | AE16: =ROUND(AD16*$J$1,2) -> 0 | AJ16: =IF($O$1="SI",400,0) -> 0 | AK16: 2.1.1.9.1.3 | AL16: =IF(H16="RIMAC EPS EMPRESA PRESTADORA DE SALUD",O16*0.0675,O16*0.09) -> 0 | AM16: =ROUND(AL16*$D$1,2) -> 0 | AN16: 2.1. 3 1. 1 5 | AO16: =IF(H16="RIMAC EPS EMPRESA PRESTADORA DE SALUD",O16*0.0225,O16*0) -> 0 | AV16: =P16+S16+V16+Y16+AB16+AE16+AH16+AJ16 -> 0 | AW16: =AV16+AM16+AP16+AS16 -> 0
A17: 15 | P17: =ROUND(O17*$D$1,2) -> 0 | V17: =ROUND(U17*$D$1,2) -> 0 | Y17: =ROUND(X17*$D$1,2) -> 0 | AB17: =ROUND(AA17*$D$1,2) -> 0 | AE17: =ROUND(AD17*$J$1,2) -> 0 | AJ17: =IF($O$1="SI",400,0) -> 0 | AK17: 2.1.1.9.1.3 | AL17: =IF(H17="RIMAC EPS EMPRESA PRESTADORA DE SALUD",O17*0.0675,O17*0.09) -> 0 | AM17: =ROUND(AL17*$D$1,2) -> 0 | AN17: 2.1. 3 1. 1 5 | AO17: =IF(H17="RIMAC EPS EMPRESA PRESTADORA DE SALUD",O17*0.0225,O17*0) -> 0 | AV17: =P17+S17+V17+Y17+AB17+AE17+AH17+AJ17 -> 0 | AW17: =AV17+AM17+AP17+AS17 -> 0
A18: 16 | P18: =ROUND(O18*$D$1,2) -> 0 | V18: =ROUND(U18*$D$1,2) -> 0 | Y18: =ROUND(X18*$D$1,2) -> 0 | AE18: =ROUND(AD18*$J$1,2) -> 0 | AJ18: =IF($O$1="SI",400,0) -> 0 | AK18: 2.1.1.9.1.3 | AL18: =IF(H18="RIMAC EPS EMPRESA PRESTADORA DE SALUD",O18*0.0675,O18*0.09) -> 0 | AM18: =ROUND(AL18*$D$1,2) -> 0 | AN18: 2.1. 3 1. 1 5 | AO18: =IF(H18="RIMAC EPS EMPRESA PRESTADORA DE SALUD",O18*0.0225,O18*0) -> 0 | AP18: =ROUND(AO18*$D$1,2) -> 0 | AV18: =P18+S18+V18+Y18+AB18+AE18+AH18+AJ18 -> 0 | AW18: =AV18+AM18+AP18+AS18 -> 0
A19: 17 | P19: =ROUND(O19*$D$1,2) -> 0 | V19: =ROUND(U19*$D$1,2) -> 0 | Y19: =ROUND(X19*$D$1,2) -> 0 | AE19: =ROUND(AD19*$J$1,2) -> 0 | AJ19: =IF($O$1="SI",400,0) -> 0 | AK19: 2.1.1.9.1.3 | AL19: =IF(H19="RIMAC EPS EMPRESA PRESTADORA DE SALUD",O19*0.0675,O19*0.09) -> 0 | AM19: =ROUND(AL19*$D$1,2) -> 0 | AN19: 2.1. 3 1. 1 5 | AO19: =IF(H19="RIMAC EPS EMPRESA PRESTADORA DE SALUD",O19*0.0225,O19*0) -> 0 | AV19: =P19+S19+V19+Y19+AB19+AE19+AH19+AJ19 -> 0 | AW19: =AV19+AM19+AP19+AS19 -> 0
A20: 18 | P20: =ROUND(O20*$D$1,2) -> 0 | V20: =ROUND(U20*$D$1,2) -> 0 | Y20: =ROUND(X20*$D$1,2) -> 0 | AE20: =ROUND(AD20*$J$1,2) -> 0 | AJ20: =IF($O$1="SI",400,0) -> 0 | AK20: 2.1.1.9.1.3 | AL20: =IF(H20="RIMAC EPS EMPRESA PRESTADORA DE SALUD",O20*0.0675,O20*0.09) -> 0 | AM20: =ROUND(AL20*$D$1,2) -> 0 | AN20: 2.1. 3 1. 1 5 | AO20: =IF(H20="RIMAC EPS EMPRESA PRESTADORA DE SALUD",O20*0.0225,O20*0) -> 0 | AV20: =P20+S20+V20+Y20+AB20+AE20+AH20+AJ20 -> 0 | AW20: =AV20+AM20+AP20+AS20 -> 0
A21: 19 | P21: =ROUND(O21*$D$1,2) -> 0 | V21: =ROUND(U21*$D$1,2) -> 0 | Y21: =ROUND(X21*$D$1,2) -> 0 | AE21: =ROUND(AD21*$J$1,2) -> 0 | AJ21: =IF($O$1="SI",400,0) -> 0 | AK21: 2.1.1.9.1.3 | AL21: =IF(H21="RIMAC EPS EMPRESA PRESTADORA DE SALUD",O21*0.0675,O21*0.09) -> 0 | AM21: =ROUND(AL21*$D$1,2) -> 0 | AN21: 2.1. 3 1. 1 5 | AO21: =IF(H21="RIMAC EPS EMPRESA PRESTADORA DE SALUD",O21*0.0225,O21*0) -> 0 | AP21: =ROUND(AO21*$D$1,2) -> 0 | AV21: =P21+S21+V21+Y21+AB21+AE21+AH21+AJ21 -> 0 | AW21: =AV21+AM21+AP21+AS21 -> 0
A22: 20 | P22: =ROUND(O22*$D$1,2) -> 0 | V22: =ROUND(U22*$D$1,2) -> 0 | Y22: =ROUND(X22*$D$1,2) -> 0 | AE22: =ROUND(AD22*$J$1,2) -> 0 | AJ22: =IF($O$1="SI",400,0) -> 0 | AK22: 2.1.1.9.1.3 | AL22: =IF(H22="RIMAC EPS EMPRESA PRESTADORA DE SALUD",O22*0.0675,O22*0.09) -> 0 | AM22: =ROUND(AL22*$D$1,2) -> 0 | AN22: 2.1. 3 1. 1 5 | AO22: =IF(H22="RIMAC EPS EMPRESA PRESTADORA DE SALUD",O22*0.0225,O22*0) -> 0 | AV22: =P22+S22+V22+Y22+AB22+AE22+AH22+AJ22 -> 0 | AW22: =AV22+AM22+AP22+AS22 -> 0
A23: 21 | P23: =ROUND(O23*$D$1,2) -> 0 | V23: =ROUND(U23*$D$1,2) -> 0 | Y23: =ROUND(X23*$D$1,2) -> 0 | AE23: =ROUND(AD23*$J$1,2) -> 0 | AJ23: =IF($O$1="SI",400,0) -> 0 | AK23: 2.1.1.9.1.3 | AL23: =IF(H23="RIMAC EPS EMPRESA PRESTADORA DE SALUD",O23*0.0675,O23*0.09) -> 0 | AM23: =ROUND(AL23*$D$1,2) -> 0 | AN23: 2.1. 3 1. 1 5 | AO23: =IF(H23="RIMAC EPS EMPRESA PRESTADORA DE SALUD",O23*0.0225,O23*0) -> 0 | AV23: =P23+S23+V23+Y23+AB23+AE23+AH23+AJ23 -> 0 | AW23: =AV23+AM23+AP23+AS23 -> 0
A24: 22 | P24: =ROUND(O24*$D$1,2) -> 0 | V24: =ROUND(U24*$D$1,2) -> 0 | Y24: =ROUND(X24*$D$1,2) -> 0 | AE24: =ROUND(AD24*$J$1,2) -> 0 | AJ24: =IF($O$1="SI",400,0) -> 0 | AK24: 2.1.1.9.1.3 | AL24: =IF(H24="RIMAC EPS EMPRESA PRESTADORA DE SALUD",O24*0.0675,O24*0.09) -> 0 | AM24: =ROUND(AL24*$D$1,2) -> 0 | AN24: 2.1. 3 1. 1 5 | AO24: =IF(H24="RIMAC EPS EMPRESA PRESTADORA DE SALUD",O24*0.0225,O24*0) -> 0 | AV24: =P24+S24+V24+Y24+AB24+AE24+AH24+AJ24 -> 0 | AW24: =AV24+AM24+AP24+AS24 -> 0
A25: 23 | P25: =ROUND(O25*$D$1,2) -> 0 | V25: =ROUND(U25*$D$1,2) -> 0 | Y25: =ROUND(X25*$D$1,2) -> 0 | AE25: =ROUND(AD25*$J$1,2) -> 0 | AJ25: =IF($O$1="SI",400,0) -> 0 | AK25: 2.1.1.9.1.3 | AL25: =IF(H25="RIMAC EPS EMPRESA PRESTADORA DE SALUD",O25*0.0675,O25*0.09) -> 0 | AM25: =ROUND(AL25*$D$1,2) -> 0 | AN25: 2.1. 3 1. 1 5 | AO25: =IF(H25="RIMAC EPS EMPRESA PRESTADORA DE SALUD",O25*0.0225,O25*0) -> 0 | AP25: =ROUND(AO25*$D$1,2) -> 0 | AR25: =O25*6% -> 0 | AS25: =ROUND(AR25*$D$1,2) -> 0 | AV25: =P25+S25+V25+Y25+AB25+AE25+AH25+AJ25 -> 0 | AW25: =AV25+AM25+AP25+AS25 -> 0
A26: 24 | P26: =ROUND(O26*$D$1,2) -> 0 | V26: =ROUND(U26*$D$1,2) -> 0 | Y26: =ROUND(X26*$D$1,2) -> 0 | AE26: =ROUND(AD26*$J$1,2) -> 0 | AJ26: =IF($O$1="SI",400,0) -> 0 | AK26: 2.1.1.9.1.3 | AL26: =IF(H26="RIMAC EPS EMPRESA PRESTADORA DE SALUD",O26*0.0675,O26*0.09) -> 0 | AM26: =ROUND(AL26*$D$1,2) -> 0 | AN26: 2.1. 3 1. 1 5 | AO26: =IF(H26="RIMAC EPS EMPRESA PRESTADORA DE SALUD",O26*0.0225,O26*0) -> 0 | AV26: =P26+S26+V26+Y26+AB26+AE26+AH26+AJ26 -> 0 | AW26: =AV26+AM26+AP26+AS26 -> 0
A27: 25 | P27: =ROUND(O27*$D$1,2) -> 0 | V27: =ROUND(U27*$D$1,2) -> 0 | Y27: =ROUND(X27*$D$1,2) -> 0 | AE27: =ROUND(AD27*$J$1,2) -> 0 | AJ27: =IF($O$1="SI",400,0) -> 0 | AK27: 2.1.1.9.1.3 | AL27: =IF(H27="RIMAC EPS EMPRESA PRESTADORA DE SALUD",O27*0.0675,O27*0.09) -> 0 | AM27: =ROUND(AL27*$D$1,2) -> 0 | AN27: 2.1. 3 1. 1 5 | AO27: =IF(H27="RIMAC EPS EMPRESA PRESTADORA DE SALUD",O27*0.0225,O27*0) -> 0 | AV27: =P27+S27+V27+Y27+AB27+AE27+AH27+AJ27 -> 0 | AW27: =AV27+AM27+AP27+AS27 -> 0
A28: 26 | P28: =ROUND(O28*$D$1,2) -> 0 | V28: =ROUND(U28*$D$1,2) -> 0 | Y28: =ROUND(X28*$D$1,2) -> 0 | AE28: =ROUND(AD28*$J$1,2) -> 0 | AJ28: =IF($O$1="SI",400,0) -> 0 | AK28: 2.1.1.9.1.3 | AL28: =IF(H28="RIMAC EPS EMPRESA PRESTADORA DE SALUD",O28*0.0675,O28*0.09) -> 0 | AM28: =ROUND(AL28*$D$1,2) -> 0 | AN28: 2.1. 3 1. 1 5 | AO28: =IF(H28="RIMAC EPS EMPRESA PRESTADORA DE SALUD",O28*0.0225,O28*0) -> 0 | AV28: =P28+S28+V28+Y28+AB28+AE28+AH28+AJ28 -> 0 | AW28: =AV28+AM28+AP28+AS28 -> 0
A29: 27 | P29: =ROUND(O29*$D$1,2) -> 0 | V29: =ROUND(U29*$D$1,2) -> 0 | Y29: =ROUND(X29*$D$1,2) -> 0 | AE29: =ROUND(AD29*$J$1,2) -> 0 | AJ29: =IF($O$1="SI",400,0) -> 0 | AK29: 2.1.1.9.1.3 | AL29: =IF(H29="RIMAC EPS EMPRESA PRESTADORA DE SALUD",O29*0.0675,O29*0.09) -> 0 | AM29: =ROUND(AL29*$D$1,2) -> 0 | AN29: 2.1. 3 1. 1 5 | AO29: =IF(H29="RIMAC EPS EMPRESA PRESTADORA DE SALUD",O29*0.0225,O29*0) -> 0 | AV29: =P29+S29+V29+Y29+AB29+AE29+AH29+AJ29 -> 0 | AW29: =AV29+AM29+AP29+AS29 -> 0
A30: 28 | P30: =ROUND(O30*$D$1,2) -> 0 | V30: =ROUND(U30*$D$1,2) -> 0 | Y30: =ROUND(X30*$D$1,2) -> 0 | AE30: =ROUND(AD30*$J$1,2) -> 0 | AJ30: =IF($O$1="SI",400,0) -> 0 | AK30: 2.1.1.9.1.3 | AL30: =IF(H30="RIMAC EPS EMPRESA PRESTADORA DE SALUD",O30*0.0675,O30*0.09) -> 0 | AM30: =ROUND(AL30*$D$1,2) -> 0 | AN30: 2.1. 3 1. 1 5 | AO30: =IF(H30="RIMAC EPS EMPRESA PRESTADORA DE SALUD",O30*0.0225,O30*0) -> 0 | AV30: =P30+S30+V30+Y30+AB30+AE30+AH30+AJ30 -> 0 | AW30: =AV30+AM30+AP30+AS30 -> 0
A31: 29 | P31: =ROUND(O31*$D$1,2) -> 0 | V31: =ROUND(U31*$D$1,2) -> 0 | Y31: =ROUND(X31*$D$1,2) -> 0 | AE31: =ROUND(AD31*$J$1,2) -> 0 | AJ31: =IF($O$1="SI",400,0) -> 0 | AK31: 2.1.1.9.1.3 | AL31: =IF(H31="RIMAC EPS EMPRESA PRESTADORA DE SALUD",O31*0.0675,O31*0.09) -> 0 | AM31: =ROUND(AL31*$D$1,2) -> 0 | AN31: 2.1. 3 1. 1 5 | AO31: =IF(H31="RIMAC EPS EMPRESA PRESTADORA DE SALUD",O31*0.0225,O31*0) -> 0 | AV31: =P31+S31+V31+Y31+AB31+AE31+AH31+AJ31 -> 0 | AW31: =AV31+AM31+AP31+AS31 -> 0
A32: 30 | P32: =ROUND(O32*$D$1,2) -> 0 | V32: =ROUND(U32*$D$1,2) -> 0 | Y32: =ROUND(X32*$D$1,2) -> 0 | AE32: =ROUND(AD32*$J$1,2) -> 0 | AJ32: =IF($O$1="SI",400,0) -> 0 | AK32: 2.1.1.9.1.3 | AL32: =IF(H32="RIMAC EPS EMPRESA PRESTADORA DE SALUD",O32*0.0675,O32*0.09) -> 0 | AM32: =ROUND(AL32*$D$1,2) -> 0 | AN32: 2.1. 3 1. 1 5 | AO32: =IF(H32="RIMAC EPS EMPRESA PRESTADORA DE SALUD",O32*0.0225,O32*0) -> 0 | AV32: =P32+S32+V32+Y32+AB32+AE32+AH32+AJ32 -> 0 | AW32: =AV32+AM32+AP32+AS32 -> 0
A33: 31 | P33: =ROUND(O33*$D$1,2) -> 0 | V33: =ROUND(U33*$D$1,2) -> 0 | Y33: =ROUND(X33*$D$1,2) -> 0 | AE33: =ROUND(AD33*$J$1,2) -> 0 | AJ33: =IF($O$1="SI",400,0) -> 0 | AK33: 2.1.1.9.1.3 | AL33: =IF(H33="RIMAC EPS EMPRESA PRESTADORA DE SALUD",O33*0.0675,O33*0.09) -> 0 | AM33: =ROUND(AL33*$D$1,2) -> 0 | AN33: 2.1. 3 1. 1 5 | AO33: =IF(H33="RIMAC EPS EMPRESA PRESTADORA DE SALUD",O33*0.0225,O33*0) -> 0 | AV33: =P33+S33+V33+Y33+AB33+AE33+AH33+AJ33 -> 0 | AW33: =AV33+AM33+AP33+AS33 -> 0
A34: 32 | P34: =ROUND(O34*$D$1,2) -> 0 | V34: =ROUND(U34*$D$1,2) -> 0 | Y34: =ROUND(X34*$D$1,2) -> 0 | AE34: =ROUND(AD34*$J$1,2) -> 0 | AJ34: =IF($O$1="SI",400,0) -> 0 | AK34: 2.1.1.9.1.3 | AL34: =IF(H34="RIMAC EPS EMPRESA PRESTADORA DE SALUD",O34*0.0675,O34*0.09) -> 0 | AM34: =ROUND(AL34*$D$1,2) -> 0 | AN34: 2.1. 3 1. 1 5 | AO34: =IF(H34="RIMAC EPS EMPRESA PRESTADORA DE SALUD",O34*0.0225,O34*0) -> 0 | AV34: =P34+S34+V34+Y34+AB34+AE34+AH34+AJ34 -> 0 | AW34: =AV34+AM34+AP34+AS34 -> 0
A35: 33 | P35: =ROUND(O35*$D$1,2) -> 0 | V35: =ROUND(U35*$D$1,2) -> 0 | Y35: =ROUND(X35*$D$1,2) -> 0 | AE35: =ROUND(AD35*$J$1,2) -> 0 | AJ35: =IF($O$1="SI",400,0) -> 0 | AK35: 2.1.1.9.1.3 | AL35: =IF(H35="RIMAC EPS EMPRESA PRESTADORA DE SALUD",O35*0.0675,O35*0.09) -> 0 | AM35: =ROUND(AL35*$D$1,2) -> 0 | AN35: 2.1. 3 1. 1 5 | AO35: =IF(H35="RIMAC EPS EMPRESA PRESTADORA DE SALUD",O35*0.0225,O35*0) -> 0 | AV35: =P35+S35+V35+Y35+AB35+AE35+AH35+AJ35 -> 0 | AW35: =AV35+AM35+AP35+AS35 -> 0
A36: 34 | P36: =ROUND(O36*$D$1,2) -> 0 | V36: =ROUND(U36*$D$1,2) -> 0 | Y36: =ROUND(X36*$D$1,2) -> 0 | AE36: =ROUND(AD36*$J$1,2) -> 0 | AJ36: =IF($O$1="SI",400,0) -> 0 | AK36: 2.1.1.9.1.3 | AL36: =IF(H36="RIMAC EPS EMPRESA PRESTADORA DE SALUD",O36*0.0675,O36*0.09) -> 0 | AM36: =ROUND(AL36*$D$1,2) -> 0 | AN36: 2.1. 3 1. 1 5 | AO36: =IF(H36="RIMAC EPS EMPRESA PRESTADORA DE SALUD",O36*0.0225,O36*0) -> 0 | AV36: =P36+S36+V36+Y36+AB36+AE36+AH36+AJ36 -> 0 | AW36: =AV36+AM36+AP36+AS36 -> 0
A37: 35 | P37: =ROUND(O37*$D$1,2) -> 0 | V37: =ROUND(U37*$D$1,2) -> 0 | Y37: =ROUND(X37*$D$1,2) -> 0 | AE37: =ROUND(AD37*$J$1,2) -> 0 | AJ37: =IF($O$1="SI",400,0) -> 0 | AK37: 2.1.1.9.1.3 | AL37: =IF(H37="RIMAC EPS EMPRESA PRESTADORA DE SALUD",O37*0.0675,O37*0.09) -> 0 | AM37: =ROUND(AL37*$D$1,2) -> 0 | AN37: 2.1. 3 1. 1 5 | AO37: =IF(H37="RIMAC EPS EMPRESA PRESTADORA DE SALUD",O37*0.0225,O37*0) -> 0 | AV37: =P37+S37+V37+Y37+AB37+AE37+AH37+AJ37 -> 0 | AW37: =AV37+AM37+AP37+AS37 -> 0
... A40: 38 | P40: =ROUND(O40*$D$1,2) -> 0 | V40: =ROUND(U40*$D$1,2) -> 0 | Y40: =ROUND(X40*$D$1,2) -> 0 | AE40: =ROUND(AD40*$J$1,2) -> 0 | AJ40: =IF($O$1="SI",400,0) -> 0 | AK40: 2.1.1.9.1.3 | AL40: =IF(H40="RIMAC EPS EMPRESA PRESTADORA DE SALUD",O40*0.0675,O40*0.09) -> 0 | AM40: =ROUND(AL40*$D$1,2) -> 0 | AN40: 2.1. 3 1. 1 5 | AO40: =IF(H40="RIMAC EPS EMPRESA PRESTADORA DE SALUD",O40*0.0225,O40*0) -> 0 | AV40: =P40+S40+V40+Y40+AB40+AE40+AH40+AJ40 -> 0 | AW40: =AV40+AM40+AP40+AS40 -> 0
A41: 39 | P41: =ROUND(O41*$D$1,2) -> 0 | V41: =ROUND(U41*$D$1,2) -> 0 | Y41: =ROUND(X41*$D$1,2) -> 0 | AE41: =ROUND(AD41*$J$1,2) -> 0 | AJ41: =IF($O$1="SI",400,0) -> 0 | AK41: 2.1.1.9.1.3 | AL41: =IF(H41="RIMAC EPS EMPRESA PRESTADORA DE SALUD",O41*0.0675,O41*0.09) -> 0 | AM41: =ROUND(AL41*$D$1,2) -> 0 | AN41: 2.1. 3 1. 1 5 | AO41: =IF(H41="RIMAC EPS EMPRESA PRESTADORA DE SALUD",O41*0.0225,O41*0) -> 0 | AP41: =ROUND(AO41*$D$1,2) -> 0 | AV41: =P41+S41+V41+Y41+AB41+AE41+AH41+AJ41 -> 0 | AW41: =AV41+AM41+AP41+AS41 -> 0
A42: 40 | P42: =ROUND(O42*$D$1,2) -> 0 | V42: =ROUND(U42*$D$1,2) -> 0 | Y42: =ROUND(X42*$D$1,2) -> 0 | AE42: =ROUND(AD42*$J$1,2) -> 0 | AJ42: =IF($O$1="SI",400,0) -> 0 | AK42: 2.1.1.9.1.3 | AL42: =IF(H42="RIMAC EPS EMPRESA PRESTADORA DE SALUD",O42*0.0675,O42*0.09) -> 0 | AM42: =ROUND(AL42*$D$1,2) -> 0 | AN42: 2.1. 3 1. 1 5 | AO42: =IF(H42="RIMAC EPS EMPRESA PRESTADORA DE SALUD",O42*0.0225,O42*0) -> 0 | AV42: =P42+S42+V42+Y42+AB42+AE42+AH42+AJ42 -> 0 | AW42: =AV42+AM42+AP42+AS42 -> 0
...
