Workbook

Sheet 2.1meta
A1: CUADRO DE EJECUCION Y PROYECCIÓN DE GASTOS DE LA GG 2.1
A2: UE: 003 G.A AREQUIPA
A4: Meta | B4: E.G. | C4: Descripción Específica Gasto | D4: PIM (1) | E4: Certificado | F4: Compromiso Anual | G4: Ejecución Devengado UE | M4: Saldo Presupuestal | U4: Proyeccion de plazas vacantes | W4: PAGO FACTURAS EPS | X4: BENEFICIOS | Y4: TOTAL PROYECCIÓN | Z4: TOTAL EJECUCION +PROYECCION (2) | AA4: Saldo disponible ( 1-2)
G5: Enero | H5: Febrero | I5: Marzo | J5: Abril | K5: Mayo | L5: TOTAL EJECUCION | N5: Junio | O5: Julio | P5: Agosto | Q5: Setiembre | R5: Octubre | S5: Noviembre | T5: Diciembre | U5: 276 | V5: 728
A6: 0001 | D6: =SUBTOTAL(9,D7:D22) -> 0 | E6: =SUBTOTAL(9,E7:E22) -> 0 | F6: =SUBTOTAL(9,F7:F22) -> 0 | G6: =SUBTOTAL(9,G7:G22) -> 0 | H6: =SUBTOTAL(9,H7:H22) -> 0 | I6: =SUBTOTAL(9,I7:I22) -> 0 | J6: =SUBTOTAL(9,J7:J22) -> 0 | K6: =SUBTOTAL(9,K7:K22) -> 0 | L6: =SUM(G6:K6) -> 0 | M6: =D6-L6 -> 0 | N6: =SUBTOTAL(9,N7:N22) -> 0 | O6: =SUBTOTAL(9,O7:O22) -> 0 | P6: =SUBTOTAL(9,P7:P22) -> 0 | Q6: =SUBTOTAL(9,Q7:Q22) -> 0 | R6: =SUBTOTAL(9,R7:R22) -> 0 | S6: =SUBTOTAL(9,S7:S22) -> 0 | T6: =SUBTOTAL(9,T7:T22) -> 0 | U6: =SUBTOTAL(9,U7:U22) -> 0 | ... X6: =SUBTOTAL(9,X7:X22) -> 0 | Y6: =SUM(N6:X6) -> 0 | Z6: =+L6+Y6 -> 0 | AA6: =+D6-Z6 -> 0
A7: 0001 | B7: 2.1.1.1.1.2 | C7: PERSONAL ADMINISTRATIVO NOMBRADO (REGIMEN PUBLICO) | L7: =SUM(G7:K7) -> 0 | M7: =D7-L7 -> 0 | U7: 0 | V7: 0 | Y7: =SUM(N7:X7) -> 0 | Z7: =+L7+Y7 -> 0 | AA7: =+D7-Z7 -> 0
A8: 0001 | B8: 2.1.1.1.1.4 | C8: PERSONAL CON CONTRATO A PLAZO INDETERMINADO (REGIMEN | L8: =SUM(G8:K8) -> 0 | M8: =D8-L8 -> 0 | U8: 0 | V8: 0 | Y8: =SUM(N8:X8) -> 0 | Z8: =+L8+Y8 -> 0 | AA8: =+D8-Z8 -> 0
A9: 0001 | B9: 2.1.1.1.1.5 | C9: PERSONAL CON CONTRATO A PLAZO FIJO (REGIMEN LABORAL | L9: =SUM(G9:K9) -> 0 | M9: =D9-L9 -> 0 | U9: 0 | V9: 0 | Y9: =SUM(N9:X9) -> 0 | Z9: =+L9+Y9 -> 0 | AA9: =+D9-Z9 -> 0
A10: 0001 | B10: 2.1.1.1.2.1 | C10: ASIGNACION A FONDOS PARA PERSONAL | L10: =SUM(G10:K10) -> 0 | M10: =D10-L10 -> 0 | U10: 0 | V10: 0 | Y10: =SUM(N10:X10) -> 0 | Z10: =+L10+Y10 -> 0 | AA10: =+D10-Z10 -> 0
A11: 0001 | B11: 2.1.1.4.1.1 | C11: PERSONAL NOMBRADO | L11: =SUM(G11:K11) -> 0 | M11: =D11-L11 -> 0 | U11: 0 | V11: 0 | Y11: =SUM(N11:X11) -> 0 | Z11: =+L11+Y11 -> 0 | AA11: =+D11-Z11 -> 0
A12: 0001 | B12: 2.1.1.4.2.1 | C12: BONO POR FUNCION JURISDICCIONAL Y FISCAL | L12: =SUM(G12:K12) -> 0 | M12: =D12-L12 -> 0 | U12: 0 | V12: 0 | Y12: =SUM(N12:X12) -> 0 | Z12: =+L12+Y12 -> 0 | AA12: =+D12-Z12 -> 0
A13: 0001 | B13: 2.1.1.4.2.2 | C13: ASIGNACION POR GASTOS OPERATIVOS | L13: =SUM(G13:K13) -> 0 | M13: =D13-L13 -> 0 | U13: 0 | V13: 0 | Y13: =SUM(N13:X13) -> 0 | Z13: =+L13+Y13 -> 0 | AA13: =+D13-Z13 -> 0
A14: 0001 | B14: 2.1.1.9.1.1 | C14: GRATIFICACIONES | L14: =SUM(G14:K14) -> 0 | M14: =D14-L14 -> 0 | U14: 0 | V14: 0 | Y14: =SUM(N14:X14) -> 0 | Z14: =+L14+Y14 -> 0 | AA14: =+D14-Z14 -> 0
A15: 0001 | B15: 2.1.1.9.1.2 | C15: AGUINALDOS | L15: =SUM(G15:K15) -> 0 | M15: =D15-L15 -> 0 | U15: 0 | V15: 0 | Y15: =SUM(N15:X15) -> 0 | Z15: =+L15+Y15 -> 0 | AA15: =+D15-Z15 -> 0
A16: 0001 | B16: 2.1.1.9.1.3 | C16: BONIFICACION POR ESCOLARIDAD | L16: =SUM(G16:K16) -> 0 | M16: =D16-L16 -> 0 | U16: 0 | V16: 0 | Y16: =SUM(N16:X16) -> 0 | Z16: =+L16+Y16 -> 0 | AA16: =+D16-Z16 -> 0
A17: 0001 | B17: 2.1.1.9.2.1 | C17: COMPENSACION POR TIEMPO DE SERVICIOS (CTS) | L17: =SUM(G17:K17) -> 0 | M17: =D17-L17 -> 0 | U17: 0 | V17: 0 | Y17: =SUM(N17:X17) -> 0 | Z17: =+L17+Y17 -> 0 | AA17: =+D17-Z17 -> 0
A18: 0001 | B18: 2.1.1.9.3.3 | C18: COMPENSACION VACACIONAL (VACACIONES TRUNCAS) | L18: =SUM(G18:K18) -> 0 | M18: =D18-L18 -> 0 | U18: 0 | V18: 0 | Y18: =SUM(N18:X18) -> 0 | Z18: =+L18+Y18 -> 0 | AA18: =+D18-Z18 -> 0
... A22: 0001 | B22: 2.1.3.1.1.5 | C22: CONTRIBUCIONES A ESSALUD | L22: =SUM(G22:K22) -> 0 | M22: =D22-L22 -> 0 | U22: 0 | V22: 0 | Y22: =SUM(N22:X22) -> 0 | Z22: =+L22+Y22 -> 0 | AA22: =+D22-Z22 -> 0
A23: 0002 | D23: =SUBTOTAL(9,D24:D39) -> 0 | E23: =SUBTOTAL(9,E24:E39) -> 0 | F23: =SUBTOTAL(9,F24:F39) -> 0 | G23: =SUBTOTAL(9,G24:G39) -> 0 | H23: =SUBTOTAL(9,H24:H39) -> 0 | I23: =SUBTOTAL(9,I24:I39) -> 0 | J23: =SUBTOTAL(9,J24:J39) -> 0 | K23: =SUBTOTAL(9,K24:K39) -> 0 | L23: =SUM(G23:K23) -> 0 | M23: =D23-L23 -> 0 | N23: =SUBTOTAL(9,N24:N39) -> 0 | O23: =SUBTOTAL(9,O24:O39) -> 0 | P23: =SUBTOTAL(9,P24:P39) -> 0 | Q23: =SUBTOTAL(9,Q24:Q39) -> 0 | R23: =SUBTOTAL(9,R24:R39) -> 0 | S23: =SUBTOTAL(9,S24:S39) -> 0 | T23: =SUBTOTAL(9,T24:T39) -> 0 | U23: =SUBTOTAL(9,U24:U39) -> 0 | ... X23: =SUBTOTAL(9,X24:X39) -> 0 | Y23: =SUM(N23:X23) -> 0 | Z23: =+L23+Y23 -> 0 | AA23: =+D23-Z23 -> 0
A24: 0002 | B24: 2.1.1.1.1.2 | C24: PERSONAL ADMINISTRATIVO NOMBRADO (REGIMEN PUBLICO) | L24: =SUM(G24:K24) -> 0 | M24: =D24-L24 -> 0 | U24: 0 | V24: 0 | Y24: =SUM(N24:X24) -> 0 | Z24: =+L24+Y24 -> 0 | AA24: =+D24-Z24 -> 0
A25: 0002 | B25: 2.1.1.1.1.4 | C25: PERSONAL CON CONTRATO A PLAZO INDETERMINADO (REGIMEN | L25: =SUM(G25:K25) -> 0 | M25: =D25-L25 -> 0 | U25: 0 | V25: 0 | Y25: =SUM(N25:X25) -> 0 | Z25: =+L25+Y25 -> 0 | AA25: =+D25-Z25 -> 0
A26: 0002 | B26: 2.1.1.1.1.5 | C26: PERSONAL CON CONTRATO A PLAZO FIJO (REGIMEN LABORAL | L26: =SUM(G26:K26) -> 0 | M26: =D26-L26 -> 0 | U26: 0 | V26: 0 | Y26: =SUM(N26:X26) -> 0 | Z26: =+L26+Y26 -> 0 | AA26: =+D26-Z26 -> 0
A27: 0002 | B27: 2.1.1.1.2.1 | C27: ASIGNACION A FONDOS PARA PERSONAL | L27: =SUM(G27:K27) -> 0 | M27: =D27-L27 -> 0 | U27: 0 | V27: 0 | Y27: =SUM(N27:X27) -> 0 | Z27: =+L27+Y27 -> 0 | AA27: =+D27-Z27 -> 0
A28: 0002 | B28: 2.1.1.4.1.1 | C28: PERSONAL NOMBRADO | L28: =SUM(G28:K28) -> 0 | M28: =D28-L28 -> 0 | U28: 0 | V28: 0 | Y28: =SUM(N28:X28) -> 0 | Z28: =+L28+Y28 -> 0 | AA28: =+D28-Z28 -> 0
A29: 0002 | B29: 2.1.1.4.2.1 | C29: BONO POR FUNCION JURISDICCIONAL Y FISCAL | L29: =SUM(G29:K29) -> 0 | M29: =D29-L29 -> 0 | U29: 0 | V29: 0 | Y29: =SUM(N29:X29) -> 0 | Z29: =+L29+Y29 -> 0 | AA29: =+D29-Z29 -> 0
A30: 0002 | B30: 2.1.1.4.2.2 | C30: ASIGNACION POR GASTOS OPERATIVOS | L30: =SUM(G30:K30) -> 0 | M30: =D30-L30 -> 0 | U30: 0 | V30: 0 | Y30: =SUM(N30:X30) -> 0 | Z30: =+L30+Y30 -> 0 | AA30: =+D30-Z30 -> 0
A31: 0002 | B31: 2.1.1.9.1.1 | C31: GRATIFICACIONES | L31: =SUM(G31:K31) -> 0 | M31: =D31-L31 -> 0 | U31: 0 | V31: 0 | Y31: =SUM(N31:X31) -> 0 | Z31: =+L31+Y31 -> 0 | AA31: =+D31-Z31 -> 0
A32: 0002 | B32: 2.1.1.9.1.2 | C32: AGUINALDOS | L32: =SUM(G32:K32) -> 0 | M32: =D32-L32 -> 0 | U32: 0 | V32: 0 | Y32: =SUM(N32:X32) -> 0 | Z32: =+L32+Y32 -> 0 | AA32: =+D32-Z32 -> 0
A33: 0002 | B33: 2.1.1.9.1.3 | C33: BONIFICACION POR ESCOLARIDAD | L33: =SUM(G33:K33) -> 0 | M33: =D33-L33 -> 0 | U33: 0 | V33: 0 | Y33: =SUM(N33:X33) -> 0 | Z33: =+L33+Y33 -> 0 | AA33: =+D33-Z33 -> 0
A34: 0002 | B34: 2.1.1.9.2.1 | C34: COMPENSACION POR TIEMPO DE SERVICIOS (CTS) | L34: =SUM(G34:K34) -> 0 | M34: =D34-L34 -> 0 | U34: 0 | V34: 0 | Y34: =SUM(N34:X34) -> 0 | Z34: =+L34+Y34 -> 0 | AA34: =+D34-Z34 -> 0
A35: 0002 | B35: 2.1.1.9.3.3 | C35: COMPENSACION VACACIONAL (VACACIONES TRUNCAS) | L35: =SUM(G35:K35) -> 0 | M35: =D35-L35 -> 0 | U35: 0 | V35: 0 | Y35: =SUM(N35:X35) -> 0 | Z35: =+L35+Y35 -> 0 | AA35: =+D35-Z35 -> 0
... A39: 0002 | B39: 2.1.3.1.1.5 | C39: CONTRIBUCIONES A ESSALUD | L39: =SUM(G39:K39) -> 0 | M39: =D39-L39 -> 0 | U39: 0 | V39: 0 | Y39: =SUM(N39:X39) -> 0 | Z39: =+L39+Y39 -> 0 | AA39: =+D39-Z39 -> 0
A40: 0003 | D40: =SUBTOTAL(9,D41:D56) -> 0 | E40: =SUBTOTAL(9,E41:E56) -> 0 | F40: =SUBTOTAL(9,F41:F56) -> 0 | G40: =SUBTOTAL(9,G41:G56) -> 0 | H40: =SUBTOTAL(9,H41:H56) -> 0 | I40: =SUBTOTAL(9,I41:I56) -> 0 | J40: =SUBTOTAL(9,J41:J56) -> 0 | K40: =SUBTOTAL(9,K41:K56) -> 0 | L40: =SUM(G40:K40) -> 0 | M40: =D40-L40 -> 0 | N40: =SUBTOTAL(9,N41:N56) -> 0 | O40: =SUBTOTAL(9,O41:O56) -> 0 | P40: =SUBTOTAL(9,P41:P56) -> 0 | Q40: =SUBTOTAL(9,Q41:Q56) -> 0 | R40: =SUBTOTAL(9,R41:R56) -> 0 | S40: =SUBTOTAL(9,S41:S56) -> 0 | T40: =SUBTOTAL(9,T41:T56) -> 0 | U40: =SUBTOTAL(9,U41:U56) -> 0 | ... X40: =SUBTOTAL(9,X41:X56) -> 0 | Y40: =SUM(N40:X40) -> 0 | Z40: =+L40+Y40 -> 0 | AA40: =+D40-Z40 -> 0
A41: 0003 | B41: 2.1.1.1.1.2 | C41: PERSONAL ADMINISTRATIVO NOMBRADO (REGIMEN PUBLICO) | L41: =SUM(G41:K41) -> 0 | M41: =D41-L41 -> 0 | U41: 0 | V41: 0 | Y41: =SUM(N41:X41) -> 0 | Z41: =+L41+Y41 -> 0 | AA41: =+D41-Z41 -> 0
A42: 0003 | B42: 2.1.1.1.1.4 | C42: PERSONAL CON CONTRATO A PLAZO INDETERMINADO (REGIMEN | L42: =SUM(G42:K42) -> 0 | M42: =D42-L42 -> 0 | U42: 0 | V42: 0 | Y42: =SUM(N42:X42) -> 0 | Z42: =+L42+Y42 -> 0 | AA42: =+D42-Z42 -> 0
A43: 0003 | B43: 2.1.1.1.1.5 | C43: PERSONAL CON CONTRATO A PLAZO FIJO (REGIMEN LABORAL | L43: =SUM(G43:K43) -> 0 | M43: =D43-L43 -> 0 | U43: 0 | V43: 0 | Y43: =SUM(N43:X43) -> 0 | Z43: =+L43+Y43 -> 0 | AA43: =+D43-Z43 -> 0
A44: 0003 | B44: 2.1.1.1.2.1 | C44: ASIGNACION A FONDOS PARA PERSONAL | L44: =SUM(G44:K44) -> 0 | M44: =D44-L44 -> 0 | U44: 0 | V44: 0 | Y44: =SUM(N44:X44) -> 0 | Z44: =+L44+Y44 -> 0 | AA44: =+D44-Z44 -> 0
A45: 0003 | B45: 2.1.1.4.1.1 | C45: PERSONAL NOMBRADO | L45: =SUM(G45:K45) -> 0 | M45: =D45-L45 -> 0 | U45: 0 | V45: 0 | Y45: =SUM(N45:X45) -> 0 | Z45: =+L45+Y45 -> 0 | AA45: =+D45-Z45 -> 0
A46: 0003 | B46: 2.1.1.4.2.1 | C46: BONO POR FUNCION JURISDICCIONAL Y FISCAL | L46: =SUM(G46:K46) -> 0 | M46: =D46-L46 -> 0 | U46: 0 | V46: 0 | Y46: =SUM(N46:X46) -> 0 | Z46: =+L46+Y46 -> 0 | AA46: =+D46-Z46 -> 0
A47: 0003 | B47: 2.1.1.4.2.2 | C47: ASIGNACION POR GASTOS OPERATIVOS | L47: =SUM(G47:K47) -> 0 | M47: =D47-L47 -> 0 | U47: 0 | V47: 0 | Y47: =SUM(N47:X47) -> 0 | Z47: =+L47+Y47 -> 0 | AA47: =+D47-Z47 -> 0
...

Sheet CATEGORIA PRESUPUESTAL
A1: EJECUTORA: 0003 MINISTERIO PUBLICO - GERENCIA ADMINISTRATIVA DE AREQUIPA (1419)
A3: Cat pptal/ Detalle Específica de Gasto | C3: PIM | D3: Certificado | E3: Compromiso Anual | F3: Ejecución Devengado UE | K3: T O T A L | L3: Saldo Presupuestal al 17.09.2021 | T3: Proyeccion de plazas vacantes | V3: PAGO FACTURAS EPS | W3: BENEFICIOS | X3: TOTAL PROYECCION | Y3: TOTAL EJECUCION +PROYECCION | Z3: SALDO DISPONIBLE
F4: 01 ENERO | G4: 02 FEBRERO | H4: 03 MARZO | I4: 04 ABRIL | J4: 05 MAYO | M4: 06 JUNIO | N4: 07 JULIO | O4: 08 AGOSTO | P4: 09 SETIEMBRE | Q4: 10 OCTUBRE | R4: 11 NOVIEMBRE | S4: 12 DICIEMBRE | T4: 276 | U4: 728
A5: 0086 MEJORA DE LOS SERVICIOS DEL SISTEMA DE JUSTICIA PENAL | C5: =SUBTOTAL(9,C6:C22) -> 0 | D5: =SUBTOTAL(9,D6:D22) -> 0 | E5: =SUBTOTAL(9,E6:E22) -> 0 | F5: =SUBTOTAL(9,F6:F22) -> 0 | G5: =SUBTOTAL(9,G6:G22) -> 0 | H5: =SUBTOTAL(9,H6:H22) -> 0 | I5: =SUBTOTAL(9,I6:I22) -> 0 | J5: =SUBTOTAL(9,J6:J22) -> 0 | K5: =SUBTOTAL(9,K6:K22) -> 0 | L5: =C5-K5 -> 0 | M5: =SUBTOTAL(9,M6:M22) -> 0 | N5: =SUBTOTAL(9,N6:N22) -> 0 | O5: =SUBTOTAL(9,O6:O22) -> 0 | P5: =SUBTOTAL(9,P6:P22) -> 0 | Q5: =SUBTOTAL(9,Q6:Q22) -> 0 | R5: =SUBTOTAL(9,R6:R22) -> 0 | S5: =SUBTOTAL(9,S6:S22) -> 0 | T5: =SUBTOTAL(9,T6:T22) -> 0 | ... Z5: =SUBTOTAL(9,Z6:Z22) -> 0
A6: 2.1.1.1.1.2 | B6: PERSONAL ADMINISTRATIVO NOMBRADO (REGIMEN PUBLICO) | C6: ='2.1meta'!D7+'2.1meta'!D24+'2.1meta'!D41+'2.1meta'!D58+'2.1meta'!D76+'2.1meta'!D93+'2.1meta'!D110+'2.1meta'!D127+'2.1meta'!D144+'2.1meta'!D161+'2.1meta'!D178+'2.1meta'!D288+'2.1meta'!D305+'2.1meta'!D322 -> 0 | D6: ='2.1meta'!E7+'2.1meta'!E24+'2.1meta'!E41+'2.1meta'!E58+'2.1meta'!E76+'2.1meta'!E93+'2.1meta'!E110+'2.1meta'!E127+'2.1meta'!E144+'2.1meta'!E161+'2.1meta'!E178+'2.1meta'!E288+'2.1meta'!E305+'2.1meta'!E322 -> 0 | E6: ='2.1meta'!F7+'2.1meta'!F24+'2.1meta'!F41+'2.1meta'!F58+'2.1meta'!F76+'2.1meta'!F93+'2.1meta'!F110+'2.1meta'!F127+'2.1meta'!F144+'2.1meta'!F161+'2.1meta'!F178+'2.1meta'!F288+'2.1meta'!F305+'2.1meta'!F322 -> 0 | F6: ='2.1meta'!G7+'2.1meta'!G24+'2.1meta'!G41+'2.1meta'!G58+'2.1meta'!G76+'2.1meta'!G93+'2.1meta'!G110+'2.1meta'!G127+'2.1meta'!G144+'2.1meta'!G161+'2.1meta'!G178+'2.1meta'!G288+'2.1meta'!G305+'2.1meta'!G322 -> 0 | G6: ='2.1meta'!H7+'2.1meta'!H24+'2.1meta'!H41+'2.1meta'!H58+'2.1meta'!H76+'2.1meta'!H93+'2.1meta'!H110+'2.1meta'!H127+'2.1meta'!H144+'2.1meta'!H161+'2.1meta'!H178+'2.1meta'!H288+'2.1meta'!H305+'2.1meta'!H322 -> 0 | H6: ='2.1meta'!I7+'2.1meta'!I24+'2.1meta'!I41+'2.1meta'!I58+'2.1meta'!I76+'2.1meta'!I93+'2.1meta'!I110+'2.1meta'!I127+'2.1meta'!I144+'2.1meta'!I161+'2.1meta'!I178+'2.1meta'!I288+'2.1meta'!I305+'2.1meta'!I322 -> 0 | I6: ='2.1meta'!J7+'2.1meta'!J24+'2.1meta'!J41+'2.1meta'!J58+'2.1meta'!J76+'2.1meta'!J93+'2.1meta'!J110+'2.1meta'!J127+'2.1meta'!J144+'2.1meta'!J161+'2.1meta'!J178+'2.1meta'!J288+'2.1meta'!J305+'2.1meta'!J322 -> 0 | J6: ='2.1meta'!K7+'2.1meta'!K24+'2.1meta'!K41+'2.1meta'!K58+'2.1meta'!K76+'2.1meta'!K93+'2.1meta'!K110+'2.1meta'!K127+'2.1meta'!K144+'2.1meta'!K161+'2.1meta'!K178+'2.1meta'!K288+'2.1meta'!K305+'2.1meta'!K322 -> 0 | K6: =SUM(F6:J6) -> 0 | L6: =C6-K6 -> 0 | M6: ='2.1meta'!N7+'2.1meta'!N24+'2.1meta'!N41+'2.1meta'!N58+'2.1meta'!N76+'2.1meta'!N93+'2.1meta'!N110+'2.1meta'!N127+'2.1meta'!N144+'2.1meta'!N161+'2.1meta'!N178+'2.1meta'!N288+'2.1meta'!N305+'2.1meta'!N322 -> 0 | N6: ='2.1meta'!O7+'2.1meta'!O24+'2.1meta'!O41+'2.1meta'!O58+'2.1meta'!O76+'2.1meta'!O93+'2.1meta'!O110+'2.1meta'!O127+'2.1meta'!O144+'2.1meta'!O161+'2.1meta'!O178+'2.1meta'!O288+'2.1meta'!O305+'2.1meta'!O322 -> 0 | O6: ='2.1meta'!P7+'2.1meta'!P24+'2.1meta'!P41+'2.1meta'!P58+'2.1meta'!P76+'2.1meta'!P93+'2.1meta'!P110+'2.1meta'!P127+'2.1meta'!P144+'2.1meta'!P161+'2.1meta'!P178+'2.1meta'!P288+'2.1meta'!P305+'2.1meta'!P322 -> 0 | P6: ='2.1meta'!Q7+'2.1meta'!Q24+'2.1meta'!Q41+'2.1meta'!Q58+'2.1meta'!Q76+'2.1meta'!Q93+'2.1meta'!Q110+'2.1meta'!Q127+'2.1meta'!Q144+'2.1meta'!Q161+'2.1meta'!Q178+'2.1meta'!Q288+'2.1meta'!Q305+'2.1meta'!Q322 -> 0 | Q6: ='2.1meta'!R7+'2.1meta'!R24+'2.1meta'!R41+'2.1meta'!R58+'2.1meta'!R76+'2.1meta'!R93+'2.1meta'!R110+'2.1meta'!R127+'2.1meta'!R144+'2.1meta'!R161+'2.1meta'!R178+'2.1meta'!R288+'2.1meta'!R305+'2.1meta'!R322 -> 0 | R6: ='2.1meta'!S7+'2.1meta'!S24+'2.1meta'!S41+'2.1meta'!S58+'2.1meta'!S76+'2.1meta'!S93+'2.1meta'!S110+'2.1meta'!S127+'2.1meta'!S144+'2.1meta'!S161+'2.1meta'!S178+'2.1meta'!S288+'2.1meta'!S305+'2.1meta'!S322 -> 0 | S6: ='2.1meta'!T7+'2.1meta'!T24+'2.1meta'!T41+'2.1meta'!T58+'2.1meta'!T76+'2.1meta'!T93+'2.1meta'!T110+'2.1meta'!T127+'2.1meta'!T144+'2.1meta'!T161+'2.1meta'!T178+'2.1meta'!T288+'2.1meta'!T305+'2.1meta'!T322 -> 0 | T6: ='2.1meta'!U7+'2.1meta'!U24+'2.1meta'!U41+'2.1meta'!U58+'2.1meta'!U76+'2.1meta'!U93+'2.1meta'!U110+'2.1meta'!U127+'2.1meta'!U144+'2.1meta'!U161+'2.1meta'!U178+'2.1meta'!U288+'2.1meta'!U305+'2.1meta'!U322 -> 0 | ... W6: ='2.1meta'!X7+'2.1meta'!X24+'2.1meta'!X41+'2.1meta'!X58+'2.1meta'!X76+'2.1meta'!X93+'2.1meta'!X110+'2.1meta'!X127+'2.1meta'!X144+'2.1meta'!X161+'2.1meta'!X178+'2.1meta'!X288+'2.1meta'!X305+'2.1meta'!X322 -> 0 | X6: =SUM(M6:W6) -> 0 | Y6: =K6+X6 -> 0 | Z6: =C6-Y6 -> 0
A7: 2.1.1.1.1.4 | B7: PERSONAL CON CONTRATO A PLAZO INDETERMINADO (REGIMEN LABORAL PRIVADO) | C7: ='2.1meta'!D8+'2.1meta'!D25+'2.1meta'!D42+'2.1meta'!D59+'2.1meta'!D77+'2.1meta'!D94+'2.1meta'!D111+'2.1meta'!D128+'2.1meta'!D145+'2.1meta'!D162+'2.1meta'!D179+'2.1meta'!D289+'2.1meta'!D306+'2.1meta'!D323 -> 0 | D7: ='2.1meta'!E8+'2.1meta'!E25+'2.1meta'!E42+'2.1meta'!E59+'2.1meta'!E77+'2.1meta'!E94+'2.1meta'!E111+'2.1meta'!E128+'2.1meta'!E145+'2.1meta'!E162+'2.1meta'!E179+'2.1meta'!E289+'2.1meta'!E306+'2.1meta'!E323 -> 0 | E7: ='2.1meta'!F8+'2.1meta'!F25+'2.1meta'!F42+'2.1meta'!F59+'2.1meta'!F77+'2.1meta'!F94+'2.1meta'!F111+'2.1meta'!F128+'2.1meta'!F145+'2.1meta'!F162+'2.1meta'!F179+'2.1meta'!F289+'2.1meta'!F306+'2.1meta'!F323 -> 0 | F7: ='2.1meta'!G8+'2.1meta'!G25+'2.1meta'!G42+'2.1meta'!G59+'2.1meta'!G77+'2.1meta'!G94+'2.1meta'!G111+'2.1meta'!G128+'2.1meta'!G145+'2.1meta'!G162+'2.1meta'!G179+'2.1meta'!G289+'2.1meta'!G306+'2.1meta'!G323 -> 0 | G7: ='2.1meta'!H8+'2.1meta'!H25+'2.1meta'!H42+'2.1meta'!H59+'2.1meta'!H77+'2.1meta'!H94+'2.1meta'!H111+'2.1meta'!H128+'2.1meta'!H145+'2.1meta'!H162+'2.1meta'!H179+'2.1meta'!H289+'2.1meta'!H306+'2.1meta'!H323 -> 0 | H7: ='2.1meta'!I8+'2.1meta'!I25+'2.1meta'!I42+'2.1meta'!I59+'2.1meta'!I77+'2.1meta'!I94+'2.1meta'!I111+'2.1meta'!I128+'2.1meta'!I145+'2.1meta'!I162+'2.1meta'!I179+'2.1meta'!I289+'2.1meta'!I306+'2.1meta'!I323 -> 0 | I7: ='2.1meta'!J8+'2.1meta'!J25+'2.1meta'!J42+'2.1meta'!J59+'2.1meta'!J77+'2.1meta'!J94+'2.1meta'!J111+'2.1meta'!J128+'2.1meta'!J145+'2.1meta'!J162+'2.1meta'!J179+'2.1meta'!J289+'2.1meta'!J306+'2.1meta'!J323 -> 0 | J7: ='2.1meta'!K8+'2.1meta'!K25+'2.1meta'!K42+'2.1meta'!K59+'2.1meta'!K77+'2.1meta'!K94+'2.1meta'!K111+'2.1meta'!K128+'2.1meta'!K145+'2.1meta'!K162+'2.1meta'!K179+'2.1meta'!K289+'2.1meta'!K306+'2.1meta'!K323 -> 0 | K7: =SUM(F7:J7) -> 0 | L7: =C7-K7 -> 0 | M7: ='2.1meta'!N8+'2.1meta'!N25+'2.1meta'!N42+'2.1meta'!N59+'2.1meta'!N77+'2.1meta'!N94+'2.1meta'!N111+'2.1meta'!N128+'2.1meta'!N145+'2.1meta'!N162+'2.1meta'!N179+'2.1meta'!N289+'2.1meta'!N306+'2.1meta'!N323 -> 0 | N7: ='2.1meta'!O8+'2.1meta'!O25+'2.1meta'!O42+'2.1meta'!O59+'2.1meta'!O77+'2.1meta'!O94+'2.1meta'!O111+'2.1meta'!O128+'2.1meta'!O145+'2.1meta'!O162+'2.1meta'!O179+'2.1meta'!O289+'2.1meta'!O306+'2.1meta'!O323 -> 0 | O7: ='2.1meta'!P8+'2.1meta'!P25+'2.1meta'!P42+'2.1meta'!P59+'2.1meta'!P77+'2.1meta'!P94+'2.1meta'!P111+'2.1meta'!P128+'2.1meta'!P145+'2.1meta'!P162+'2.1meta'!P179+'2.1meta'!P289+'2.1meta'!P306+'2.1meta'!P323 -> 0 | P7: ='2.1meta'!Q8+'2.1meta'!Q25+'2.1meta'!Q42+'2.1meta'!Q59+'2.1meta'!Q77+'2.1meta'!Q94+'2.1meta'!Q111+'2.1meta'!Q128+'2.1meta'!Q145+'2.1meta'!Q162+'2.1meta'!Q179+'2.1meta'!Q289+'2.1meta'!Q306+'2.1meta'!Q323 -> 0 | Q7: ='2.1meta'!R8+'2.1meta'!R25+'2.1meta'!R42+'2.1meta'!R59+'2.1meta'!R77+'2.1meta'!R94+'2.1meta'!R111+'2.1meta'!R128+'2.1meta'!R145+'2.1meta'!R162+'2.1meta'!R179+'2.1meta'!R289+'2.1meta'!R306+'2.1meta'!R323 -> 0 | R7: ='2.1meta'!S8+'2.1meta'!S25+'2.1meta'!S42+'2.1meta'!S59+'2.1meta'!S77+'2.1meta'!S94+'2.1meta'!S111+'2.1meta'!S128+'2.1meta'!S145+'2.1meta'!S162+'2.1meta'!S179+'2.1meta'!S289+'2.1meta'!S306+'2.1meta'!S323 -> 0 | S7: ='2.1meta'!T8+'2.1meta'!T25+'2.1meta'!T42+'2.1meta'!T59+'2.1meta'!T77+'2.1meta'!T94+'2.1meta'!T111+'2.1meta'!T128+'2.1meta'!T145+'2.1meta'!T162+'2.1meta'!T179+'2.1meta'!T289+'2.1meta'!T306+'2.1meta'!T323 -> 0 | T7: ='2.1meta'!U8+'2.1meta'!U25+'2.1meta'!U42+'2.1meta'!U59+'2.1meta'!U77+'2.1meta'!U94+'2.1meta'!U111+'2.1meta'!U128+'2.1meta'!U145+'2.1meta'!U162+'2.1meta'!U179+'2.1meta'!U289+'2.1meta'!U306+'2.1meta'!U323 -> 0 | ... W7: ='2.1meta'!X8+'2.1meta'!X25+'2.1meta'!X42+'2.1meta'!X59+'2.1meta'!X77+'2.1meta'!X94+'2.1meta'!X111+'2.1meta'!X128+'2.1meta'!X145+'2.1meta'!X162+'2.1meta'!X179+'2.1meta'!X289+'2.1meta'!X306+'2.1meta'!X323 -> 0 | X7: =SUM(M7:W7) -> 0 | Y7: =K7+X7 -> 0 | Z7: =C7-Y7 -> 0
A8: 2.1.1.1.1.5 | B8: PERSONAL CON CONTRATO A PLAZO FIJO (REGIMEN LABORAL PRIVADO) | C8: ='2.1meta'!D9+'2.1meta'!D26+'2.1meta'!D43+'2.1meta'!D60+'2.1meta'!D78+'2.1meta'!D95+'2.1meta'!D112+'2.1meta'!D129+'2.1meta'!D146+'2.1meta'!D163+'2.1meta'!D180+'2.1meta'!D290+'2.1meta'!D307+'2.1meta'!D324 -> 0 | D8: ='2.1meta'!E8+'2.1meta'!E25+'2.1meta'!E42+'2.1meta'!E60+'2.1meta'!E77+'2.1meta'!E94+'2.1meta'!E111+'2.1meta'!E128+'2.1meta'!E145+'2.1meta'!E162+'2.1meta'!E179+'2.1meta'!E289+'2.1meta'!E306+'2.1meta'!E323 -> 0 | E8: ='2.1meta'!F8+'2.1meta'!F25+'2.1meta'!F42+'2.1meta'!F60+'2.1meta'!F77+'2.1meta'!F94+'2.1meta'!F111+'2.1meta'!F128+'2.1meta'!F145+'2.1meta'!F162+'2.1meta'!F179+'2.1meta'!F289+'2.1meta'!F306+'2.1meta'!F323 -> 0 | F8: ='2.1meta'!G9+'2.1meta'!G26+'2.1meta'!G43+'2.1meta'!G60+'2.1meta'!G78+'2.1meta'!G95+'2.1meta'!G112+'2.1meta'!G129+'2.1meta'!G146+'2.1meta'!G163+'2.1meta'!G180+'2.1meta'!G290+'2.1meta'!G307+'2.1meta'!G324 -> 0 | G8: ='2.1meta'!H9+'2.1meta'!H26+'2.1meta'!H43+'2.1meta'!H60+'2.1meta'!H78+'2.1meta'!H95+'2.1meta'!H112+'2.1meta'!H129+'2.1meta'!H146+'2.1meta'!H163+'2.1meta'!H180+'2.1meta'!H290+'2.1meta'!H307+'2.1meta'!H324 -> 0 | H8: ='2.1meta'!I9+'2.1meta'!I26+'2.1meta'!I43+'2.1meta'!I60+'2.1meta'!I78+'2.1meta'!I95+'2.1meta'!I112+'2.1meta'!I129+'2.1meta'!I146+'2.1meta'!I163+'2.1meta'!I180+'2.1meta'!I290+'2.1meta'!I307+'2.1meta'!I324 -> 0 | I8: ='2.1meta'!J9+'2.1meta'!J26+'2.1meta'!J43+'2.1meta'!J60+'2.1meta'!J78+'2.1meta'!J95+'2.1meta'!J112+'2.1meta'!J129+'2.1meta'!J146+'2.1meta'!J163+'2.1meta'!J180+'2.1meta'!J290+'2.1meta'!J307+'2.1meta'!J324 -> 0 | J8: ='2.1meta'!K9+'2.1meta'!K26+'2.1meta'!K43+'2.1meta'!K60+'2.1meta'!K78+'2.1meta'!K95+'2.1meta'!K112+'2.1meta'!K129+'2.1meta'!K146+'2.1meta'!K163+'2.1meta'!K180+'2.1meta'!K290+'2.1meta'!K307+'2.1meta'!K324 -> 0 | K8: =SUM(F8:J8) -> 0 | L8: =C8-K8 -> 0 | M8: ='2.1meta'!N9+'2.1meta'!N26+'2.1meta'!N43+'2.1meta'!N60+'2.1meta'!N78+'2.1meta'!N95+'2.1meta'!N112+'2.1meta'!N129+'2.1meta'!N146+'2.1meta'!N163+'2.1meta'!N180+'2.1meta'!N290+'2.1meta'!N307+'2.1meta'!N324 -> 0 | N8: ='2.1meta'!O9+'2.1meta'!O26+'2.1meta'!O43+'2.1meta'!O60+'2.1meta'!O78+'2.1meta'!O95+'2.1meta'!O112+'2.1meta'!O129+'2.1meta'!O146+'2.1meta'!O163+'2.1meta'!O180+'2.1meta'!O290+'2.1meta'!O307+'2.1meta'!O324 -> 0 | O8: ='2.1meta'!P9+'2.1meta'!P26+'2.1meta'!P43+'2.1meta'!P60+'2.1meta'!P78+'2.1meta'!P95+'2.1meta'!P112+'2.1meta'!P129+'2.1meta'!P146+'2.1meta'!P163+'2.1meta'!P180+'2.1meta'!P290+'2.1meta'!P307+'2.1meta'!P324 -> 0 | P8: ='2.1meta'!Q9+'2.1meta'!Q26+'2.1meta'!Q43+'2.1meta'!Q60+'2.1meta'!Q78+'2.1meta'!Q95+'2.1meta'!Q112+'2.1meta'!Q129+'2.1meta'!Q146+'2.1meta'!Q163+'2.1meta'!Q180+'2.1meta'!Q290+'2.1meta'!Q307+'2.1meta'!Q324 -> 0 | Q8: ='2.1meta'!R9+'2.1meta'!R26+'2.1meta'!R43+'2.1meta'!R60+'2.1meta'!R78+'2.1meta'!R95+'2.1meta'!R112+'2.1meta'!R129+'2.1meta'!R146+'2.1meta'!R163+'2.1meta'!R180+'2.1meta'!R290+'2.1meta'!R307+'2.1meta'!R324 -> 0 | R8: ='2.1meta'!S9+'2.1meta'!S26+'2.1meta'!S43+'2.1meta'!S60+'2.1meta'!S78+'2.1meta'!S95+'2.1meta'!S112+'2.1meta'!S129+'2.1meta'!S146+'2.1meta'!S163+'2.1meta'!S180+'2.1meta'!S290+'2.1meta'!S307+'2.1meta'!S324 -> 0 | S8: ='2.1meta'!T9+'2.1meta'!T26+'2.1meta'!T43+'2.1meta'!T60+'2.1meta'!T78+'2.1meta'!T95+'2.1meta'!T112+'2.1meta'!T129+'2.1meta'!T146+'2.1meta'!T163+'2.1meta'!T180+'2.1meta'!T290+'2.1meta'!T307+'2.1meta'!T324 -> 0 | T8: ='2.1meta'!U9+'2.1meta'!U26+'2.1meta'!U43+'2.1meta'!U60+'2.1meta'!U78+'2.1meta'!U95+'2.1meta'!U112+'2.1meta'!U129+'2.1meta'!U146+'2.1meta'!U163+'2.1meta'!U180+'2.1meta'!U290+'2.1meta'!U307+'2.1meta'!U324 -> 0 | ... W8: ='2.1meta'!X9+'2.1meta'!X26+'2.1meta'!X43+'2.1meta'!X60+'2.1meta'!X78+'2.1meta'!X95+'2.1meta'!X112+'2.1meta'!X129+'2.1meta'!X146+'2.1meta'!X163+'2.1meta'!X180+'2.1meta'!X290+'2.1meta'!X307+'2.1meta'!X324 -> 0 | X8: =SUM(M8:W8) -> 0 | Y8: =K8+X8 -> 0 | Z8: =C8-Y8 -> 0
A9: 2.1.1.1.2.1 | B9: ASIGNACION A FONDOS PARA PERSONAL | C9: ='2.1meta'!D10+'2.1meta'!D27+'2.1meta'!D44+'2.1meta'!D61+'2.1meta'!D79+'2.1meta'!D96+'2.1meta'!D113+'2.1meta'!D130+'2.1meta'!D147+'2.1meta'!D164+'2.1meta'!D181+'2.1meta'!D291+'2.1meta'!D308+'2.1meta'!D325 -> 0 | D9: ='2.1meta'!E9+'2.1meta'!E26+'2.1meta'!E43+'2.1meta'!E61+'2.1meta'!E78+'2.1meta'!E95+'2.1meta'!E112+'2.1meta'!E129+'2.1meta'!E146+'2.1meta'!E163+'2.1meta'!E180+'2.1meta'!E290+'2.1meta'!E307+'2.1meta'!E324 -> 0 | E9: ='2.1meta'!F9+'2.1meta'!F26+'2.1meta'!F43+'2.1meta'!F61+'2.1meta'!F78+'2.1meta'!F95+'2.1meta'!F112+'2.1meta'!F129+'2.1meta'!F146+'2.1meta'!F163+'2.1meta'!F180+'2.1meta'!F290+'2.1meta'!F307+'2.1meta'!F324 -> 0 | F9: ='2.1meta'!G10+'2.1meta'!G27+'2.1meta'!G44+'2.1meta'!G61+'2.1meta'!G79+'2.1meta'!G96+'2.1meta'!G113+'2.1meta'!G130+'2.1meta'!G147+'2.1meta'!G164+'2.1meta'!G181+'2.1meta'!G291+'2.1meta'!G308+'2.1meta'!G325 -> 0 | G9: ='2.1meta'!H10+'2.1meta'!H27+'2.1meta'!H44+'2.1meta'!H61+'2.1meta'!H79+'2.1meta'!H96+'2.1meta'!H113+'2.1meta'!H130+'2.1meta'!H147+'2.1meta'!H164+'2.1meta'!H181+'2.1meta'!H291+'2.1meta'!H308+'2.1meta'!H325 -> 0 | H9: ='2.1meta'!I10+'2.1meta'!I27+'2.1meta'!I44+'2.1meta'!I61+'2.1meta'!I79+'2.1meta'!I96+'2.1meta'!I113+'2.1meta'!I130+'2.1meta'!I147+'2.1meta'!I164+'2.1meta'!I181+'2.1meta'!I291+'2.1meta'!I308+'2.1meta'!I325 -> 0 | I9: ='2.1meta'!J10+'2.1meta'!J27+'2.1meta'!J44+'2.1meta'!J61+'2.1meta'!J79+'2.1meta'!J96+'2.1meta'!J113+'2.1meta'!J130+'2.1meta'!J147+'2.1meta'!J164+'2.1meta'!J181+'2.1meta'!J291+'2.1meta'!J308+'2.1meta'!J325 -> 0 | J9: ='2.1meta'!K10+'2.1meta'!K27+'2.1meta'!K44+'2.1meta'!K61+'2.1meta'!K79+'2.1meta'!K96+'2.1meta'!K113+'2.1meta'!K130+'2.1meta'!K147+'2.1meta'!K164+'2.1meta'!K181+'2.1meta'!K291+'2.1meta'!K308+'2.1meta'!K325 -> 0 | K9: =SUM(F9:J9) -> 0 | L9: =C9-K9 -> 0 | M9: ='2.1meta'!N10+'2.1meta'!N27+'2.1meta'!N44+'2.1meta'!N61+'2.1meta'!N79+'2.1meta'!N96+'2.1meta'!N113+'2.1meta'!N130+'2.1meta'!N147+'2.1meta'!N164+'2.1meta'!N181+'2.1meta'!N291+'2.1meta'!N308+'2.1meta'!N325 -> 0 | N9: ='2.1meta'!O10+'2.1meta'!O27+'2.1meta'!O44+'2.1meta'!O61+'2.1meta'!O79+'2.1meta'!O96+'2.1meta'!O113+'2.1meta'!O130+'2.1meta'!O147+'2.1meta'!O164+'2.1meta'!O181+'2.1meta'!O291+'2.1meta'!O308+'2.1meta'!O325 -> 0 | O9: ='2.1meta'!P10+'2.1meta'!P27+'2.1meta'!P44+'2.1meta'!P61+'2.1meta'!P79+'2.1meta'!P96+'2.1meta'!P113+'2.1meta'!P130+'2.1meta'!P147+'2.1meta'!P164+'2.1meta'!P181+'2.1meta'!P291+'2.1meta'!P308+'2.1meta'!P325 -> 0 | P9: ='2.1meta'!Q10+'2.1meta'!Q27+'2.1meta'!Q44+'2.1meta'!Q61+'2.1meta'!Q79+'2.1meta'!Q96+'2.1meta'!Q113+'2.1meta'!Q130+'2.1meta'!Q147+'2.1meta'!Q164+'2.1meta'!Q181+'2.1meta'!Q291+'2.1meta'!Q308+'2.1meta'!Q325 -> 0 | Q9: ='2.1meta'!R10+'2.1meta'!R27+'2.1meta'!R44+'2.1meta'!R61+'2.1meta'!R79+'2.1meta'!R96+'2.1meta'!R113+'2.1meta'!R130+'2.1meta'!R147+'2.1meta'!R164+'2.1meta'!R181+'2.1meta'!R291+'2.1meta'!R308+'2.1meta'!R325 -> 0 | R9: ='2.1meta'!S10+'2.1meta'!S27+'2.1meta'!S44+'2.1meta'!S61+'2.1meta'!S79+'2.1meta'!S96+'2.1meta'!S113+'2.1meta'!S130+'2.1meta'!S147+'2.1meta'!S164+'2.1meta'!S181+'2.1meta'!S291+'2.1meta'!S308+'2.1meta'!S325 -> 0 | S9: ='2.1meta'!T10+'2.1meta'!T27+'2.1meta'!T44+'2.1meta'!T61+'2.1meta'!T79+'2.1meta'!T96+'2.1meta'!T113+'2.1meta'!T130+'2.1meta'!T147+'2.1meta'!T164+'2.1meta'!T181+'2.1meta'!T291+'2.1meta'!T308+'2.1meta'!T325 -> 0 | T9: ='2.1meta'!U10+'2.1meta'!U27+'2.1meta'!U44+'2.1meta'!U61+'2.1meta'!U79+'2.1meta'!U96+'2.1meta'!U113+'2.1meta'!U130+'2.1meta'!U147+'2.1meta'!U164+'2.1meta'!U181+'2.1meta'!U291+'2.1meta'!U308+'2.1meta'!U325 -> 0 | ... W9: ='2.1meta'!X10+'2.1meta'!X27+'2.1meta'!X44+'2.1meta'!X61+'2.1meta'!X79+'2.1meta'!X96+'2.1meta'!X113+'2.1meta'!X130+'2.1meta'!X147+'2.1meta'!X164+'2.1meta'!X181+'2.1meta'!X291+'2.1meta'!X308+'2.1meta'!X325 -> 0 | X9: =SUM(M9:W9) -> 0 | Y9: =K9+X9 -> 0 | Z9: =C9-Y9 -> 0
A10: 2.1.1.3.1.2 | B10: PERSONAL CONTRATADO | C10: ='2.1meta'!D62 -> 0 | D10: ='2.1meta'!E10+'2.1meta'!E27+'2.1meta'!E44+'2.1meta'!E62+'2.1meta'!E79+'2.1meta'!E96+'2.1meta'!E113+'2.1meta'!E130+'2.1meta'!E147+'2.1meta'!E164+'2.1meta'!E181+'2.1meta'!E291+'2.1meta'!E308+'2.1meta'!E325 -> 0 | E10: ='2.1meta'!F10+'2.1meta'!F27+'2.1meta'!F44+'2.1meta'!F62+'2.1meta'!F79+'2.1meta'!F96+'2.1meta'!F113+'2.1meta'!F130+'2.1meta'!F147+'2.1meta'!F164+'2.1meta'!F181+'2.1meta'!F291+'2.1meta'!F308+'2.1meta'!F325 -> 0 | F10: ='2.1meta'!G62 -> 0 | G10: ='2.1meta'!H62 -> 0 | H10: ='2.1meta'!I62 -> 0 | I10: ='2.1meta'!J62 -> 0 | J10: ='2.1meta'!K62 -> 0 | K10: =SUM(F10:J10) -> 0 | L10: =C10-K10 -> 0 | M10: ='2.1meta'!N62 -> 0 | N10: ='2.1meta'!O62 -> 0 | O10: ='2.1meta'!P62 -> 0 | P10: ='2.1meta'!Q62 -> 0 | Q10: ='2.1meta'!R62 -> 0 | R10: ='2.1meta'!S62 -> 0 | S10: ='2.1meta'!T62 -> 0 | T10: ='2.1meta'!U62 -> 0 | ... W10: ='2.1meta'!X62 -> 0 | X10: =SUM(M10:W10) -> 0 | Y10: =K10+X10 -> 0 | Z10: =C10-Y10 -> 0
A11: 2.1.1.4.1.1 | B11: PERSONAL NOMBRADO | C11: ='2.1meta'!D11+'2.1meta'!D28+'2.1meta'!D45+'2.1meta'!D63+'2.1meta'!D80+'2.1meta'!D97+'2.1meta'!D114+'2.1meta'!D131+'2.1meta'!D148+'2.1meta'!D165+'2.1meta'!D182+'2.1meta'!D292+'2.1meta'!D309+'2.1meta'!D326 -> 0 | D11: ='2.1meta'!E11+'2.1meta'!E28+'2.1meta'!E45+'2.1meta'!E63+'2.1meta'!E80+'2.1meta'!E97+'2.1meta'!E114+'2.1meta'!E131+'2.1meta'!E148+'2.1meta'!E165+'2.1meta'!E182+'2.1meta'!E292+'2.1meta'!E309+'2.1meta'!E326 -> 0 | E11: ='2.1meta'!F11+'2.1meta'!F28+'2.1meta'!F45+'2.1meta'!F63+'2.1meta'!F80+'2.1meta'!F97+'2.1meta'!F114+'2.1meta'!F131+'2.1meta'!F148+'2.1meta'!F165+'2.1meta'!F182+'2.1meta'!F292+'2.1meta'!F309+'2.1meta'!F326 -> 0 | F11: ='2.1meta'!G11+'2.1meta'!G28+'2.1meta'!G45+'2.1meta'!G63+'2.1meta'!G80+'2.1meta'!G97+'2.1meta'!G114+'2.1meta'!G131+'2.1meta'!G148+'2.1meta'!G165+'2.1meta'!G182+'2.1meta'!G292+'2.1meta'!G309+'2.1meta'!G326 -> 0 | G11: ='2.1meta'!H11+'2.1meta'!H28+'2.1meta'!H45+'2.1meta'!H63+'2.1meta'!H80+'2.1meta'!H97+'2.1meta'!H114+'2.1meta'!H131+'2.1meta'!H148+'2.1meta'!H165+'2.1meta'!H182+'2.1meta'!H292+'2.1meta'!H309+'2.1meta'!H326 -> 0 | H11: ='2.1meta'!I11+'2.1meta'!I28+'2.1meta'!I45+'2.1meta'!I63+'2.1meta'!I80+'2.1meta'!I97+'2.1meta'!I114+'2.1meta'!I131+'2.1meta'!I148+'2.1meta'!I165+'2.1meta'!I182+'2.1meta'!I292+'2.1meta'!I309+'2.1meta'!I326 -> 0 | I11: ='2.1meta'!J11+'2.1meta'!J28+'2.1meta'!J45+'2.1meta'!J63+'2.1meta'!J80+'2.1meta'!J97+'2.1meta'!J114+'2.1meta'!J131+'2.1meta'!J148+'2.1meta'!J165+'2.1meta'!J182+'2.1meta'!J292+'2.1meta'!J309+'2.1meta'!J326 -> 0 | J11: ='2.1meta'!K11+'2.1meta'!K28+'2.1meta'!K45+'2.1meta'!K63+'2.1meta'!K80+'2.1meta'!K97+'2.1meta'!K114+'2.1meta'!K131+'2.1meta'!K148+'2.1meta'!K165+'2.1meta'!K182+'2.1meta'!K292+'2.1meta'!K309+'2.1meta'!K326 -> 0 | K11: =SUM(F11:J11) -> 0 | L11: =C11-K11 -> 0 | M11: ='2.1meta'!N11+'2.1meta'!N28+'2.1meta'!N45+'2.1meta'!N63+'2.1meta'!N80+'2.1meta'!N97+'2.1meta'!N114+'2.1meta'!N131+'2.1meta'!N148+'2.1meta'!N165+'2.1meta'!N182+'2.1meta'!N292+'2.1meta'!N309+'2.1meta'!N326 -> 0 | N11: ='2.1meta'!O11+'2.1meta'!O28+'2.1meta'!O45+'2.1meta'!O63+'2.1meta'!O80+'2.1meta'!O97+'2.1meta'!O114+'2.1meta'!O131+'2.1meta'!O148+'2.1meta'!O165+'2.1meta'!O182+'2.1meta'!O292+'2.1meta'!O309+'2.1meta'!O326 -> 0 | O11: ='2.1meta'!P11+'2.1meta'!P28+'2.1meta'!P45+'2.1meta'!P63+'2.1meta'!P80+'2.1meta'!P97+'2.1meta'!P114+'2.1meta'!P131+'2.1meta'!P148+'2.1meta'!P165+'2.1meta'!P182+'2.1meta'!P292+'2.1meta'!P309+'2.1meta'!P326 -> 0 | P11: ='2.1meta'!Q11+'2.1meta'!Q28+'2.1meta'!Q45+'2.1meta'!Q63+'2.1meta'!Q80+'2.1meta'!Q97+'2.1meta'!Q114+'2.1meta'!Q131+'2.1meta'!Q148+'2.1meta'!Q165+'2.1meta'!Q182+'2.1meta'!Q292+'2.1meta'!Q309+'2.1meta'!Q326 -> 0 | Q11: ='2.1meta'!R11+'2.1meta'!R28+'2.1meta'!R45+'2.1meta'!R63+'2.1meta'!R80+'2.1meta'!R97+'2.1meta'!R114+'2.1meta'!R131+'2.1meta'!R148+'2.1meta'!R165+'2.1meta'!R182+'2.1meta'!R292+'2.1meta'!R309+'2.1meta'!R326 -> 0 | R11: ='2.1meta'!S11+'2.1meta'!S28+'2.1meta'!S45+'2.1meta'!S63+'2.1meta'!S80+'2.1meta'!S97+'2.1meta'!S114+'2.1meta'!S131+'2.1meta'!S148+'2.1meta'!S165+'2.1meta'!S182+'2.1meta'!S292+'2.1meta'!S309+'2.1meta'!S326 -> 0 | S11: ='2.1meta'!T11+'2.1meta'!T28+'2.1meta'!T45+'2.1meta'!T63+'2.1meta'!T80+'2.1meta'!T97+'2.1meta'!T114+'2.1meta'!T131+'2.1meta'!T148+'2.1meta'!T165+'2.1meta'!T182+'2.1meta'!T292+'2.1meta'!T309+'2.1meta'!T326 -> 0 | T11: ='2.1meta'!U11+'2.1meta'!U28+'2.1meta'!U45+'2.1meta'!U63+'2.1meta'!U80+'2.1meta'!U97+'2.1meta'!U114+'2.1meta'!U131+'2.1meta'!U148+'2.1meta'!U165+'2.1meta'!U182+'2.1meta'!U292+'2.1meta'!U309+'2.1meta'!U326 -> 0 | ... W11: ='2.1meta'!X11+'2.1meta'!X28+'2.1meta'!X45+'2.1meta'!X63+'2.1meta'!X80+'2.1meta'!X97+'2.1meta'!X114+'2.1meta'!X131+'2.1meta'!X148+'2.1meta'!X165+'2.1meta'!X182+'2.1meta'!X292+'2.1meta'!X309+'2.1meta'!X326 -> 0 | X11: =SUM(M11:W11) -> 0 | Y11: =K11+X11 -> 0 | Z11: =C11-Y11 -> 0
A12: 2.1.1.4.2.1 | B12: BONO POR FUNCION JURISDICCIONAL Y FISCAL | C12: ='2.1meta'!D12+'2.1meta'!D29+'2.1meta'!D46+'2.1meta'!D64+'2.1meta'!D81+'2.1meta'!D98+'2.1meta'!D115+'2.1meta'!D132+'2.1meta'!D149+'2.1meta'!D166+'2.1meta'!D183+'2.1meta'!D293+'2.1meta'!D310+'2.1meta'!D327 -> 0 | D12: ='2.1meta'!E12+'2.1meta'!E29+'2.1meta'!E46+'2.1meta'!E64+'2.1meta'!E81+'2.1meta'!E98+'2.1meta'!E115+'2.1meta'!E132+'2.1meta'!E149+'2.1meta'!E166+'2.1meta'!E183+'2.1meta'!E293+'2.1meta'!E310+'2.1meta'!E327 -> 0 | E12: ='2.1meta'!F12+'2.1meta'!F29+'2.1meta'!F46+'2.1meta'!F64+'2.1meta'!F81+'2.1meta'!F98+'2.1meta'!F115+'2.1meta'!F132+'2.1meta'!F149+'2.1meta'!F166+'2.1meta'!F183+'2.1meta'!F293+'2.1meta'!F310+'2.1meta'!F327 -> 0 | F12: ='2.1meta'!G12+'2.1meta'!G29+'2.1meta'!G46+'2.1meta'!G64+'2.1meta'!G81+'2.1meta'!G98+'2.1meta'!G115+'2.1meta'!G132+'2.1meta'!G149+'2.1meta'!G166+'2.1meta'!G183+'2.1meta'!G293+'2.1meta'!G310+'2.1meta'!G327 -> 0 | G12: ='2.1meta'!H12+'2.1meta'!H29+'2.1meta'!H46+'2.1meta'!H64+'2.1meta'!H81+'2.1meta'!H98+'2.1meta'!H115+'2.1meta'!H132+'2.1meta'!H149+'2.1meta'!H166+'2.1meta'!H183+'2.1meta'!H293+'2.1meta'!H310+'2.1meta'!H327 -> 0 | H12: ='2.1meta'!I12+'2.1meta'!I29+'2.1meta'!I46+'2.1meta'!I64+'2.1meta'!I81+'2.1meta'!I98+'2.1meta'!I115+'2.1meta'!I132+'2.1meta'!I149+'2.1meta'!I166+'2.1meta'!I183+'2.1meta'!I293+'2.1meta'!I310+'2.1meta'!I327 -> 0 | I12: ='2.1meta'!J12+'2.1meta'!J29+'2.1meta'!J46+'2.1meta'!J64+'2.1meta'!J81+'2.1meta'!J98+'2.1meta'!J115+'2.1meta'!J132+'2.1meta'!J149+'2.1meta'!J166+'2.1meta'!J183+'2.1meta'!J293+'2.1meta'!J310+'2.1meta'!J327 -> 0 | J12: ='2.1meta'!K12+'2.1meta'!K29+'2.1meta'!K46+'2.1meta'!K64+'2.1meta'!K81+'2.1meta'!K98+'2.1meta'!K115+'2.1meta'!K132+'2.1meta'!K149+'2.1meta'!K166+'2.1meta'!K183+'2.1meta'!K293+'2.1meta'!K310+'2.1meta'!K327 -> 0 | K12: =SUM(F12:J12) -> 0 | L12: =C12-K12 -> 0 | M12: ='2.1meta'!N12+'2.1meta'!N29+'2.1meta'!N46+'2.1meta'!N64+'2.1meta'!N81+'2.1meta'!N98+'2.1meta'!N115+'2.1meta'!N132+'2.1meta'!N149+'2.1meta'!N166+'2.1meta'!N183+'2.1meta'!N293+'2.1meta'!N310+'2.1meta'!N327 -> 0 | N12: ='2.1meta'!O12+'2.1meta'!O29+'2.1meta'!O46+'2.1meta'!O64+'2.1meta'!O81+'2.1meta'!O98+'2.1meta'!O115+'2.1meta'!O132+'2.1meta'!O149+'2.1meta'!O166+'2.1meta'!O183+'2.1meta'!O293+'2.1meta'!O310+'2.1meta'!O327 -> 0 | O12: ='2.1meta'!P12+'2.1meta'!P29+'2.1meta'!P46+'2.1meta'!P64+'2.1meta'!P81+'2.1meta'!P98+'2.1meta'!P115+'2.1meta'!P132+'2.1meta'!P149+'2.1meta'!P166+'2.1meta'!P183+'2.1meta'!P293+'2.1meta'!P310+'2.1meta'!P327 -> 0 | P12: ='2.1meta'!Q12+'2.1meta'!Q29+'2.1meta'!Q46+'2.1meta'!Q64+'2.1meta'!Q81+'2.1meta'!Q98+'2.1meta'!Q115+'2.1meta'!Q132+'2.1meta'!Q149+'2.1meta'!Q166+'2.1meta'!Q183+'2.1meta'!Q293+'2.1meta'!Q310+'2.1meta'!Q327 -> 0 | Q12: ='2.1meta'!R12+'2.1meta'!R29+'2.1meta'!R46+'2.1meta'!R64+'2.1meta'!R81+'2.1meta'!R98+'2.1meta'!R115+'2.1meta'!R132+'2.1meta'!R149+'2.1meta'!R166+'2.1meta'!R183+'2.1meta'!R293+'2.1meta'!R310+'2.1meta'!R327 -> 0 | R12: ='2.1meta'!S12+'2.1meta'!S29+'2.1meta'!S46+'2.1meta'!S64+'2.1meta'!S81+'2.1meta'!S98+'2.1meta'!S115+'2.1meta'!S132+'2.1meta'!S149+'2.1meta'!S166+'2.1meta'!S183+'2.1meta'!S293+'2.1meta'!S310+'2.1meta'!S327 -> 0 | S12: ='2.1meta'!T12+'2.1meta'!T29+'2.1meta'!T46+'2.1meta'!T64+'2.1meta'!T81+'2.1meta'!T98+'2.1meta'!T115+'2.1meta'!T132+'2.1meta'!T149+'2.1meta'!T166+'2.1meta'!T183+'2.1meta'!T293+'2.1meta'!T310+'2.1meta'!T327 -> 0 | T12: ='2.1meta'!U12+'2.1meta'!U29+'2.1meta'!U46+'2.1meta'!U64+'2.1meta'!U81+'2.1meta'!U98+'2.1meta'!U115+'2.1meta'!U132+'2.1meta'!U149+'2.1meta'!U166+'2.1meta'!U183+'2.1meta'!U293+'2.1meta'!U310+'2.1meta'!U327 -> 0 | ... V12: ='2.1meta'!W12+'2.1meta'!W29+'2.1meta'!W46+'2.1meta'!W64+'2.1meta'!W81+'2.1meta'!W98+'2.1meta'!W115+'2.1meta'!W132+'2.1meta'!W149+'2.1meta'!W166+'2.1meta'!W183+'2.1meta'!W293+'2.1meta'!W310+'2.1meta'!W327 -> 0 | W12: ='2.1meta'!X13+'2.1meta'!X30+'2.1meta'!X47+'2.1meta'!X64+'2.1meta'!X82+'2.1meta'!X99+'2.1meta'!X116+'2.1meta'!X133+'2.1meta'!X150+'2.1meta'!X167+'2.1meta'!X184+'2.1meta'!X294+'2.1meta'!X311+'2.1meta'!X328 -> 0 | X12: =SUM(M12:W12) -> 0 | Y12: =K12+X12 -> 0 | Z12: =C12-Y12 -> 0
A13: 2.1.1.4.2.2 | B13: ASIGNACION POR GASTOS OPERATIVOS | C13: ='2.1meta'!D13+'2.1meta'!D30+'2.1meta'!D47+'2.1meta'!D65+'2.1meta'!D82+'2.1meta'!D99+'2.1meta'!D116+'2.1meta'!D133+'2.1meta'!D150+'2.1meta'!D167+'2.1meta'!D184+'2.1meta'!D294+'2.1meta'!D311+'2.1meta'!D328 -> 0 | D13: ='2.1meta'!E13+'2.1meta'!E30+'2.1meta'!E47+'2.1meta'!E65+'2.1meta'!E82+'2.1meta'!E99+'2.1meta'!E116+'2.1meta'!E133+'2.1meta'!E150+'2.1meta'!E167+'2.1meta'!E184+'2.1meta'!E294+'2.1meta'!E311+'2.1meta'!E328 -> 0 | E13: ='2.1meta'!F13+'2.1meta'!F30+'2.1meta'!F47+'2.1meta'!F65+'2.1meta'!F82+'2.1meta'!F99+'2.1meta'!F116+'2.1meta'!F133+'2.1meta'!F150+'2.1meta'!F167+'2.1meta'!F184+'2.1meta'!F294+'2.1meta'!F311+'2.1meta'!F328 -> 0 | F13: ='2.1meta'!G13+'2.1meta'!G30+'2.1meta'!G47+'2.1meta'!G65+'2.1meta'!G82+'2.1meta'!G99+'2.1meta'!G116+'2.1meta'!G133+'2.1meta'!G150+'2.1meta'!G167+'2.1meta'!G184+'2.1meta'!G294+'2.1meta'!G311+'2.1meta'!G328 -> 0 | G13: ='2.1meta'!H13+'2.1meta'!H30+'2.1meta'!H47+'2.1meta'!H65+'2.1meta'!H82+'2.1meta'!H99+'2.1meta'!H116+'2.1meta'!H133+'2.1meta'!H150+'2.1meta'!H167+'2.1meta'!H184+'2.1meta'!H294+'2.1meta'!H311+'2.1meta'!H328 -> 0 | H13: ='2.1meta'!I13+'2.1meta'!I30+'2.1meta'!I47+'2.1meta'!I65+'2.1meta'!I82+'2.1meta'!I99+'2.1meta'!I116+'2.1meta'!I133+'2.1meta'!I150+'2.1meta'!I167+'2.1meta'!I184+'2.1meta'!I294+'2.1meta'!I311+'2.1meta'!I328 -> 0 | I13: ='2.1meta'!J13+'2.1meta'!J30+'2.1meta'!J47+'2.1meta'!J65+'2.1meta'!J82+'2.1meta'!J99+'2.1meta'!J116+'2.1meta'!J133+'2.1meta'!J150+'2.1meta'!J167+'2.1meta'!J184+'2.1meta'!J294+'2.1meta'!J311+'2.1meta'!J328 -> 0 | J13: ='2.1meta'!K13+'2.1meta'!K30+'2.1meta'!K47+'2.1meta'!K65+'2.1meta'!K82+'2.1meta'!K99+'2.1meta'!K116+'2.1meta'!K133+'2.1meta'!K150+'2.1meta'!K167+'2.1meta'!K184+'2.1meta'!K294+'2.1meta'!K311+'2.1meta'!K328 -> 0 | K13: =SUM(F13:J13) -> 0 | L13: =C13-K13 -> 0 | M13: ='2.1meta'!N13+'2.1meta'!N30+'2.1meta'!N47+'2.1meta'!N65+'2.1meta'!N82+'2.1meta'!N99+'2.1meta'!N116+'2.1meta'!N133+'2.1meta'!N150+'2.1meta'!N167+'2.1meta'!N184+'2.1meta'!N294+'2.1meta'!N311+'2.1meta'!N328 -> 0 | N13: ='2.1meta'!O13+'2.1meta'!O30+'2.1meta'!O47+'2.1meta'!O65+'2.1meta'!O82+'2.1meta'!O99+'2.1meta'!O116+'2.1meta'!O133+'2.1meta'!O150+'2.1meta'!O167+'2.1meta'!O184+'2.1meta'!O294+'2.1meta'!O311+'2.1meta'!O328 -> 0 | O13: ='2.1meta'!P13+'2.1meta'!P30+'2.1meta'!P47+'2.1meta'!P65+'2.1meta'!P82+'2.1meta'!P99+'2.1meta'!P116+'2.1meta'!P133+'2.1meta'!P150+'2.1meta'!P167+'2.1meta'!P184+'2.1meta'!P294+'2.1meta'!P311+'2.1meta'!P328 -> 0 | P13: ='2.1meta'!Q13+'2.1meta'!Q30+'2.1meta'!Q47+'2.1meta'!Q65+'2.1meta'!Q82+'2.1meta'!Q99+'2.1meta'!Q116+'2.1meta'!Q133+'2.1meta'!Q150+'2.1meta'!Q167+'2.1meta'!Q184+'2.1meta'!Q294+'2.1meta'!Q311+'2.1meta'!Q328 -> 0 | Q13: ='2.1meta'!R13+'2.1meta'!R30+'2.1meta'!R47+'2.1meta'!R65+'2.1meta'!R82+'2.1meta'!R99+'2.1meta'!R116+'2.1meta'!R133+'2.1meta'!R150+'2.1meta'!R167+'2.1meta'!R184+'2.1meta'!R294+'2.1meta'!R311+'2.1meta'!R328 -> 0 | R13: ='2.1meta'!S13+'2.1meta'!S30+'2.1meta'!S47+'2.1meta'!S65+'2.1meta'!S82+'2.1meta'!S99+'2.1meta'!S116+'2.1meta'!S133+'2.1meta'!S150+'2.1meta'!S167+'2.1meta'!S184+'2.1meta'!S294+'2.1meta'!S311+'2.1meta'!S328 -> 0 | S13: ='2.1meta'!T13+'2.1meta'!T30+'2.1meta'!T47+'2.1meta'!T65+'2.1meta'!T82+'2.1meta'!T99+'2.1meta'!T116+'2.1meta'!T133+'2.1meta'!T150+'2.1meta'!T167+'2.1meta'!T184+'2.1meta'!T294+'2.1meta'!T311+'2.1meta'!T328 -> 0 | T13: ='2.1meta'!U13+'2.1meta'!U30+'2.1meta'!U47+'2.1meta'!U65+'2.1meta'!U82+'2.1meta'!U99+'2.1meta'!U116+'2.1meta'!U133+'2.1meta'!U150+'2.1meta'!U167+'2.1meta'!U184+'2.1meta'!U294+'2.1meta'!U311+'2.1meta'!U328 -> 0 | ... W13: ='2.1meta'!X13+'2.1meta'!X30+'2.1meta'!X47+'2.1meta'!X65+'2.1meta'!X82+'2.1meta'!X99+'2.1meta'!X116+'2.1meta'!X133+'2.1meta'!X150+'2.1meta'!X167+'2.1meta'!X184+'2.1meta'!X294+'2.1meta'!X311+'2.1meta'!X328 -> 0 | X13: =SUM(M13:W13) -> 0 | Y13: =K13+X13 -> 0 | Z13: =C13-Y13 -> 0
A14: 2.1.1.9.1.1 | B14: GRATIFICACIONES | C14: ='2.1meta'!D14+'2.1meta'!D31+'2.1meta'!D48+'2.1meta'!D66+'2.1meta'!D83+'2.1meta'!D100+'2.1meta'!D117+'2.1meta'!D134+'2.1meta'!D151+'2.1meta'!D168+'2.1meta'!D185+'2.1meta'!D295+'2.1meta'!D312+'2.1meta'!D329 -> 0 | D14: ='2.1meta'!E14+'2.1meta'!E31+'2.1meta'!E48+'2.1meta'!E66+'2.1meta'!E83+'2.1meta'!E100+'2.1meta'!E117+'2.1meta'!E134+'2.1meta'!E151+'2.1meta'!E168+'2.1meta'!E185+'2.1meta'!E295+'2.1meta'!E312+'2.1meta'!E329 -> 0 | E14: ='2.1meta'!F14+'2.1meta'!F31+'2.1meta'!F48+'2.1meta'!F66+'2.1meta'!F83+'2.1meta'!F100+'2.1meta'!F117+'2.1meta'!F134+'2.1meta'!F151+'2.1meta'!F168+'2.1meta'!F185+'2.1meta'!F295+'2.1meta'!F312+'2.1meta'!F329 -> 0 | F14: ='2.1meta'!G14+'2.1meta'!G31+'2.1meta'!G48+'2.1meta'!G66+'2.1meta'!G83+'2.1meta'!G100+'2.1meta'!G117+'2.1meta'!G134+'2.1meta'!G151+'2.1meta'!G168+'2.1meta'!G185+'2.1meta'!G295+'2.1meta'!G312+'2.1meta'!G329 -> 0 | G14: ='2.1meta'!H14+'2.1meta'!H31+'2.1meta'!H48+'2.1meta'!H66+'2.1meta'!H83+'2.1meta'!H100+'2.1meta'!H117+'2.1meta'!H134+'2.1meta'!H151+'2.1meta'!H168+'2.1meta'!H185+'2.1meta'!H295+'2.1meta'!H312+'2.1meta'!H329 -> 0 | H14: ='2.1meta'!I14+'2.1meta'!I31+'2.1meta'!I48+'2.1meta'!I66+'2.1meta'!I83+'2.1meta'!I100+'2.1meta'!I117+'2.1meta'!I134+'2.1meta'!I151+'2.1meta'!I168+'2.1meta'!I185+'2.1meta'!I295+'2.1meta'!I312+'2.1meta'!I329 -> 0 | I14: ='2.1meta'!J14+'2.1meta'!J31+'2.1meta'!J48+'2.1meta'!J66+'2.1meta'!J83+'2.1meta'!J100+'2.1meta'!J117+'2.1meta'!J134+'2.1meta'!J151+'2.1meta'!J168+'2.1meta'!J185+'2.1meta'!J295+'2.1meta'!J312+'2.1meta'!J329 -> 0 | J14: ='2.1meta'!K14+'2.1meta'!K31+'2.1meta'!K48+'2.1meta'!K66+'2.1meta'!K83+'2.1meta'!K100+'2.1meta'!K117+'2.1meta'!K134+'2.1meta'!K151+'2.1meta'!K168+'2.1meta'!K185+'2.1meta'!K295+'2.1meta'!K312+'2.1meta'!K329 -> 0 | K14: =SUM(F14:J14) -> 0 | L14: =C14-K14 -> 0 | M14: ='2.1meta'!N14+'2.1meta'!N31+'2.1meta'!N48+'2.1meta'!N66+'2.1meta'!N83+'2.1meta'!N100+'2.1meta'!N117+'2.1meta'!N134+'2.1meta'!N151+'2.1meta'!N168+'2.1meta'!N185+'2.1meta'!N295+'2.1meta'!N312+'2.1meta'!N329 -> 0 | N14: ='2.1meta'!O14+'2.1meta'!O31+'2.1meta'!O48+'2.1meta'!O66+'2.1meta'!O83+'2.1meta'!O100+'2.1meta'!O117+'2.1meta'!O134+'2.1meta'!O151+'2.1meta'!O168+'2.1meta'!O185+'2.1meta'!O295+'2.1meta'!O312+'2.1meta'!O329 -> 0 | O14: ='2.1meta'!P14+'2.1meta'!P31+'2.1meta'!P48+'2.1meta'!P66+'2.1meta'!P83+'2.1meta'!P100+'2.1meta'!P117+'2.1meta'!P134+'2.1meta'!P151+'2.1meta'!P168+'2.1meta'!P185+'2.1meta'!P295+'2.1meta'!P312+'2.1meta'!P329 -> 0 | P14: ='2.1meta'!Q14+'2.1meta'!Q31+'2.1meta'!Q48+'2.1meta'!Q66+'2.1meta'!Q83+'2.1meta'!Q100+'2.1meta'!Q117+'2.1meta'!Q134+'2.1meta'!Q151+'2.1meta'!Q168+'2.1meta'!Q185+'2.1meta'!Q295+'2.1meta'!Q312+'2.1meta'!Q329 -> 0 | Q14: ='2.1meta'!R14+'2.1meta'!R31+'2.1meta'!R48+'2.1meta'!R66+'2.1meta'!R83+'2.1meta'!R100+'2.1meta'!R117+'2.1meta'!R134+'2.1meta'!R151+'2.1meta'!R168+'2.1meta'!R185+'2.1meta'!R295+'2.1meta'!R312+'2.1meta'!R329 -> 0 | R14: ='2.1meta'!S14+'2.1meta'!S31+'2.1meta'!S48+'2.1meta'!S66+'2.1meta'!S83+'2.1meta'!S100+'2.1meta'!S117+'2.1meta'!S134+'2.1meta'!S151+'2.1meta'!S168+'2.1meta'!S185+'2.1meta'!S295+'2.1meta'!S312+'2.1meta'!S329 -> 0 | S14: ='2.1meta'!T14+'2.1meta'!T31+'2.1meta'!T48+'2.1meta'!T66+'2.1meta'!T83+'2.1meta'!T100+'2.1meta'!T117+'2.1meta'!T134+'2.1meta'!T151+'2.1meta'!T168+'2.1meta'!T185+'2.1meta'!T295+'2.1meta'!T312+'2.1meta'!T329 -> 0 | T14: ='2.1meta'!U14+'2.1meta'!U31+'2.1meta'!U48+'2.1meta'!U66+'2.1meta'!U83+'2.1meta'!U100+'2.1meta'!U117+'2.1meta'!U134+'2.1meta'!U151+'2.1meta'!U168+'2.1meta'!U185+'2.1meta'!U295+'2.1meta'!U312+'2.1meta'!U329 -> 0 | ... W14: ='2.1meta'!X14+'2.1meta'!X31+'2.1meta'!X48+'2.1meta'!X66+'2.1meta'!X83+'2.1meta'!X100+'2.1meta'!X117+'2.1meta'!X134+'2.1meta'!X151+'2.1meta'!X168+'2.1meta'!X185+'2.1meta'!X295+'2.1meta'!X312+'2.1meta'!X329 -> 0 | X14: =SUM(M14:W14) -> 0 | Y14: =K14+X14 -> 0 | Z14: =C14-Y14 -> 0
A15: 2.1.1.9.1.2 | B15: AGUINALDOS | C15: ='2.1meta'!D15+'2.1meta'!D32+'2.1meta'!D49+'2.1meta'!D67+'2.1meta'!D84+'2.1meta'!D101+'2.1meta'!D118+'2.1meta'!D135+'2.1meta'!D152+'2.1meta'!D169+'2.1meta'!D186+'2.1meta'!D296+'2.1meta'!D313+'2.1meta'!D330 -> 0 | D15: ='2.1meta'!E15+'2.1meta'!E32+'2.1meta'!E49+'2.1meta'!E66+'2.1meta'!E84+'2.1meta'!E101+'2.1meta'!E118+'2.1meta'!E135+'2.1meta'!E152+'2.1meta'!E169+'2.1meta'!E186+'2.1meta'!E296+'2.1meta'!E313+'2.1meta'!E330 -> 0 | E15: ='2.1meta'!F15+'2.1meta'!F32+'2.1meta'!F49+'2.1meta'!F66+'2.1meta'!F84+'2.1meta'!F101+'2.1meta'!F118+'2.1meta'!F135+'2.1meta'!F152+'2.1meta'!F169+'2.1meta'!F186+'2.1meta'!F296+'2.1meta'!F313+'2.1meta'!F330 -> 0 | F15: ='2.1meta'!G15+'2.1meta'!G32+'2.1meta'!G49+'2.1meta'!G67+'2.1meta'!G84+'2.1meta'!G101+'2.1meta'!G118+'2.1meta'!G135+'2.1meta'!G152+'2.1meta'!G169+'2.1meta'!G186+'2.1meta'!G296+'2.1meta'!G313+'2.1meta'!G330 -> 0 | G15: ='2.1meta'!H15+'2.1meta'!H32+'2.1meta'!H49+'2.1meta'!H67+'2.1meta'!H84+'2.1meta'!H101+'2.1meta'!H118+'2.1meta'!H135+'2.1meta'!H152+'2.1meta'!H169+'2.1meta'!H186+'2.1meta'!H296+'2.1meta'!H313+'2.1meta'!H330 -> 0 | H15: ='2.1meta'!I15+'2.1meta'!I32+'2.1meta'!I49+'2.1meta'!I67+'2.1meta'!I84+'2.1meta'!I101+'2.1meta'!I118+'2.1meta'!I135+'2.1meta'!I152+'2.1meta'!I169+'2.1meta'!I186+'2.1meta'!I296+'2.1meta'!I313+'2.1meta'!I330 -> 0 | I15: ='2.1meta'!J15+'2.1meta'!J32+'2.1meta'!J49+'2.1meta'!J67+'2.1meta'!J84+'2.1meta'!J101+'2.1meta'!J118+'2.1meta'!J135+'2.1meta'!J152+'2.1meta'!J169+'2.1meta'!J186+'2.1meta'!J296+'2.1meta'!J313+'2.1meta'!J330 -> 0 | J15: ='2.1meta'!K15+'2.1meta'!K32+'2.1meta'!K49+'2.1meta'!K67+'2.1meta'!K84+'2.1meta'!K101+'2.1meta'!K118+'2.1meta'!K135+'2.1meta'!K152+'2.1meta'!K169+'2.1meta'!K186+'2.1meta'!K296+'2.1meta'!K313+'2.1meta'!K330 -> 0 | K15: =SUM(F15:J15) -> 0 | L15: =C15-K15 -> 0 | M15: ='2.1meta'!N15+'2.1meta'!N32+'2.1meta'!N49+'2.1meta'!N67+'2.1meta'!N84+'2.1meta'!N101+'2.1meta'!N118+'2.1meta'!N135+'2.1meta'!N152+'2.1meta'!N169+'2.1meta'!N186+'2.1meta'!N296+'2.1meta'!N313+'2.1meta'!N330 -> 0 | N15: ='2.1meta'!O15+'2.1meta'!O32+'2.1meta'!O49+'2.1meta'!O67+'2.1meta'!O84+'2.1meta'!O101+'2.1meta'!O118+'2.1meta'!O135+'2.1meta'!O152+'2.1meta'!O169+'2.1meta'!O186+'2.1meta'!O296+'2.1meta'!O313+'2.1meta'!O330 -> 0 | O15: ='2.1meta'!P15+'2.1meta'!P32+'2.1meta'!P49+'2.1meta'!P67+'2.1meta'!P84+'2.1meta'!P101+'2.1meta'!P118+'2.1meta'!P135+'2.1meta'!P152+'2.1meta'!P169+'2.1meta'!P186+'2.1meta'!P296+'2.1meta'!P313+'2.1meta'!P330 -> 0 | P15: ='2.1meta'!Q15+'2.1meta'!Q32+'2.1meta'!Q49+'2.1meta'!Q67+'2.1meta'!Q84+'2.1meta'!Q101+'2.1meta'!Q118+'2.1meta'!Q135+'2.1meta'!Q152+'2.1meta'!Q169+'2.1meta'!Q186+'2.1meta'!Q296+'2.1meta'!Q313+'2.1meta'!Q330 -> 0 | Q15: ='2.1meta'!R15+'2.1meta'!R32+'2.1meta'!R49+'2.1meta'!R67+'2.1meta'!R84+'2.1meta'!R101+'2.1meta'!R118+'2.1meta'!R135+'2.1meta'!R152+'2.1meta'!R169+'2.1meta'!R186+'2.1meta'!R296+'2.1meta'!R313+'2.1meta'!R330 -> 0 | R15: ='2.1meta'!S15+'2.1meta'!S32+'2.1meta'!S49+'2.1meta'!S67+'2.1meta'!S84+'2.1meta'!S101+'2.1meta'!S118+'2.1meta'!S135+'2.1meta'!S152+'2.1meta'!S169+'2.1meta'!S186+'2.1meta'!S296+'2.1meta'!S313+'2.1meta'!S330 -> 0 | S15: ='2.1meta'!T15+'2.1meta'!T32+'2.1meta'!T49+'2.1meta'!T67+'2.1meta'!T84+'2.1meta'!T101+'2.1meta'!T118+'2.1meta'!T135+'2.1meta'!T152+'2.1meta'!T169+'2.1meta'!T186+'2.1meta'!T296+'2.1meta'!T313+'2.1meta'!T330 -> 0 | T15: ='2.1meta'!U15+'2.1meta'!U32+'2.1meta'!U49+'2.1meta'!U67+'2.1meta'!U84+'2.1meta'!U101+'2.1meta'!U118+'2.1meta'!U135+'2.1meta'!U152+'2.1meta'!U169+'2.1meta'!U186+'2.1meta'!U296+'2.1meta'!U313+'2.1meta'!U330 -> 0 | ... W15: ='2.1meta'!X15+'2.1meta'!X32+'2.1meta'!X49+'2.1meta'!X67+'2.1meta'!X84+'2.1meta'!X101+'2.1meta'!X118+'2.1meta'!X135+'2.1meta'!X152+'2.1meta'!X169+'2.1meta'!X186+'2.1meta'!X296+'2.1meta'!X313+'2.1meta'!X330 -> 0 | X15: =SUM(M15:W15) -> 0 | Y15: =K15+X15 -> 0 | Z15: =C15-Y15 -> 0
A16: 2.1.1.9.1.3 | B16: BONIFICACION POR ESCOLARIDAD | C16: ='2.1meta'!D16+'2.1meta'!D33+'2.1meta'!D50+'2.1meta'!D68+'2.1meta'!D85+'2.1meta'!D102+'2.1meta'!D119+'2.1meta'!D136+'2.1meta'!D153+'2.1meta'!D170+'2.1meta'!D187+'2.1meta'!D297+'2.1meta'!D314+'2.1meta'!D331 -> 0 | D16: ='2.1meta'!E16+'2.1meta'!E33+'2.1meta'!E50+'2.1meta'!E68+'2.1meta'!E85+'2.1meta'!E102+'2.1meta'!E119+'2.1meta'!E136+'2.1meta'!E153+'2.1meta'!E170+'2.1meta'!E187+'2.1meta'!E297+'2.1meta'!E314+'2.1meta'!E331 -> 0 | E16: ='2.1meta'!F16+'2.1meta'!F33+'2.1meta'!F50+'2.1meta'!F68+'2.1meta'!F85+'2.1meta'!F102+'2.1meta'!F119+'2.1meta'!F136+'2.1meta'!F153+'2.1meta'!F170+'2.1meta'!F187+'2.1meta'!F297+'2.1meta'!F314+'2.1meta'!F331 -> 0 | F16: ='2.1meta'!G16+'2.1meta'!G33+'2.1meta'!G50+'2.1meta'!G68+'2.1meta'!G85+'2.1meta'!G102+'2.1meta'!G119+'2.1meta'!G136+'2.1meta'!G153+'2.1meta'!G170+'2.1meta'!G187+'2.1meta'!G297+'2.1meta'!G314+'2.1meta'!G331 -> 0 | G16: ='2.1meta'!H16+'2.1meta'!H33+'2.1meta'!H50+'2.1meta'!H68+'2.1meta'!H85+'2.1meta'!H102+'2.1meta'!H119+'2.1meta'!H136+'2.1meta'!H153+'2.1meta'!H170+'2.1meta'!H187+'2.1meta'!H297+'2.1meta'!H314+'2.1meta'!H331 -> 0 | H16: ='2.1meta'!I16+'2.1meta'!I33+'2.1meta'!I50+'2.1meta'!I68+'2.1meta'!I85+'2.1meta'!I102+'2.1meta'!I119+'2.1meta'!I136+'2.1meta'!I153+'2.1meta'!I170+'2.1meta'!I187+'2.1meta'!I297+'2.1meta'!I314+'2.1meta'!I331 -> 0 | I16: ='2.1meta'!J16+'2.1meta'!J33+'2.1meta'!J50+'2.1meta'!J68+'2.1meta'!J85+'2.1meta'!J102+'2.1meta'!J119+'2.1meta'!J136+'2.1meta'!J153+'2.1meta'!J170+'2.1meta'!J187+'2.1meta'!J297+'2.1meta'!J314+'2.1meta'!J331 -> 0 | J16: ='2.1meta'!K16+'2.1meta'!K33+'2.1meta'!K50+'2.1meta'!K68+'2.1meta'!K85+'2.1meta'!K102+'2.1meta'!K119+'2.1meta'!K136+'2.1meta'!K153+'2.1meta'!K170+'2.1meta'!K187+'2.1meta'!K297+'2.1meta'!K314+'2.1meta'!K331 -> 0 | K16: =SUM(F16:J16) -> 0 | L16: =C16-K16 -> 0 | M16: ='2.1meta'!N16+'2.1meta'!N33+'2.1meta'!N50+'2.1meta'!N68+'2.1meta'!N85+'2.1meta'!N102+'2.1meta'!N119+'2.1meta'!N136+'2.1meta'!N153+'2.1meta'!N170+'2.1meta'!N187+'2.1meta'!N297+'2.1meta'!N314+'2.1meta'!N331 -> 0 | N16: ='2.1meta'!O16+'2.1meta'!O33+'2.1meta'!O50+'2.1meta'!O68+'2.1meta'!O85+'2.1meta'!O102+'2.1meta'!O119+'2.1meta'!O136+'2.1meta'!O153+'2.1meta'!O170+'2.1meta'!O187+'2.1meta'!O297+'2.1meta'!O314+'2.1meta'!O331 -> 0 | O16: ='2.1meta'!P16+'2.1meta'!P33+'2.1meta'!P50+'2.1meta'!P68+'2.1meta'!P85+'2.1meta'!P102+'2.1meta'!P119+'2.1meta'!P136+'2.1meta'!P153+'2.1meta'!P170+'2.1meta'!P187+'2.1meta'!P297+'2.1meta'!P314+'2.1meta'!P331 -> 0 | P16: ='2.1meta'!Q16+'2.1meta'!Q33+'2.1meta'!Q50+'2.1meta'!Q68+'2.1meta'!Q85+'2.1meta'!Q102+'2.1meta'!Q119+'2.1meta'!Q136+'2.1meta'!Q153+'2.1meta'!Q170+'2.1meta'!Q187+'2.1meta'!Q297+'2.1meta'!Q314+'2.1meta'!Q331 -> 0 | Q16: ='2.1meta'!R16+'2.1meta'!R33+'2.1meta'!R50+'2.1meta'!R68+'2.1meta'!R85+'2.1meta'!R102+'2.1meta'!R119+'2.1meta'!R136+'2.1meta'!R153+'2.1meta'!R170+'2.1meta'!R187+'2.1meta'!R297+'2.1meta'!R314+'2.1meta'!R331 -> 0 | R16: ='2.1meta'!S16+'2.1meta'!S33+'2.1meta'!S50+'2.1meta'!S68+'2.1meta'!S85+'2.1meta'!S102+'2.1meta'!S119+'2.1meta'!S136+'2.1meta'!S153+'2.1meta'!S170+'2.1meta'!S187+'2.1meta'!S297+'2.1meta'!S314+'2.1meta'!S331 -> 0 | S16: ='2.1meta'!T16+'2.1meta'!T33+'2.1meta'!T50+'2.1meta'!T68+'2.1meta'!T85+'2.1meta'!T102+'2.1meta'!T119+'2.1meta'!T136+'2.1meta'!T153+'2.1meta'!T170+'2.1meta'!T187+'2.1meta'!T297+'2.1meta'!T314+'2.1meta'!T331 -> 0 | T16: ='2.1meta'!U16+'2.1meta'!U33+'2.1meta'!U50+'2.1meta'!U68+'2.1meta'!U85+'2.1meta'!U102+'2.1meta'!U119+'2.1meta'!U136+'2.1meta'!U153+'2.1meta'!U170+'2.1meta'!U187+'2.1meta'!U297+'2.1meta'!U314+'2.1meta'!U331 -> 0 | ... W16: ='2.1meta'!X16+'2.1meta'!X33+'2.1meta'!X50+'2.1meta'!X68+'2.1meta'!X85+'2.1meta'!X102+'2.1meta'!X119+'2.1meta'!X136+'2.1meta'!X153+'2.1meta'!X170+'2.1meta'!X187+'2.1meta'!X297+'2.1meta'!X314+'2.1meta'!X331 -> 0 | X16: =SUM(M16:W16) -> 0 | Y16: =K16+X16 -> 0 | Z16: =C16-Y16 -> 0
A17: 2.1.1.9.2.1 | B17: COMPENSACION POR TIEMPO DE SERVICIOS (CTS) | C17: ='2.1meta'!D17+'2.1meta'!D34+'2.1meta'!D51+'2.1meta'!D69+'2.1meta'!D86+'2.1meta'!D103+'2.1meta'!D120+'2.1meta'!D137+'2.1meta'!D154+'2.1meta'!D171+'2.1meta'!D188+'2.1meta'!D298+'2.1meta'!D315+'2.1meta'!D332 -> 0 | D17: ='2.1meta'!E17+'2.1meta'!E34+'2.1meta'!E51+'2.1meta'!E69+'2.1meta'!E86+'2.1meta'!E103+'2.1meta'!E120+'2.1meta'!E137+'2.1meta'!E154+'2.1meta'!E171+'2.1meta'!E188+'2.1meta'!E298+'2.1meta'!E315+'2.1meta'!E332 -> 0 | E17: ='2.1meta'!F17+'2.1meta'!F34+'2.1meta'!F51+'2.1meta'!F69+'2.1meta'!F86+'2.1meta'!F103+'2.1meta'!F120+'2.1meta'!F137+'2.1meta'!F154+'2.1meta'!F171+'2.1meta'!F188+'2.1meta'!F298+'2.1meta'!F315+'2.1meta'!F332 -> 0 | F17: ='2.1meta'!G17+'2.1meta'!G34+'2.1meta'!G51+'2.1meta'!G69+'2.1meta'!G86+'2.1meta'!G103+'2.1meta'!G120+'2.1meta'!G137+'2.1meta'!G154+'2.1meta'!G171+'2.1meta'!G188+'2.1meta'!G298+'2.1meta'!G315+'2.1meta'!G332 -> 0 | G17: ='2.1meta'!H17+'2.1meta'!H34+'2.1meta'!H51+'2.1meta'!H69+'2.1meta'!H86+'2.1meta'!H103+'2.1meta'!H120+'2.1meta'!H137+'2.1meta'!H154+'2.1meta'!H171+'2.1meta'!H188+'2.1meta'!H298+'2.1meta'!H315+'2.1meta'!H332 -> 0 | H17: ='2.1meta'!I17+'2.1meta'!I34+'2.1meta'!I51+'2.1meta'!I69+'2.1meta'!I86+'2.1meta'!I103+'2.1meta'!I120+'2.1meta'!I137+'2.1meta'!I154+'2.1meta'!I171+'2.1meta'!I188+'2.1meta'!I298+'2.1meta'!I315+'2.1meta'!I332 -> 0 | I17: ='2.1meta'!J17+'2.1meta'!J34+'2.1meta'!J51+'2.1meta'!J69+'2.1meta'!J86+'2.1meta'!J103+'2.1meta'!J120+'2.1meta'!J137+'2.1meta'!J154+'2.1meta'!J171+'2.1meta'!J188+'2.1meta'!J298+'2.1meta'!J315+'2.1meta'!J332 -> 0 | J17: ='2.1meta'!K17+'2.1meta'!K34+'2.1meta'!K51+'2.1meta'!K69+'2.1meta'!K86+'2.1meta'!K103+'2.1meta'!K120+'2.1meta'!K137+'2.1meta'!K154+'2.1meta'!K171+'2.1meta'!K188+'2.1meta'!K298+'2.1meta'!K315+'2.1meta'!K332 -> 0 | K17: =SUM(F17:J17) -> 0 | L17: =C17-K17 -> 0 | M17: ='2.1meta'!N17+'2.1meta'!N34+'2.1meta'!N51+'2.1meta'!N69+'2.1meta'!N86+'2.1meta'!N103+'2.1meta'!N120+'2.1meta'!N137+'2.1meta'!N154+'2.1meta'!N171+'2.1meta'!N188+'2.1meta'!N298+'2.1meta'!N315+'2.1meta'!N332 -> 0 | N17: ='2.1meta'!O17+'2.1meta'!O34+'2.1meta'!O51+'2.1meta'!O69+'2.1meta'!O86+'2.1meta'!O103+'2.1meta'!O120+'2.1meta'!O137+'2.1meta'!O154+'2.1meta'!O171+'2.1meta'!O188+'2.1meta'!O298+'2.1meta'!O315+'2.1meta'!O332 -> 0 | O17: ='2.1meta'!P17+'2.1meta'!P34+'2.1meta'!P51+'2.1meta'!P69+'2.1meta'!P86+'2.1meta'!P103+'2.1meta'!P120+'2.1meta'!P137+'2.1meta'!P154+'2.1meta'!P171+'2.1meta'!P188+'2.1meta'!P298+'2.1meta'!P315+'2.1meta'!P332 -> 0 | P17: ='2.1meta'!Q17+'2.1meta'!Q34+'2.1meta'!Q51+'2.1meta'!Q69+'2.1meta'!Q86+'2.1meta'!Q103+'2.1meta'!Q120+'2.1meta'!Q137+'2.1meta'!Q154+'2.1meta'!Q171+'2.1meta'!Q188+'2.1meta'!Q298+'2.1meta'!Q315+'2.1meta'!Q332 -> 0 | Q17: ='2.1meta'!R17+'2.1meta'!R34+'2.1meta'!R51+'2.1meta'!R69+'2.1meta'!R86+'2.1meta'!R103+'2.1meta'!R120+'2.1meta'!R137+'2.1meta'!R154+'2.1meta'!R171+'2.1meta'!R188+'2.1meta'!R298+'2.1meta'!R315+'2.1meta'!R332 -> 0 | R17: ='2.1meta'!S17+'2.1meta'!S34+'2.1meta'!S51+'2.1meta'!S69+'2.1meta'!S86+'2.1meta'!S103+'2.1meta'!S120+'2.1meta'!S137+'2.1meta'!S154+'2.1meta'!S171+'2.1meta'!S188+'2.1meta'!S298+'2.1meta'!S315+'2.1meta'!S332 -> 0 | S17: ='2.1meta'!T17+'2.1meta'!T34+'2.1meta'!T51+'2.1meta'!T69+'2.1meta'!T86+'2.1meta'!T103+'2.1meta'!T120+'2.1meta'!T137+'2.1meta'!T154+'2.1meta'!T171+'2.1meta'!T188+'2.1meta'!T298+'2.1meta'!T315+'2.1meta'!T332 -> 0 | T17: ='2.1meta'!U17+'2.1meta'!U34+'2.1meta'!U51+'2.1meta'!U69+'2.1meta'!U86+'2.1meta'!U103+'2.1meta'!U120+'2.1meta'!U137+'2.1meta'!U154+'2.1meta'!U171+'2.1meta'!U188+'2.1meta'!U298+'2.1meta'!U315+'2.1meta'!U332 -> 0 | ... W17: ='2.1meta'!X17+'2.1meta'!X34+'2.1meta'!X51+'2.1meta'!X69+'2.1meta'!X86+'2.1meta'!X103+'2.1meta'!X120+'2.1meta'!X137+'2.1meta'!X154+'2.1meta'!X171+'2.1meta'!X188+'2.1meta'!X298+'2.1meta'!X315+'2.1meta'!X332 -> 0 | X17: =SUM(M17:W17) -> 0 | Y17: =K17+X17 -> 0 | Z17: =C17-Y17 -> 0
A18: 2.1.1.9.3.3 | B18: COMPENSACION VACACIONAL (VACACIONES TRUNCAS) | C18: ='2.1meta'!D18+'2.1meta'!D35+'2.1meta'!D52+'2.1meta'!D70+'2.1meta'!D87+'2.1meta'!D104+'2.1meta'!D121+'2.1meta'!D138+'2.1meta'!D155+'2.1meta'!D172+'2.1meta'!D189+'2.1meta'!D299+'2.1meta'!D316+'2.1meta'!D333 -> 0 | D18: ='2.1meta'!E18+'2.1meta'!E35+'2.1meta'!E52+'2.1meta'!E70+'2.1meta'!E87+'2.1meta'!E104+'2.1meta'!E121+'2.1meta'!E138+'2.1meta'!E155+'2.1meta'!E172+'2.1meta'!E189+'2.1meta'!E299+'2.1meta'!E316+'2.1meta'!E333 -> 0 | E18: ='2.1meta'!F18+'2.1meta'!F35+'2.1meta'!F52+'2.1meta'!F70+'2.1meta'!F87+'2.1meta'!F104+'2.1meta'!F121+'2.1meta'!F138+'2.1meta'!F155+'2.1meta'!F172+'2.1meta'!F189+'2.1meta'!F299+'2.1meta'!F316+'2.1meta'!F333 -> 0 | F18: ='2.1meta'!G18+'2.1meta'!G35+'2.1meta'!G52+'2.1meta'!G70+'2.1meta'!G87+'2.1meta'!G104+'2.1meta'!G121+'2.1meta'!G138+'2.1meta'!G155+'2.1meta'!G172+'2.1meta'!G189+'2.1meta'!G299+'2.1meta'!G316+'2.1meta'!G333 -> 0 | G18: ='2.1meta'!H18+'2.1meta'!H35+'2.1meta'!H52+'2.1meta'!H70+'2.1meta'!H87+'2.1meta'!H104+'2.1meta'!H121+'2.1meta'!H138+'2.1meta'!H155+'2.1meta'!H172+'2.1meta'!H189+'2.1meta'!H299+'2.1meta'!H316+'2.1meta'!H333 -> 0 | H18: ='2.1meta'!I18+'2.1meta'!I35+'2.1meta'!I52+'2.1meta'!I70+'2.1meta'!I87+'2.1meta'!I104+'2.1meta'!I121+'2.1meta'!I138+'2.1meta'!I155+'2.1meta'!I172+'2.1meta'!I189+'2.1meta'!I299+'2.1meta'!I316+'2.1meta'!I333 -> 0 | I18: ='2.1meta'!J18+'2.1meta'!J35+'2.1meta'!J52+'2.1meta'!J70+'2.1meta'!J87+'2.1meta'!J104+'2.1meta'!J121+'2.1meta'!J138+'2.1meta'!J155+'2.1meta'!J172+'2.1meta'!J189+'2.1meta'!J299+'2.1meta'!J316+'2.1meta'!J333 -> 0 | J18: ='2.1meta'!K18+'2.1meta'!K35+'2.1meta'!K52+'2.1meta'!K70+'2.1meta'!K87+'2.1meta'!K104+'2.1meta'!K121+'2.1meta'!K138+'2.1meta'!K155+'2.1meta'!K172+'2.1meta'!K189+'2.1meta'!K299+'2.1meta'!K316+'2.1meta'!K333 -> 0 | K18: =SUM(F18:J18) -> 0 | L18: =C18-K18 -> 0 | M18: ='2.1meta'!N18+'2.1meta'!N35+'2.1meta'!N52+'2.1meta'!N70+'2.1meta'!N87+'2.1meta'!N104+'2.1meta'!N121+'2.1meta'!N138+'2.1meta'!N155+'2.1meta'!N172+'2.1meta'!N189+'2.1meta'!N299+'2.1meta'!N316+'2.1meta'!N333 -> 0 | N18: ='2.1meta'!O18+'2.1meta'!O35+'2.1meta'!O52+'2.1meta'!O70+'2.1meta'!O87+'2.1meta'!O104+'2.1meta'!O121+'2.1meta'!O138+'2.1meta'!O155+'2.1meta'!O172+'2.1meta'!O189+'2.1meta'!O299+'2.1meta'!O316+'2.1meta'!O333 -> 0 | O18: ='2.1meta'!P18+'2.1meta'!P35+'2.1meta'!P52+'2.1meta'!P70+'2.1meta'!P87+'2.1meta'!P104+'2.1meta'!P121+'2.1meta'!P138+'2.1meta'!P155+'2.1meta'!P172+'2.1meta'!P189+'2.1meta'!P299+'2.1meta'!P316+'2.1meta'!P333 -> 0 | P18: ='2.1meta'!Q18+'2.1meta'!Q35+'2.1meta'!Q52+'2.1meta'!Q70+'2.1meta'!Q87+'2.1meta'!Q104+'2.1meta'!Q121+'2.1meta'!Q138+'2.1meta'!Q155+'2.1meta'!Q172+'2.1meta'!Q189+'2.1meta'!Q299+'2.1meta'!Q316+'2.1meta'!Q333 -> 0 | Q18: ='2.1meta'!R18+'2.1meta'!R35+'2.1meta'!R52+'2.1meta'!R70+'2.1meta'!R87+'2.1meta'!R104+'2.1meta'!R121+'2.1meta'!R138+'2.1meta'!R155+'2.1meta'!R172+'2.1meta'!R189+'2.1meta'!R299+'2.1meta'!R316+'2.1meta'!R333 -> 0 | R18: ='2.1meta'!S18+'2.1meta'!S35+'2.1meta'!S52+'2.1meta'!S70+'2.1meta'!S87+'2.1meta'!S104+'2.1meta'!S121+'2.1meta'!S138+'2.1meta'!S155+'2.1meta'!S172+'2.1meta'!S189+'2.1meta'!S299+'2.1meta'!S316+'2.1meta'!S333 -> 0 | S18: ='2.1meta'!T18+'2.1meta'!T35+'2.1meta'!T52+'2.1meta'!T70+'2.1meta'!T87+'2.1meta'!T104+'2.1meta'!T121+'2.1meta'!T138+'2.1meta'!T155+'2.1meta'!T172+'2.1meta'!T189+'2.1meta'!T299+'2.1meta'!T316+'2.1meta'!T333 -> 0 | T18: ='2.1meta'!U18+'2.1meta'!U35+'2.1meta'!U52+'2.1meta'!U70+'2.1meta'!U87+'2.1meta'!U104+'2.1meta'!U121+'2.1meta'!U138+'2.1meta'!U155+'2.1meta'!U172+'2.1meta'!U189+'2.1meta'!U299+'2.1meta'!U316+'2.1meta'!U333 -> 0 | ... W18: ='2.1meta'!X18+'2.1meta'!X35+'2.1meta'!X52+'2.1meta'!X70+'2.1meta'!X87+'2.1meta'!X104+'2.1meta'!X121+'2.1meta'!X138+'2.1meta'!X155+'2.1meta'!X172+'2.1meta'!X189+'2.1meta'!X299+'2.1meta'!X316+'2.1meta'!X333 -> 0 | X18: =SUM(M18:W18) -> 0 | Y18: =K18+X18 -> 0 | Z18: =C18-Y18 -> 0
