Workbook

Sheet 2.1meta
A1: CUADRO DE EJECUCION Y PROYECCIÓN DE GASTOS DE LA GG 2.1
A2: UE: 003 G.A AREQUIPA
A4: Meta | B4: E.G. | C4: Descripción Específica Gasto | D4: PIM (1) | E4: Certificado | F4: Compromiso Anual | G4: Ejecución Devengado UE | S4: Saldo Presupuestal | U4: Proyeccion de plazas vacantes | W4: PAGO FACTURAS EPS | X4: BENEFICIOS | Y4: TOTAL PROYECCIÓN | Z4: TOTAL EJECUCION +PROYECCION (2) | AA4: Saldo disponible ( 1-2)
G5: Enero | H5: Febrero | I5: Marzo | J5: Abril | K5: Mayo | L5: Junio | M5: Julio | N5: Agosto | O5: Setiembre | P5: Octubre | Q5: Noviembre | R5: TOTAL EJECUCION | T5: Diciembre | U5: 276 | V5: 728
A6: 0001 | D6: =SUBTOTAL(9,D7:D22) -> 0 | E6: =SUBTOTAL(9,E7:E22) -> 0 | F6: =SUBTOTAL(9,F7:F22) -> 0 | G6: =SUBTOTAL(9,G7:G22) -> 0 | H6: =SUBTOTAL(9,H7:H22) -> 0 | I6: =SUBTOTAL(9,I7:I22) -> 0 | J6: =SUBTOTAL(9,J7:J22) -> 0 | K6: =SUBTOTAL(9,K7:K22) -> 0 | ... Q6: =SUBTOTAL(9,Q7:Q22) -> 0 | R6: =SUM(G6:Q6) -> 0 | S6: =D6-R6 -> 0 | T6: =SUBTOTAL(9,T7:T22) -> 0 | U6: =SUBTOTAL(9,U7:U22) -> 0 | V6: =SUBTOTAL(9,V7:V22) -> 0 | W6: =SUBTOTAL(9,W7:W22) -> 0 | X6: =SUBTOTAL(9,X7:X22) -> 0 | Y6: =SUM(T6:X6) -> 0 | Z6: =+R6+Y6 -> 0 | AA6: =+D6-Z6 -> 0
A7: 0001 | B7: 2.1.1.1.1.2 | C7: PERSONAL ADMINISTRATIVO NOMBRADO (REGIMEN PUBLICO) | R7: =SUM(G7:Q7) -> 0 | S7: =D7-R7 -> 0 | U7: 0 | V7: 0 | Y7: =SUM(T7:X7) -> 0 | Z7: =+R7+Y7 -> 0 | AA7: =+D7-Z7 -> 0
A8: 0001 | B8: 2.1.1.1.1.4 | C8: PERSONAL CON CONTRATO A PLAZO INDETERMINADO (REGIMEN | R8: =SUM(G8:Q8) -> 0 | S8: =D8-R8 -> 0 | U8: 0 | V8: 0 | Y8: =SUM(T8:X8) -> 0 | Z8: =+R8+Y8 -> 0 | AA8: =+D8-Z8 -> 0
A9: 0001 | B9: 2.1.1.1.1.5 | C9: PERSONAL CON CONTRATO A PLAZO FIJO (REGIMEN LABORAL | R9: =SUM(G9:Q9) -> 0 | S9: =D9-R9 -> 0 | U9: 0 | V9: 0 | Y9: =SUM(T9:X9) -> 0 | Z9: =+R9+Y9 -> 0 | AA9: =+D9-Z9 -> 0
A10: 0001 | B10: 2.1.1.1.2.1 | C10: ASIGNACION A FONDOS PARA PERSONAL | R10: =SUM(G10:Q10) -> 0 | S10: =D10-R10 -> 0 | U10: 0 | V10: 0 | Y10: =SUM(T10:X10) -> 0 | Z10: =+R10+Y10 -> 0 | AA10: =+D10-Z10 -> 0
A11: 0001 | B11: 2.1.1.4.1.1 | C11: PERSONAL NOMBRADO | R11: =SUM(G11:Q11) -> 0 | S11: =D11-R11 -> 0 | U11: 0 | V11: 0 | Y11: =SUM(T11:X11) -> 0 | Z11: =+R11+Y11 -> 0 | AA11: =+D11-Z11 -> 0
A12: 0001 | B12: 2.1.1.4.2.1 | C12: BONO POR FUNCION JURISDICCIONAL Y FISCAL | R12: =SUM(G12:Q12) -> 0 | S12: =D12-R12 -> 0 | U12: 0 | V12: 0 | Y12: =SUM(T12:X12) -> 0 | Z12: =+R12+Y12 -> 0 | AA12: =+D12-Z12 -> 0
A13: 0001 | B13: 2.1.1.4.2.2 | C13: ASIGNACION POR GASTOS OPERATIVOS | R13: =SUM(G13:Q13) -> 0 | S13: =D13-R13 -> 0 | U13: 0 | V13: 0 | Y13: =SUM(T13:X13) -> 0 | Z13: =+R13+Y13 -> 0 | AA13: =+D13-Z13 -> 0
A14: 0001 | B14: 2.1.1.9.1.1 | C14: GRATIFICACIONES | R14: =SUM(G14:Q14) -> 0 | S14: =D14-R14 -> 0 | U14: 0 | V14: 0 | Y14: =SUM(T14:X14) -> 0 | Z14: =+R14+Y14 -> 0 | AA14: =+D14-Z14 -> 0
A15: 0001 | B15: 2.1.1.9.1.2 | C15: AGUINALDOS | R15: =SUM(G15:Q15) -> 0 | S15: =D15-R15 -> 0 | U15: 0 | V15: 0 | Y15: =SUM(T15:X15) -> 0 | Z15: =+R15+Y15 -> 0 | AA15: =+D15-Z15 -> 0
A16: 0001 | B16: 2.1.1.9.1.3 | C16: BONIFICACION POR ESCOLARIDAD | R16: =SUM(G16:Q16) -> 0 | S16: =D16-R16 -> 0 | U16: 0 | V16: 0 | Y16: =SUM(T16:X16) -> 0 | Z16: =+R16+Y16 -> 0 | AA16: =+D16-Z16 -> 0
A17: 0001 | B17: 2.1.1.9.2.1 | C17: COMPENSACION POR TIEMPO DE SERVICIOS (CTS) | R17: =SUM(G17:Q17) -> 0 | S17: =D17-R17 -> 0 | U17: 0 | V17: 0 | Y17: =SUM(T17:X17) -> 0 | Z17: =+R17+Y17 -> 0 | AA17: =+D17-Z17 -> 0
A18: 0001 | B18: 2.1.1.9.3.3 | C18: COMPENSACION VACACIONAL (VACACIONES TRUNCAS) | R18: =SUM(G18:Q18) -> 0 | S18: =D18-R18 -> 0 | U18: 0 | V18: 0 | Y18: =SUM(T18:X18) -> 0 | Z18: =+R18+Y18 -> 0 | AA18: =+D18-Z18 -> 0
... A22: 0001 | B22: 2.1.3.1.1.5 | C22: CONTRIBUCIONES A ESSALUD | R22: =SUM(G22:Q22) -> 0 | S22: =D22-R22 -> 0 | U22: 0 | V22: 0 | Y22: =SUM(T22:X22) -> 0 | Z22: =+R22+Y22 -> 0 | AA22: =+D22-Z22 -> 0
A23: 0002 | D23: =SUBTOTAL(9,D24:D39) -> 0 | E23: =SUBTOTAL(9,E24:E39) -> 0 | F23: =SUBTOTAL(9,F24:F39) -> 0 | G23: =SUBTOTAL(9,G24:G39) -> 0 | H23: =SUBTOTAL(9,H24:H39) -> 0 | I23: =SUBTOTAL(9,I24:I39) -> 0 | J23: =SUBTOTAL(9,J24:J39) -> 0 | K23: =SUBTOTAL(9,K24:K39) -> 0 | ... Q23: =SUBTOTAL(9,Q24:Q39) -> 0 | R23: =SUM(G23:Q23) -> 0 | S23: =D23-R23 -> 0 | T23: =SUBTOTAL(9,T24:T39) -> 0 | U23: =SUBTOTAL(9,U24:U39) -> 0 | V23: =SUBTOTAL(9,V24:V39) -> 0 | W23: =SUBTOTAL(9,W24:W39) -> 0 | X23: =SUBTOTAL(9,X24:X39) -> 0 | Y23: =SUM(T23:X23) -> 0 | Z23: =+R23+Y23 -> 0 | AA23: =+D23-Z23 -> 0
A24: 0002 | B24: 2.1.1.1.1.2 | C24: PERSONAL ADMINISTRATIVO NOMBRADO (REGIMEN PUBLICO) | R24: =SUM(G24:Q24) -> 0 | S24: =D24-R24 -> 0 | U24: 0 | V24: 0 | Y24: =SUM(T24:X24) -> 0 | Z24: =+R24+Y24 -> 0 | AA24: =+D24-Z24 -> 0
A25: 0002 | B25: 2.1.1.1.1.4 | C25: PERSONAL CON CONTRATO A PLAZO INDETERMINADO (REGIMEN | R25: =SUM(G25:Q25) -> 0 | S25: =D25-R25 -> 0 | U25: 0 | V25: 0 | Y25: =SUM(T25:X25) -> 0 | Z25: =+R25+Y25 -> 0 | AA25: =+D25-Z25 -> 0
A26: 0002 | B26: 2.1.1.1.1.5 | C26: PERSONAL CON CONTRATO A PLAZO FIJO (REGIMEN LABORAL | R26: =SUM(G26:Q26) -> 0 | S26: =D26-R26 -> 0 | U26: 0 | V26: 0 | Y26: =SUM(T26:X26) -> 0 | Z26: =+R26+Y26 -> 0 | AA26: =+D26-Z26 -> 0
A27: 0002 | B27: 2.1.1.1.2.1 | C27: ASIGNACION A FONDOS PARA PERSONAL | R27: =SUM(G27:Q27) -> 0 | S27: =D27-R27 -> 0 | U27: 0 | V27: 0 | Y27: =SUM(T27:X27) -> 0 | Z27: =+R27+Y27 -> 0 | AA27: =+D27-Z27 -> 0
A28: 0002 | B28: 2.1.1.4.1.1 | C28: PERSONAL NOMBRADO | R28: =SUM(G28:Q28) -> 0 | S28: =D28-R28 -> 0 | U28: 0 | V28: 0 | Y28: =SUM(T28:X28) -> 0 | Z28: =+R28+Y28 -> 0 | AA28: =+D28-Z28 -> 0
A29: 0002 | B29: 2.1.1.4.2.1 | C29: BONO POR FUNCION JURISDICCIONAL Y FISCAL | R29: =SUM(G29:Q29) -> 0 | S29: =D29-R29 -> 0 | U29: 0 | V29: 0 | Y29: =SUM(T29:X29) -> 0 | Z29: =+R29+Y29 -> 0 | AA29: =+D29-Z29 -> 0
A30: 0002 | B30: 2.1.1.4.2.2 | C30: ASIGNACION POR GASTOS OPERATIVOS | R30: =SUM(G30:Q30) -> 0 | S30: =D30-R30 -> 0 | U30: 0 | V30: 0 | Y30: =SUM(T30:X30) -> 0 | Z30: =+R30+Y30 -> 0 | AA30: =+D30-Z30 -> 0
A31: 0002 | B31: 2.1.1.9.1.1 | C31: GRATIFICACIONES | R31: =SUM(G31:Q31) -> 0 | S31: =D31-R31 -> 0 | U31: 0 | V31: 0 | Y31: =SUM(T31:X31) -> 0 | Z31: =+R31+Y31 -> 0 | AA31: =+D31-Z31 -> 0
A32: 0002 | B32: 2.1.1.9.1.2 | C32: AGUINALDOS | R32: =SUM(G32:Q32) -> 0 | S32: =D32-R32 -> 0 | U32: 0 | V32: 0 | Y32: =SUM(T32:X32) -> 0 | Z32: =+R32+Y32 -> 0 | AA32: =+D32-Z32 -> 0
A33: 0002 | B33: 2.1.1.9.1.3 | C33: BONIFICACION POR ESCOLARIDAD | R33: =SUM(G33:Q33) -> 0 | S33: =D33-R33 -> 0 | U33: 0 | V33: 0 | Y33: =SUM(T33:X33) -> 0 | Z33: =+R33+Y33 -> 0 | AA33: =+D33-Z33 -> 0
A34: 0002 | B34: 2.1.1.9.2.1 | C34: COMPENSACION POR TIEMPO DE SERVICIOS (CTS) | R34: =SUM(G34:Q34) -> 0 | S34: =D34-R34 -> 0 | U34: 0 | V34: 0 | Y34: =SUM(T34:X34) -> 0 | Z34: =+R34+Y34 -> 0 | AA34: =+D34-Z34 -> 0
A35: 0002 | B35: 2.1.1.9.3.3 | C35: COMPENSACION VACACIONAL (VACACIONES TRUNCAS) | R35: =SUM(G35:Q35) -> 0 | S35: =D35-R35 -> 0 | U35: 0 | V35: 0 | Y35: =SUM(T35:X35) -> 0 | Z35: =+R35+Y35 -> 0 | AA35: =+D35-Z35 -> 0
... A39: 0002 | B39: 2.1.3.1.1.5 | C39: CONTRIBUCIONES A ESSALUD | R39: =SUM(G39:Q39) -> 0 | S39: =D39-R39 -> 0 | U39: 0 | V39: 0 | Y39: =SUM(T39:X39) -> 0 | Z39: =+R39+Y39 -> 0 | AA39: =+D39-Z39 -> 0
A40: 0003 | D40: =SUBTOTAL(9,D41:D56) -> 0 | E40: =SUBTOTAL(9,E41:E56) -> 0 | F40: =SUBTOTAL(9,F41:F56) -> 0 | G40: =SUBTOTAL(9,G41:G56) -> 0 | H40: =SUBTOTAL(9,H41:H56) -> 0 | I40: =SUBTOTAL(9,I41:I56) -> 0 | J40: =SUBTOTAL(9,J41:J56) -> 0 | K40: =SUBTOTAL(9,K41:K56) -> 0 | ... Q40: =SUBTOTAL(9,Q41:Q56) -> 0 | R40: =SUM(G40:Q40) -> 0 | S40: =D40-R40 -> 0 | T40: =SUBTOTAL(9,T41:T56) -> 0 | U40: =SUBTOTAL(9,U41:U56) -> 0 | V40: =SUBTOTAL(9,V41:V56) -> 0 | W40: =SUBTOTAL(9,W41:W56) -> 0 | X40: =SUBTOTAL(9,X41:X56) -> 0 | Y40: =SUM(T40:X40) -> 0 | Z40: =+R40+Y40 -> 0 | AA40: =+D40-Z40 -> 0
A41: 0003 | B41: 2.1.1.1.1.2 | C41: PERSONAL ADMINISTRATIVO NOMBRADO (REGIMEN PUBLICO) | R41: =SUM(G41:Q41) -> 0 | S41: =D41-R41 -> 0 | U41: 0 | V41: 0 | Y41: =SUM(T41:X41) -> 0 | Z41: =+R41+Y41 -> 0 | AA41: =+D41-Z41 -> 0
A42: 0003 | B42: 2.1.1.1.1.4 | C42: PERSONAL CON CONTRATO A PLAZO INDETERMINADO (REGIMEN | R42: =SUM(G42:Q42) -> 0 | S42: =D42-R42 -> 0 | U42: 0 | V42: 0 | Y42: =SUM(T42:X42) -> 0 | Z42: =+R42+Y42 -> 0 | AA42: =+D42-Z42 -> 0
A43: 0003 | B43: 2.1.1.1.1.5 | C43: PERSONAL CON CONTRATO A PLAZO FIJO (REGIMEN LABORAL | R43: =SUM(G43:Q43) -> 0 | S43: =D43-R43 -> 0 | U43: 0 | V43: 0 | Y43: =SUM(T43:X43) -> 0 | Z43: =+R43+Y43 -> 0 | AA43: =+D43-Z43 -> 0
A44: 0003 | B44: 2.1.1.1.2.1 | C44: ASIGNACION A FONDOS PARA PERSONAL | R44: =SUM(G44:Q44) -> 0 | S44: =D44-R44 -> 0 | U44: 0 | V44: 0 | Y44: =SUM(T44:X44) -> 0 | Z44: =+R44+Y44 -> 0 | AA44: =+D44-Z44 -> 0
A45: 0003 | B45: 2.1.1.4.1.1 | C45: PERSONAL NOMBRADO | R45: =SUM(G45:Q45) -> 0 | S45: =D45-R45 -> 0 | U45: 0 | V45: 0 | Y45: =SUM(T45:X45) -> 0 | Z45: =+R45+Y45 -> 0 | AA45: =+D45-Z45 -> 0
A46: 0003 | B46: 2.1.1.4.2.1 | C46: BONO POR FUNCION JURISDICCIONAL Y FISCAL | R46: =SUM(G46:Q46) -> 0 | S46: =D46-R46 -> 0 | U46: 0 | V46: 0 | Y46: =SUM(T46:X46) -> 0 | Z46: =+R46+Y46 -> 0 | AA46: =+D46-Z46 -> 0
A47: 0003 | B47: 2.1.1.4.2.2 | C47: ASIGNACION POR GASTOS OPERATIVOS | R47: =SUM(G47:Q47) -> 0 | S47: =D47-R47 -> 0 | U47: 0 | V47: 0 | Y47: =SUM(T47:X47) -> 0 | Z47: =+R47+Y47 -> 0 | AA47: =+D47-Z47 -> 0
...

Sheet CATEGORIA PRESUPUESTAL
A1: EJECUTORA: 0003 MINISTERIO PUBLICO - GERENCIA ADMINISTRATIVA DE AREQUIPA (1419)
A3: Cat pptal/ Detalle Específica de Gasto | C3: PIM | D3: Certificado | E3: Compromiso Anual | F3: Ejecución Devengado UE | Q3: T O T A L | R3: Saldo Presupuestal al 17.09.2021 | T3: Proyeccion de plazas vacantes | V3: PAGO FACTURAS EPS | W3: BENEFICIOS | X3: TOTAL PROYECCION | Y3: TOTAL EJECUCION +PROYECCION | Z3: SALDO DISPONIBLE
F4: 01 ENERO | G4: 02 FEBRERO | H4: 03 MARZO | I4: 04 ABRIL | J4: 05 MAYO | K4: 06 JUNIO | L4: 07 JULIO | M4: 08 AGOSTO | N4: 09 SETIEMBRE | O4: 10 OCTUBRE | P4: 11 NOVIEMBRE | S4: 12 DICIEMBRE | T4: 276 | U4: 728
A5: 0086 MEJORA DE LOS SERVICIOS DEL SISTEMA DE JUSTICIA PENAL | C5: =SUBTOTAL(9,C6:C22) -> 0 | D5: =SUBTOTAL(9,D6:D22) -> 0 | E5: =SUBTOTAL(9,E6:E22) -> 0 | F5: =SUBTOTAL(9,F6:F22) -> 0 | G5: =SUBTOTAL(9,G6:G22) -> 0 | H5: =SUBTOTAL(9,H6:H22) -> 0 | I5: =SUBTOTAL(9,I6:I22) -> 0 | J5: =SUBTOTAL(9,J6:J22) -> 0 | ... Q5: =SUBTOTAL(9,Q6:Q22) -> 0 | R5: =C5-Q5 -> 0 | S5: =SUBTOTAL(9,S6:S22) -> 0 | T5: =SUBTOTAL(9,T6:T22) -> 0 | U5: =SUBTOTAL(9,U6:U22) -> 0 | V5: =SUBTOTAL(9,V6:V22) -> 0 | W5: =SUBTOTAL(9,W6:W22) -> 0 | X5: =SUBTOTAL(9,X6:X22) -> 0 | Y5: =SUBTOTAL(9,Y6:Y22) -> 0 | Z5: =SUBTOTAL(9,Z6:Z22) -> 0
A6: 2.1.1.1.1.2 | B6: PERSONAL ADMINISTRATIVO NOMBRADO (REGIMEN PUBLICO) | C6: ='2.1meta'!D7+'2.1meta'!D24+'2.1meta'!D41+'2.1meta'!D58+'2.1meta'!D76+'2.1meta'!D93+'2.1meta'!D110+'2.1meta'!D127+'2.1meta'!D144+'2.1meta'!D161+'2.1meta'!D178+'2.1meta'!D288+'2.1meta'!D305+'2.1meta'!D322 -> 0 | D6: ='2.1meta'!E7+'2.1meta'!E24+'2.1meta'!E41+'2.1meta'!E58+'2.1meta'!E76+'2.1meta'!E93+'2.1meta'!E110+'2.1meta'!E127+'2.1meta'!E144+'2.1meta'!E161+'2.1meta'!E178+'2.1meta'!E288+'2.1meta'!E305+'2.1meta'!E322 -> 0 | E6: ='2.1meta'!F7+'2.1meta'!F24+'2.1meta'!F41+'2.1meta'!F58+'2.1meta'!F76+'2.1meta'!F93+'2.1meta'!F110+'2.1meta'!F127+'2.1meta'!F144+'2.1meta'!F161+'2.1meta'!F178+'2.1meta'!F288+'2.1meta'!F305+'2.1meta'!F322 -> 0 | F6: ='2.1meta'!G7+'2.1meta'!G24+'2.1meta'!G41+'2.1meta'!G58+'2.1meta'!G76+'2.1meta'!G93+'2.1meta'!G110+'2.1meta'!G127+'2.1meta'!G144+'2.1meta'!G161+'2.1meta'!G178+'2.1meta'!G288+'2.1meta'!G305+'2.1meta'!G322 -> 0 | G6: ='2.1meta'!H7+'2.1meta'!H24+'2.1meta'!H41+'2.1meta'!H58+'2.1meta'!H76+'2.1meta'!H93+'2.1meta'!H110+'2.1meta'!H127+'2.1meta'!H144+'2.1meta'!H161+'2.1meta'!H178+'2.1meta'!H288+'2.1meta'!H305+'2.1meta'!H322 -> 0 | H6: ='2.1meta'!I7+'2.1meta'!I24+'2.1meta'!I41+'2.1meta'!I58+'2.1meta'!I76+'2.1meta'!I93+'2.1meta'!I110+'2.1meta'!I127+'2.1meta'!I144+'2.1meta'!I161+'2.1meta'!I178+'2.1meta'!I288+'2.1meta'!I305+'2.1meta'!I322 -> 0 | I6: ='2.1meta'!J7+'2.1meta'!J24+'2.1meta'!J41+'2.1meta'!J58+'2.1meta'!J76+'2.1meta'!J93+'2.1meta'!J110+'2.1meta'!J127+'2.1meta'!J144+'2.1meta'!J161+'2.1meta'!J178+'2.1meta'!J288+'2.1meta'!J305+'2.1meta'!J322 -> 0 | J6: ='2.1meta'!K7+'2.1meta'!K24+'2.1meta'!K41+'2.1meta'!K58+'2.1meta'!K76+'2.1meta'!K93+'2.1meta'!K110+'2.1meta'!K127+'2.1meta'!K144+'2.1meta'!K161+'2.1meta'!K178+'2.1meta'!K288+'2.1meta'!K305+'2.1meta'!K322 -> 0 | ... P6: ='2.1meta'!Q7+'2.1meta'!Q24+'2.1meta'!Q41+'2.1meta'!Q58+'2.1meta'!Q76+'2.1meta'!Q93+'2.1meta'!Q110+'2.1meta'!Q127+'2.1meta'!Q144+'2.1meta'!Q161+'2.1meta'!Q178+'2.1meta'!Q288+'2.1meta'!Q305+'2.1meta'!Q322 -> 0 | Q6: =SUM(F6:P6) -> 0 | R6: =C6-Q6 -> 0 | S6: ='2.1meta'!T7+'2.1meta'!T24+'2.1meta'!T41+'2.1meta'!T58+'2.1meta'!T76+'2.1meta'!T93+'2.1meta'!T110+'2.1meta'!T127+'2.1meta'!T144+'2.1meta'!T161+'2.1meta'!T178+'2.1meta'!T288+'2.1meta'!T305+'2.1meta'!T322 -> 0 | T6: ='2.1meta'!U7+'2.1meta'!U24+'2.1meta'!U41+'2.1meta'!U58+'2.1meta'!U76+'2.1meta'!U93+'2.1meta'!U110+'2.1meta'!U127+'2.1meta'!U144+'2.1meta'!U161+'2.1meta'!U178+'2.1meta'!U288+'2.1meta'!U305+'2.1meta'!U322 -> 0 | U6: ='2.1meta'!V7+'2.1meta'!V24+'2.1meta'!V41+'2.1meta'!V58+'2.1meta'!V76+'2.1meta'!V93+'2.1meta'!V110+'2.1meta'!V127+'2.1meta'!V144+'2.1meta'!V161+'2.1meta'!V178+'2.1meta'!V288+'2.1meta'!V305+'2.1meta'!V322 -> 0 | V6: ='2.1meta'!W7+'2.1meta'!W24+'2.1meta'!W41+'2.1meta'!W58+'2.1meta'!W76+'2.1meta'!W93+'2.1meta'!W110+'2.1meta'!W127+'2.1meta'!W144+'2.1meta'!W161+'2.1meta'!W178+'2.1meta'!W288+'2.1meta'!W305+'2.1meta'!W322 -> 0 | W6: ='2.1meta'!X7+'2.1meta'!X24+'2.1meta'!X41+'2.1meta'!X58+'2.1meta'!X76+'2.1meta'!X93+'2.1meta'!X110+'2.1meta'!X127+'2.1meta'!X144+'2.1meta'!X161+'2.1meta'!X178+'2.1meta'!X288+'2.1meta'!X305+'2.1meta'!X322 -> 0 | X6: =SUM(S6:W6) -> 0 | Y6: =Q6+X6 -> 0 | Z6: =C6-Y6 -> 0
A7: 2.1.1.1.1.4 | B7: PERSONAL CON CONTRATO A PLAZO INDETERMINADO (REGIMEN LABORAL PRIVADO) | C7: ='2.1meta'!D8+'2.1meta'!D25+'2.1meta'!D42+'2.1meta'!D59+'2.1meta'!D77+'2.1meta'!D94+'2.1meta'!D111+'2.1meta'!D128+'2.1meta'!D145+'2.1meta'!D162+'2.1meta'!D179+'2.1meta'!D289+'2.1meta'!D306+'2.1meta'!D323 -> 0 | D7: ='2.1meta'!E8+'2.1meta'!E25+'2.1meta'!E42+'2.1meta'!E59+'2.1meta'!E77+'2.1meta'!E94+'2.1meta'!E111+'2.1meta'!E128+'2.1meta'!E145+'2.1meta'!E162+'2.1meta'!E179+'2.1meta'!E289+'2.1meta'!E306+'2.1meta'!E323 -> 0 | E7: ='2.1meta'!F8+'2.1meta'!F25+'2.1meta'!F42+'2.1meta'!F59+'2.1meta'!F77+'2.1meta'!F94+'2.1meta'!F111+'2.1meta'!F128+'2.1meta'!F145+'2.1meta'!F162+'2.1meta'!F179+'2.1meta'!F289+'2.1meta'!F306+'2.1meta'!F323 -> 0 | F7: ='2.1meta'!G8+'2.1meta'!G25+'2.1meta'!G42+'2.1meta'!G59+'2.1meta'!G77+'2.1meta'!G94+'2.1meta'!G111+'2.1meta'!G128+'2.1meta'!G145+'2.1meta'!G162+'2.1meta'!G179+'2.1meta'!G289+'2.1meta'!G306+'2.1meta'!G323 -> 0 | G7: ='2.1meta'!H8+'2.1meta'!H25+'2.1meta'!H42+'2.1meta'!H59+'2.1meta'!H77+'2.1meta'!H94+'2.1meta'!H111+'2.1meta'!H128+'2.1meta'!H145+'2.1meta'!H162+'2.1meta'!H179+'2.1meta'!H289+'2.1meta'!H306+'2.1meta'!H323 -> 0 | H7: ='2.1meta'!I8+'2.1meta'!I25+'2.1meta'!I42+'2.1meta'!I59+'2.1meta'!I77+'2.1meta'!I94+'2.1meta'!I111+'2.1meta'!I128+'2.1meta'!I145+'2.1meta'!I162+'2.1meta'!I179+'2.1meta'!I289+'2.1meta'!I306+'2.1meta'!I323 -> 0 | I7: ='2.1meta'!J8+'2.1meta'!J25+'2.1meta'!J42+'2.1meta'!J59+'2.1meta'!J77+'2.1meta'!J94+'2.1meta'!J111+'2.1meta'!J128+'2.1meta'!J145+'2.1meta'!J162+'2.1meta'!J179+'2.1meta'!J289+'2.1meta'!J306+'2.1meta'!J323 -> 0 | J7: ='2.1meta'!K8+'2.1meta'!K25+'2.1meta'!K42+'2.1meta'!K59+'2.1meta'!K77+'2.1meta'!K94+'2.1meta'!K111+'2.1meta'!K128+'2.1meta'!K145+'2.1meta'!K162+'2.1meta'!K179+'2.1meta'!K289+'2.1meta'!K306+'2.1meta'!K323 -> 0 | ... P7: ='2.1meta'!Q8+'2.1meta'!Q25+'2.1meta'!Q42+'2.1meta'!Q59+'2.1meta'!Q77+'2.1meta'!Q94+'2.1meta'!Q111+'2.1meta'!Q128+'2.1meta'!Q145+'2.1meta'!Q162+'2.1meta'!Q179+'2.1meta'!Q289+'2.1meta'!Q306+'2.1meta'!Q323 -> 0 | Q7: =SUM(F7:P7) -> 0 | R7: =C7-Q7 -> 0 | S7: ='2.1meta'!T8+'2.1meta'!T25+'2.1meta'!T42+'2.1meta'!T59+'2.1meta'!T77+'2.1meta'!T94+'2.1meta'!T111+'2.1meta'!T128+'2.1meta'!T145+'2.1meta'!T162+'2.1meta'!T179+'2.1meta'!T289+'2.1meta'!T306+'2.1meta'!T323 -> 0 | T7: ='2.1meta'!U8+'2.1meta'!U25+'2.1meta'!U42+'2.1meta'!U59+'2.1meta'!U77+'2.1meta'!U94+'2.1meta'!U111+'2.1meta'!U128+'2.1meta'!U145+'2.1meta'!U162+'2.1meta'!U179+'2.1meta'!U289+'2.1meta'!U306+'2.1meta'!U323 -> 0 | U7: ='2.1meta'!V8+'2.1meta'!V25+'2.1meta'!V42+'2.1meta'!V59+'2.1meta'!V77+'2.1meta'!V94+'2.1meta'!V111+'2.1meta'!V128+'2.1meta'!V145+'2.1meta'!V162+'2.1meta'!V179+'2.1meta'!V289+'2.1meta'!V306+'2.1meta'!V323 -> 0 | V7: ='2.1meta'!W8+'2.1meta'!W25+'2.1meta'!W42+'2.1meta'!W59+'2.1meta'!W77+'2.1meta'!W94+'2.1meta'!W111+'2.1meta'!W128+'2.1meta'!W145+'2.1meta'!W162+'2.1meta'!W179+'2.1meta'!W289+'2.1meta'!W306+'2.1meta'!W323 -> 0 | W7: ='2.1meta'!X8+'2.1meta'!X25+'2.1meta'!X42+'2.1meta'!X59+'2.1meta'!X77+'2.1meta'!X94+'2.1meta'!X111+'2.1meta'!X128+'2.1meta'!X145+'2.1meta'!X162+'2.1meta'!X179+'2.1meta'!X289+'2.1meta'!X306+'2.1meta'!X323 -> 0 | X7: =SUM(S7:W7) -> 0 | Y7: =Q7+X7 -> 0 | Z7: =C7-Y7 -> 0
A8: 2.1.1.1.1.5 | B8: PERSONAL CON CONTRATO A PLAZO FIJO (REGIMEN LABORAL PRIVADO) | C8: ='2.1meta'!D9+'2.1meta'!D26+'2.1meta'!D43+'2.1meta'!D60+'2.1meta'!D78+'2.1meta'!D95+'2.1meta'!D112+'2.1meta'!D129+'2.1meta'!D146+'2.1meta'!D163+'2.1meta'!D180+'2.1meta'!D290+'2.1meta'!D307+'2.1meta'!D324 -> 0 | D8: ='2.1meta'!E8+'2.1meta'!E25+'2.1meta'!E42+'2.1meta'!E60+'2.1meta'!E77+'2.1meta'!E94+'2.1meta'!E111+'2.1meta'!E128+'2.1meta'!E145+'2.1meta'!E162+'2.1meta'!E179+'2.1meta'!E289+'2.1meta'!E306+'2.1meta'!E323 -> 0 | E8: ='2.1meta'!F8+'2.1meta'!F25+'2.1meta'!F42+'2.1meta'!F60+'2.1meta'!F77+'2.1meta'!F94+'2.1meta'!F111+'2.1meta'!F128+'2.1meta'!F145+'2.1meta'!F162+'2.1meta'!F179+'2.1meta'!F289+'2.1meta'!F306+'2.1meta'!F323 -> 0 | F8: ='2.1meta'!G9+'2.1meta'!G26+'2.1meta'!G43+'2.1meta'!G60+'2.1meta'!G78+'2.1meta'!G95+'2.1meta'!G112+'2.1meta'!G129+'2.1meta'!G146+'2.1meta'!G163+'2.1meta'!G180+'2.1meta'!G290+'2.1meta'!G307+'2.1meta'!G324 -> 0 | G8: ='2.1meta'!H9+'2.1meta'!H26+'2.1meta'!H43+'2.1meta'!H60+'2.1meta'!H78+'2.1meta'!H95+'2.1meta'!H112+'2.1meta'!H129+'2.1meta'!H146+'2.1meta'!H163+'2.1meta'!H180+'2.1meta'!H290+'2.1meta'!H307+'2.1meta'!H324 -> 0 | H8: ='2.1meta'!I9+'2.1meta'!I26+'2.1meta'!I43+'2.1meta'!I60+'2.1meta'!I78+'2.1meta'!I95+'2.1meta'!I112+'2.1meta'!I129+'2.1meta'!I146+'2.1meta'!I163+'2.1meta'!I180+'2.1meta'!I290+'2.1meta'!I307+'2.1meta'!I324 -> 0 | I8: ='2.1meta'!J9+'2.1meta'!J26+'2.1meta'!J43+'2.1meta'!J60+'2.1meta'!J78+'2.1meta'!J95+'2.1meta'!J112+'2.1meta'!J129+'2.1meta'!J146+'2.1meta'!J163+'2.1meta'!J180+'2.1meta'!J290+'2.1meta'!J307+'2.1meta'!J324 -> 0 | J8: ='2.1meta'!K9+'2.1meta'!K26+'2.1meta'!K43+'2.1meta'!K60+'2.1meta'!K78+'2.1meta'!K95+'2.1meta'!K112+'2.1meta'!K129+'2.1meta'!K146+'2.1meta'!K163+'2.1meta'!K180+'2.1meta'!K290+'2.1meta'!K307+'2.1meta'!K324 -> 0 | K8: ='2.1meta'!L9+'2.1meta'!L26+'2.1meta'!L43+'2.1meta'!L60+'2.1meta'!L78+'2.1meta'!L95+'2.1meta'!L112+'2.1meta'!L129+'2.1meta'!L146+'2.1meta'!L163+'2.1meta'!L180+'2.1meta'!L290+'2.1meta'!L307+'2.1meta'!L324 -> 0 | L8: ='2.1meta'!M9+'2.1meta'!M26+'2.1meta'!M43+'2.1meta'!M60+'2.1meta'!M78+'2.1meta'!M95+'2.1meta'!M112+'2.1meta'!M129+'2.1meta'!M146+'2.1meta'!M163+'2.1meta'!M180+'2.1meta'!M290+'2.1meta'!M307+'2.1meta'!M324 -> 0 | M8: ='2.1meta'!N9+'2.1meta'!N26+'2.1meta'!N43+'2.1meta'!N60+'2.1meta'!N78+'2.1meta'!N95+'2.1meta'!N112+'2.1meta'!N129+'2.1meta'!N146+'2.1meta'!N163+'2.1meta'!N180+'2.1meta'!N290+'2.1meta'!N307+'2.1meta'!N324 -> 0 | ... P8: ='2.1meta'!Q9+'2.1meta'!Q26+'2.1meta'!Q43+'2.1meta'!Q60+'2.1meta'!Q78+'2.1meta'!Q95+'2.1meta'!Q112+'2.1meta'!Q129+'2.1meta'!Q146+'2.1meta'!Q163+'2.1meta'!Q180+'2.1meta'!Q290+'2.1meta'!Q307+'2.1meta'!Q324 -> 0 | Q8: =SUM(F8:P8) -> 0 | R8: =C8-Q8 -> 0 | S8: ='2.1meta'!T9+'2.1meta'!T26+'2.1meta'!T43+'2.1meta'!T60+'2.1meta'!T78+'2.1meta'!T95+'2.1meta'!T112+'2.1meta'!T129+'2.1meta'!T146+'2.1meta'!T163+'2.1meta'!T180+'2.1meta'!T290+'2.1meta'!T307+'2.1meta'!T324 -> 0 | T8: ='2.1meta'!U9+'2.1meta'!U26+'2.1meta'!U43+'2.1meta'!U60+'2.1meta'!U78+'2.1meta'!U95+'2.1meta'!U112+'2.1meta'!U129+'2.1meta'!U146+'2.1meta'!U163+'2.1meta'!U180+'2.1meta'!U290+'2.1meta'!U307+'2.1meta'!U324 -> 0 | U8: ='2.1meta'!V9+'2.1meta'!V26+'2.1meta'!V43+'2.1meta'!V60+'2.1meta'!V78+'2.1meta'!V95+'2.1meta'!V112+'2.1meta'!V129+'2.1meta'!V146+'2.1meta'!V163+'2.1meta'!V180+'2.1meta'!V290+'2.1meta'!V307+'2.1meta'!V324 -> 0 | V8: ='2.1meta'!W9+'2.1meta'!W26+'2.1meta'!W43+'2.1meta'!W60+'2.1meta'!W78+'2.1meta'!W95+'2.1meta'!W112+'2.1meta'!W129+'2.1meta'!W146+'2.1meta'!W163+'2.1meta'!W180+'2.1meta'!W290+'2.1meta'!W307+'2.1meta'!W324 -> 0 | W8: ='2.1meta'!X9+'2.1meta'!X26+'2.1meta'!X43+'2.1meta'!X60+'2.1meta'!X78+'2.1meta'!X95+'2.1meta'!X112+'2.1meta'!X129+'2.1meta'!X146+'2.1meta'!X163+'2.1meta'!X180+'2.1meta'!X290+'2.1meta'!X307+'2.1meta'!X324 -> 0 | X8: =SUM(S8:W8) -> 0 | Y8: =Q8+X8 -> 0 | Z8: =C8-Y8 -> 0
A9: 2.1.1.1.2.1 | B9: ASIGNACION A FONDOS PARA PERSONAL | C9: ='2.1meta'!D10+'2.1meta'!D27+'2.1meta'!D44+'2.1meta'!D61+'2.1meta'!D79+'2.1meta'!D96+'2.1meta'!D113+'2.1meta'!D130+'2.1meta'!D147+'2.1meta'!D164+'2.1meta'!D181+'2.1meta'!D291+'2.1meta'!D308+'2.1meta'!D325 -> 0 | D9: ='2.1meta'!E9+'2.1meta'!E26+'2.1meta'!E43+'2.1meta'!E61+'2.1meta'!E78+'2.1meta'!E95+'2.1meta'!E112+'2.1meta'!E129+'2.1meta'!E146+'2.1meta'!E163+'2.1meta'!E180+'2.1meta'!E290+'2.1meta'!E307+'2.1meta'!E324 -> 0 | E9: ='2.1meta'!F9+'2.1meta'!F26+'2.1meta'!F43+'2.1meta'!F61+'2.1meta'!F78+'2.1meta'!F95+'2.1meta'!F112+'2.1meta'!F129+'2.1meta'!F146+'2.1meta'!F163+'2.1meta'!F180+'2.1meta'!F290+'2.1meta'!F307+'2.1meta'!F324 -> 0 | F9: ='2.1meta'!G10+'2.1meta'!G27+'2.1meta'!G44+'2.1meta'!G61+'2.1meta'!G79+'2.1meta'!G96+'2.1meta'!G113+'2.1meta'!G130+'2.1meta'!G147+'2.1meta'!G164+'2.1meta'!G181+'2.1meta'!G291+'2.1meta'!G308+'2.1meta'!G325 -> 0 | G9: ='2.1meta'!H10+'2.1meta'!H27+'2.1meta'!H44+'2.1meta'!H61+'2.1meta'!H79+'2.1meta'!H96+'2.1meta'!H113+'2.1meta'!H130+'2.1meta'!H147+'2.1meta'!H164+'2.1meta'!H181+'2.1meta'!H291+'2.1meta'!H308+'2.1meta'!H325 -> 0 | H9: ='2.1meta'!I10+'2.1meta'!I27+'2.1meta'!I44+'2.1meta'!I61+'2.1meta'!I79+'2.1meta'!I96+'2.1meta'!I113+'2.1meta'!I130+'2.1meta'!I147+'2.1meta'!I164+'2.1meta'!I181+'2.1meta'!I291+'2.1meta'!I308+'2.1meta'!I325 -> 0 | I9: ='2.1meta'!J10+'2.1meta'!J27+'2.1meta'!J44+'2.1meta'!J61+'2.1meta'!J79+'2.1meta'!J96+'2.1meta'!J113+'2.1meta'!J130+'2.1meta'!J147+'2.1meta'!J164+'2.1meta'!J181+'2.1meta'!J291+'2.1meta'!J308+'2.1meta'!J325 -> 0 | J9: ='2.1meta'!K10+'2.1meta'!K27+'2.1meta'!K44+'2.1meta'!K61+'2.1meta'!K79+'2.1meta'!K96+'2.1meta'!K113+'2.1meta'!K130+'2.1meta'!K147+'2.1meta'!K164+'2.1meta'!K181+'2.1meta'!K291+'2.1meta'!K308+'2.1meta'!K325 -> 0 | K9: ='2.1meta'!L10+'2.1meta'!L27+'2.1meta'!L44+'2.1meta'!L61+'2.1meta'!L79+'2.1meta'!L96+'2.1meta'!L113+'2.1meta'!L130+'2.1meta'!L147+'2.1meta'!L164+'2.1meta'!L181+'2.1meta'!L291+'2.1meta'!L308+'2.1meta'!L325 -> 0 | L9: ='2.1meta'!M10+'2.1meta'!M27+'2.1meta'!M44+'2.1meta'!M61+'2.1meta'!M79+'2.1meta'!M96+'2.1meta'!M113+'2.1meta'!M130+'2.1meta'!M147+'2.1meta'!M164+'2.1meta'!M181+'2.1meta'!M291+'2.1meta'!M308+'2.1meta'!M325 -> 0 | M9: ='2.1meta'!N10+'2.1meta'!N27+'2.1meta'!N44+'2.1meta'!N61+'2.1meta'!N79+'2.1meta'!N96+'2.1meta'!N113+'2.1meta'!N130+'2.1meta'!N147+'2.1meta'!N164+'2.1meta'!N181+'2.1meta'!N291+'2.1meta'!N308+'2.1meta'!N325 -> 0 | ... P9: ='2.1meta'!Q10+'2.1meta'!Q27+'2.1meta'!Q44+'2.1meta'!Q61+'2.1meta'!Q79+'2.1meta'!Q96+'2.1meta'!Q113+'2.1meta'!Q130+'2.1meta'!Q147+'2.1meta'!Q164+'2.1meta'!Q181+'2.1meta'!Q291+'2.1meta'!Q308+'2.1meta'!Q325 -> 0 | Q9: =SUM(F9:P9) -> 0 | R9: =C9-Q9 -> 0 | S9: ='2.1meta'!T10+'2.1meta'!T27+'2.1meta'!T44+'2.1meta'!T61+'2.1meta'!T79+'2.1meta'!T96+'2.1meta'!T113+'2.1meta'!T130+'2.1meta'!T147+'2.1meta'!T164+'2.1meta'!T181+'2.1meta'!T291+'2.1meta'!T308+'2.1meta'!T325 -> 0 | T9: ='2.1meta'!U10+'2.1meta'!U27+'2.1meta'!U44+'2.1meta'!U61+'2.1meta'!U79+'2.1meta'!U96+'2.1meta'!U113+'2.1meta'!U130+'2.1meta'!U147+'2.1meta'!U164+'2.1meta'!U181+'2.1meta'!U291+'2.1meta'!U308+'2.1meta'!U325 -> 0 | U9: ='2.1meta'!V10+'2.1meta'!V27+'2.1meta'!V44+'2.1meta'!V61+'2.1meta'!V79+'2.1meta'!V96+'2.1meta'!V113+'2.1meta'!V130+'2.1meta'!V147+'2.1meta'!V164+'2.1meta'!V181+'2.1meta'!V291+'2.1meta'!V308+'2.1meta'!V325 -> 0 | V9: ='2.1meta'!W10+'2.1meta'!W27+'2.1meta'!W44+'2.1meta'!W61+'2.1meta'!W79+'2.1meta'!W96+'2.1meta'!W113+'2.1meta'!W130+'2.1meta'!W147+'2.1meta'!W164+'2.1meta'!W181+'2.1meta'!W291+'2.1meta'!W308+'2.1meta'!W325 -> 0 | W9: ='2.1meta'!X10+'2.1meta'!X27+'2.1meta'!X44+'2.1meta'!X61+'2.1meta'!X79+'2.1meta'!X96+'2.1meta'!X113+'2.1meta'!X130+'2.1meta'!X147+'2.1meta'!X164+'2.1meta'!X181+'2.1meta'!X291+'2.1meta'!X308+'2.1meta'!X325 -> 0 | X9: =SUM(S9:W9) -> 0 | Y9: =Q9+X9 -> 0 | Z9: =C9-Y9 -> 0
A10: 2.1.1.3.1.2 | B10: PERSONAL CONTRATADO | C10: ='2.1meta'!D62 -> 0 | D10: ='2.1meta'!E10+'2.1meta'!E27+'2.1meta'!E44+'2.1meta'!E62+'2.1meta'!E79+'2.1meta'!E96+'2.1meta'!E113+'2.1meta'!E130+'2.1meta'!E147+'2.1meta'!E164+'2.1meta'!E181+'2.1meta'!E291+'2.1meta'!E308+'2.1meta'!E325 -> 0 | E10: ='2.1meta'!F10+'2.1meta'!F27+'2.1meta'!F44+'2.1meta'!F62+'2.1meta'!F79+'2.1meta'!F96+'2.1meta'!F113+'2.1meta'!F130+'2.1meta'!F147+'2.1meta'!F164+'2.1meta'!F181+'2.1meta'!F291+'2.1meta'!F308+'2.1meta'!F325 -> 0 | F10: ='2.1meta'!G62 -> 0 | G10: ='2.1meta'!H62 -> 0 | H10: ='2.1meta'!I62 -> 0 | I10: ='2.1meta'!J62 -> 0 | J10: ='2.1meta'!K62 -> 0 | K10: ='2.1meta'!L62 -> 0 | L10: ='2.1meta'!M62 -> 0 | M10: ='2.1meta'!N62 -> 0 | ... P10: ='2.1meta'!Q62 -> 0 | Q10: =SUM(F10:P10) -> 0 | R10: =C10-Q10 -> 0 | S10: ='2.1meta'!T62 -> 0 | T10: ='2.1meta'!U62 -> 0 | U10: ='2.1meta'!V62 -> 0 | V10: ='2.1meta'!W62 -> 0 | W10: ='2.1meta'!X62 -> 0 | X10: =SUM(S10:W10) -> 0 | Y10: =Q10+X10 -> 0 | Z10: =C10-Y10 -> 0
A11: 2.1.1.4.1.1 | B11: PERSONAL NOMBRADO | C11: ='2.1meta'!D11+'2.1meta'!D28+'2.1meta'!D45+'2.1meta'!D63+'2.1meta'!D80+'2.1meta'!D97+'2.1meta'!D114+'2.1meta'!D131+'2.1meta'!D148+'2.1meta'!D165+'2.1meta'!D182+'2.1meta'!D292+'2.1meta'!D309+'2.1meta'!D326 -> 0 | D11: ='2.1meta'!E11+'2.1meta'!E28+'2.1meta'!E45+'2.1meta'!E63+'2.1meta'!E80+'2.1meta'!E97+'2.1meta'!E114+'2.1meta'!E131+'2.1meta'!E148+'2.1meta'!E165+'2.1meta'!E182+'2.1meta'!E292+'2.1meta'!E309+'2.1meta'!E326 -> 0 | E11: ='2.1meta'!F11+'2.1meta'!F28+'2.1meta'!F45+'2.1meta'!F63+'2.1meta'!F80+'2.1meta'!F97+'2.1meta'!F114+'2.1meta'!F131+'2.1meta'!F148+'2.1meta'!F165+'2.1meta'!F182+'2.1meta'!F292+'2.1meta'!F309+'2.1meta'!F326 -> 0 | F11: ='2.1meta'!G11+'2.1meta'!G28+'2.1meta'!G45+'2.1meta'!G63+'2.1meta'!G80+'2.1meta'!G97+'2.1meta'!G114+'2.1meta'!G131+'2.1meta'!G148+'2.1meta'!G165+'2.1meta'!G182+'2.1meta'!G292+'2.1meta'!G309+'2.1meta'!G326 -> 0 | G11: ='2.1meta'!H11+'2.1meta'!H28+'2.1meta'!H45+'2.1meta'!H63+'2.1meta'!H80+'2.1meta'!H97+'2.1meta'!H114+'2.1meta'!H131+'2.1meta'!H148+'2.1meta'!H165+'2.1meta'!H182+'2.1meta'!H292+'2.1meta'!H309+'2.1meta'!H326 -> 0 | H11: ='2.1meta'!I11+'2.1meta'!I28+'2.1meta'!I45+'2.1meta'!I63+'2.1meta'!I80+'2.1meta'!I97+'2.1meta'!I114+'2.1meta'!I131+'2.1meta'!I148+'2.1meta'!I165+'2.1meta'!I182+'2.1meta'!I292+'2.1meta'!I309+'2.1meta'!I326 -> 0 | I11: ='2.1meta'!J11+'2.1meta'!J28+'2.1meta'!J45+'2.1meta'!J63+'2.1meta'!J80+'2.1meta'!J97+'2.1meta'!J114+'2.1meta'!J131+'2.1meta'!J148+'2.1meta'!J165+'2.1meta'!J182+'2.1meta'!J292+'2.1meta'!J309+'2.1meta'!J326 -> 0 | J11: ='2.1meta'!K11+'2.1meta'!K28+'2.1meta'!K45+'2.1meta'!K63+'2.1meta'!K80+'2.1meta'!K97+'2.1meta'!K114+'2.1meta'!K131+'2.1meta'!K148+'2.1meta'!K165+'2.1meta'!K182+'2.1meta'!K292+'2.1meta'!K309+'2.1meta'!K326 -> 0 | ... P11: ='2.1meta'!Q11+'2.1meta'!Q28+'2.1meta'!Q45+'2.1meta'!Q63+'2.1meta'!Q80+'2.1meta'!Q97+'2.1meta'!Q114+'2.1meta'!Q131+'2.1meta'!Q148+'2.1meta'!Q165+'2.1meta'!Q182+'2.1meta'!Q292+'2.1meta'!Q309+'2.1meta'!Q326 -> 0 | Q11: =SUM(F11:P11) -> 0 | R11: =C11-Q11 -> 0 | S11: ='2.1meta'!T11+'2.1meta'!T28+'2.1meta'!T45+'2.1meta'!T63+'2.1meta'!T80+'2.1meta'!T97+'2.1meta'!T114+'2.1meta'!T131+'2.1meta'!T148+'2.1meta'!T165+'2.1meta'!T182+'2.1meta'!T292+'2.1meta'!T309+'2.1meta'!T326 -> 0 | T11: ='2.1meta'!U11+'2.1meta'!U28+'2.1meta'!U45+'2.1meta'!U63+'2.1meta'!U80+'2.1meta'!U97+'2.1meta'!U114+'2.1meta'!U131+'2.1meta'!U148+'2.1meta'!U165+'2.1meta'!U182+'2.1meta'!U292+'2.1meta'!U309+'2.1meta'!U326 -> 0 | U11: ='2.1meta'!V11+'2.1meta'!V28+'2.1meta'!V45+'2.1meta'!V63+'2.1meta'!V80+'2.1meta'!V97+'2.1meta'!V114+'2.1meta'!V131+'2.1meta'!V148+'2.1meta'!V165+'2.1meta'!V182+'2.1meta'!V292+'2.1meta'!V309+'2.1meta'!V326 -> 0 | V11: ='2.1meta'!W11+'2.1meta'!W28+'2.1meta'!W45+'2.1meta'!W63+'2.1meta'!W80+'2.1meta'!W97+'2.1meta'!W114+'2.1meta'!W131+'2.1meta'!W148+'2.1meta'!W165+'2.1meta'!W182+'2.1meta'!W292+'2.1meta'!W309+'2.1meta'!W326 -> 0 | W11: ='2.1meta'!X11+'2.1meta'!X28+'2.1meta'!X45+'2.1meta'!X63+'2.1meta'!X80+'2.1meta'!X97+'2.1meta'!X114+'2.1meta'!X131+'2.1meta'!X148+'2.1meta'!X165+'2.1meta'!X182+'2.1meta'!X292+'2.1meta'!X309+'2.1meta'!X326 -> 0 | X11: =SUM(S11:W11) -> 0 | Y11: =Q11+X11 -> 0 | Z11: =C11-Y11 -> 0
A12: 2.1.1.4.2.1 | B12: BONO POR FUNCION JURISDICCIONAL Y FISCAL | C12: ='2.1meta'!D12+'2.1meta'!D29+'2.1meta'!D46+'2.1meta'!D64+'2.1meta'!D81+'2.1meta'!D98+'2.1meta'!D115+'2.1meta'!D132+'2.1meta'!D149+'2.1meta'!D166+'2.1meta'!D183+'2.1meta'!D293+'2.1meta'!D310+'2.1meta'!D327 -> 0 | D12: ='2.1meta'!E12+'2.1meta'!E29+'2.1meta'!E46+'2.1meta'!E64+'2.1meta'!E81+'2.1meta'!E98+'2.1meta'!E115+'2.1meta'!E132+'2.1meta'!E149+'2.1meta'!E166+'2.1meta'!E183+'2.1meta'!E293+'2.1meta'!E310+'2.1meta'!E327 -> 0 | E12: ='2.1meta'!F12+'2.1meta'!F29+'2.1meta'!F46+'2.1meta'!F64+'2.1meta'!F81+'2.1meta'!F98+'2.1meta'!F115+'2.1meta'!F132+'2.1meta'!F149+'2.1meta'!F166+'2.1meta'!F183+'2.1meta'!F293+'2.1meta'!F310+'2.1meta'!F327 -> 0 | F12: ='2.1meta'!G12+'2.1meta'!G29+'2.1meta'!G46+'2.1meta'!G64+'2.1meta'!G81+'2.1meta'!G98+'2.1meta'!G115+'2.1meta'!G132+'2.1meta'!G149+'2.1meta'!G166+'2.1meta'!G183+'2.1meta'!G293+'2.1meta'!G310+'2.1meta'!G327 -> 0 | G12: ='2.1meta'!H12+'2.1meta'!H29+'2.1meta'!H46+'2.1meta'!H64+'2.1meta'!H81+'2.1meta'!H98+'2.1meta'!H115+'2.1meta'!H132+'2.1meta'!H149+'2.1meta'!H166+'2.1meta'!H183+'2.1meta'!H293+'2.1meta'!H310+'2.1meta'!H327 -> 0 | H12: ='2.1meta'!I12+'2.1meta'!I29+'2.1meta'!I46+'2.1meta'!I64+'2.1meta'!I81+'2.1meta'!I98+'2.1meta'!I115+'2.1meta'!I132+'2.1meta'!I149+'2.1meta'!I166+'2.1meta'!I183+'2.1meta'!I293+'2.1meta'!I310+'2.1meta'!I327 -> 0 | I12: ='2.1meta'!J12+'2.1meta'!J29+'2.1meta'!J46+'2.1meta'!J64+'2.1meta'!J81+'2.1meta'!J98+'2.1meta'!J115+'2.1meta'!J132+'2.1meta'!J149+'2.1meta'!J166+'2.1meta'!J183+'2.1meta'!J293+'2.1meta'!J310+'2.1meta'!J327 -> 0 | J12: ='2.1meta'!K12+'2.1meta'!K29+'2.1meta'!K46+'2.1meta'!K64+'2.1meta'!K81+'2.1meta'!K98+'2.1meta'!K115+'2.1meta'!K132+'2.1meta'!K149+'2.1meta'!K166+'2.1meta'!K183+'2.1meta'!K293+'2.1meta'!K310+'2.1meta'!K327 -> 0 | ... P12: ='2.1meta'!Q12+'2.1meta'!Q29+'2.1meta'!Q46+'2.1meta'!Q64+'2.1meta'!Q81+'2.1meta'!Q98+'2.1meta'!Q115+'2.1meta'!Q132+'2.1meta'!Q149+'2.1meta'!Q166+'2.1meta'!Q183+'2.1meta'!Q293+'2.1meta'!Q310+'2.1meta'!Q327 -> 0 | Q12: =SUM(F12:P12) -> 0 | R12: =C12-Q12 -> 0 | S12: ='2.1meta'!T12+'2.1meta'!T29+'2.1meta'!T46+'2.1meta'!T64+'2.1meta'!T81+'2.1meta'!T98+'2.1meta'!T115+'2.1meta'!T132+'2.1meta'!T149+'2.1meta'!T166+'2.1meta'!T183+'2.1meta'!T293+'2.1meta'!T310+'2.1meta'!T327 -> 0 | T12: ='2.1meta'!U12+'2.1meta'!U29+'2.1meta'!U46+'2.1meta'!U64+'2.1meta'!U81+'2.1meta'!U98+'2.1meta'!U115+'2.1meta'!U132+'2.1meta'!U149+'2.1meta'!U166+'2.1meta'!U183+'2.1meta'!U293+'2.1meta'!U310+'2.1meta'!U327 -> 0 | U12: ='2.1meta'!V12+'2.1meta'!V29+'2.1meta'!V46+'2.1meta'!V64+'2.1meta'!V81+'2.1meta'!V98+'2.1meta'!V115+'2.1meta'!V132+'2.1meta'!V149+'2.1meta'!V166+'2.1meta'!V183+'2.1meta'!V293+'2.1meta'!V310+'2.1meta'!V327 -> 0 | V12: ='2.1meta'!W12+'2.1meta'!W29+'2.1meta'!W46+'2.1meta'!W64+'2.1meta'!W81+'2.1meta'!W98+'2.1meta'!W115+'2.1meta'!W132+'2.1meta'!W149+'2.1meta'!W166+'2.1meta'!W183+'2.1meta'!W293+'2.1meta'!W310+'2.1meta'!W327 -> 0 | W12: ='2.1meta'!X13+'2.1meta'!X30+'2.1meta'!X47+'2.1meta'!X64+'2.1meta'!X82+'2.1meta'!X99+'2.1meta'!X116+'2.1meta'!X133+'2.1meta'!X150+'2.1meta'!X167+'2.1meta'!X184+'2.1meta'!X294+'2.1meta'!X311+'2.1meta'!X328 -> 0 | X12: =SUM(S12:W12) -> 0 | Y12: =Q12+X12 -> 0 | Z12: =C12-Y12 -> 0
A13: 2.1.1.4.2.2 | B13: ASIGNACION POR GASTOS OPERATIVOS | C13: ='2.1meta'!D13+'2.1meta'!D30+'2.1meta'!D47+'2.1meta'!D65+'2.1meta'!D82+'2.1meta'!D99+'2.1meta'!D116+'2.1meta'!D133+'2.1meta'!D150+'2.1meta'!D167+'2.1meta'!D184+'2.1meta'!D294+'2.1meta'!D311+'2.1meta'!D328 -> 0 | D13: ='2.1meta'!E13+'2.1meta'!E30+'2.1meta'!E47+'2.1meta'!E65+'2.1meta'!E82+'2.1meta'!E99+'2.1meta'!E116+'2.1meta'!E133+'2.1meta'!E150+'2.1meta'!E167+'2.1meta'!E184+'2.1meta'!E294+'2.1meta'!E311+'2.1meta'!E328 -> 0 | E13: ='2.1meta'!F13+'2.1meta'!F30+'2.1meta'!F47+'2.1meta'!F65+'2.1meta'!F82+'2.1meta'!F99+'2.1meta'!F116+'2.1meta'!F133+'2.1meta'!F150+'2.1meta'!F167+'2.1meta'!F184+'2.1meta'!F294+'2.1meta'!F311+'2.1meta'!F328 -> 0 | F13: ='2.1meta'!G13+'2.1meta'!G30+'2.1meta'!G47+'2.1meta'!G65+'2.1meta'!G82+'2.1meta'!G99+'2.1meta'!G116+'2.1meta'!G133+'2.1meta'!G150+'2.1meta'!G167+'2.1meta'!G184+'2.1meta'!G294+'2.1meta'!G311+'2.1meta'!G328 -> 0 | G13: ='2.1meta'!H13+'2.1meta'!H30+'2.1meta'!H47+'2.1meta'!H65+'2.1meta'!H82+'2.1meta'!H99+'2.1meta'!H116+'2.1meta'!H133+'2.1meta'!H150+'2.1meta'!H167+'2.1meta'!H184+'2.1meta'!H294+'2.1meta'!H311+'2.1meta'!H328 -> 0 | H13: ='2.1meta'!I13+'2.1meta'!I30+'2.1meta'!I47+'2.1meta'!I65+'2.1meta'!I82+'2.1meta'!I99+'2.1meta'!I116+'2.1meta'!I133+'2.1meta'!I150+'2.1meta'!I167+'2.1meta'!I184+'2.1meta'!I294+'2.1meta'!I311+'2.1meta'!I328 -> 0 | I13: ='2.1meta'!J13+'2.1meta'!J30+'2.1meta'!J47+'2.1meta'!J65+'2.1meta'!J82+'2.1meta'!J99+'2.1meta'!J116+'2.1meta'!J133+'2.1meta'!J150+'2.1meta'!J167+'2.1meta'!J184+'2.1meta'!J294+'2.1meta'!J311+'2.1meta'!J328 -> 0 | J13: ='2.1meta'!K13+'2.1meta'!K30+'2.1meta'!K47+'2.1meta'!K65+'2.1meta'!K82+'2.1meta'!K99+'2.1meta'!K116+'2.1meta'!K133+'2.1meta'!K150+'2.1meta'!K167+'2.1meta'!K184+'2.1meta'!K294+'2.1meta'!K311+'2.1meta'!K328 -> 0 | ... P13: ='2.1meta'!Q13+'2.1meta'!Q30+'2.1meta'!Q47+'2.1meta'!Q65+'2.1meta'!Q82+'2.1meta'!Q99+'2.1meta'!Q116+'2.1meta'!Q133+'2.1meta'!Q150+'2.1meta'!Q167+'2.1meta'!Q184+'2.1meta'!Q294+'2.1meta'!Q311+'2.1meta'!Q328 -> 0 | Q13: =SUM(F13:P13) -> 0 | R13: =C13-Q13 -> 0 | S13: ='2.1meta'!T13+'2.1meta'!T30+'2.1meta'!T47+'2.1meta'!T65+'2.1meta'!T82+'2.1meta'!T99+'2.1meta'!T116+'2.1meta'!T133+'2.1meta'!T150+'2.1meta'!T167+'2.1meta'!T184+'2.1meta'!T294+'2.1meta'!T311+'2.1meta'!T328 -> 0 | T13: ='2.1meta'!U13+'2.1meta'!U30+'2.1meta'!U47+'2.1meta'!U65+'2.1meta'!U82+'2.1meta'!U99+'2.1meta'!U116+'2.1meta'!U133+'2.1meta'!U150+'2.1meta'!U167+'2.1meta'!U184+'2.1meta'!U294+'2.1meta'!U311+'2.1meta'!U328 -> 0 | U13: ='2.1meta'!V13+'2.1meta'!V30+'2.1meta'!V47+'2.1meta'!V65+'2.1meta'!V82+'2.1meta'!V99+'2.1meta'!V116+'2.1meta'!V133+'2.1meta'!V150+'2.1meta'!V167+'2.1meta'!V184+'2.1meta'!V294+'2.1meta'!V311+'2.1meta'!V328 -> 0 | V13: ='2.1meta'!W13+'2.1meta'!W30+'2.1meta'!W47+'2.1meta'!W65+'2.1meta'!W82+'2.1meta'!W99+'2.1meta'!W116+'2.1meta'!W133+'2.1meta'!W150+'2.1meta'!W167+'2.1meta'!W184+'2.1meta'!W294+'2.1meta'!W311+'2.1meta'!W328 -> 0 | W13: ='2.1meta'!X13+'2.1meta'!X30+'2.1meta'!X47+'2.1meta'!X65+'2.1meta'!X82+'2.1meta'!X99+'2.1meta'!X116+'2.1meta'!X133+'2.1meta'!X150+'2.1meta'!X167+'2.1meta'!X184+'2.1meta'!X294+'2.1meta'!X311+'2.1meta'!X328 -> 0 | X13: =SUM(S13:W13) -> 0 | Y13: =Q13+X13 -> 0 | Z13: =C13-Y13 -> 0
A14: 2.1.1.9.1.1 | B14: GRATIFICACIONES | C14: ='2.1meta'!D14+'2.1meta'!D31+'2.1meta'!D48+'2.1meta'!D66+'2.1meta'!D83+'2.1meta'!D100+'2.1meta'!D117+'2.1meta'!D134+'2.1meta'!D151+'2.1meta'!D168+'2.1meta'!D185+'2.1meta'!D295+'2.1meta'!D312+'2.1meta'!D329 -> 0 | D14: ='2.1meta'!E14+'2.1meta'!E31+'2.1meta'!E48+'2.1meta'!E66+'2.1meta'!E83+'2.1meta'!E100+'2.1meta'!E117+'2.1meta'!E134+'2.1meta'!E151+'2.1meta'!E168+'2.1meta'!E185+'2.1meta'!E295+'2.1meta'!E312+'2.1meta'!E329 -> 0 | E14: ='2.1meta'!F14+'2.1meta'!F31+'2.1meta'!F48+'2.1meta'!F66+'2.1meta'!F83+'2.1meta'!F100+'2.1meta'!F117+'2.1meta'!F134+'2.1meta'!F151+'2.1meta'!F168+'2.1meta'!F185+'2.1meta'!F295+'2.1meta'!F312+'2.1meta'!F329 -> 0 | F14: ='2.1meta'!G14+'2.1meta'!G31+'2.1meta'!G48+'2.1meta'!G66+'2.1meta'!G83+'2.1meta'!G100+'2.1meta'!G117+'2.1meta'!G134+'2.1meta'!G151+'2.1meta'!G168+'2.1meta'!G185+'2.1meta'!G295+'2.1meta'!G312+'2.1meta'!G329 -> 0 | G14: ='2.1meta'!H14+'2.1meta'!H31+'2.1meta'!H48+'2.1meta'!H66+'2.1meta'!H83+'2.1meta'!H100+'2.1meta'!H117+'2.1meta'!H134+'2.1meta'!H151+'2.1meta'!H168+'2.1meta'!H185+'2.1meta'!H295+'2.1meta'!H312+'2.1meta'!H329 -> 0 | H14: ='2.1meta'!I14+'2.1meta'!I31+'2.1meta'!I48+'2.1meta'!I66+'2.1meta'!I83+'2.1meta'!I100+'2.1meta'!I117+'2.1meta'!I134+'2.1meta'!I151+'2.1meta'!I168+'2.1meta'!I185+'2.1meta'!I295+'2.1meta'!I312+'2.1meta'!I329 -> 0 | I14: ='2.1meta'!J14+'2.1meta'!J31+'2.1meta'!J48+'2.1meta'!J66+'2.1meta'!J83+'2.1meta'!J100+'2.1meta'!J117+'2.1meta'!J134+'2.1meta'!J151+'2.1meta'!J168+'2.1meta'!J185+'2.1meta'!J295+'2.1meta'!J312+'2.1meta'!J329 -> 0 | J14: ='2.1meta'!K14+'2.1meta'!K31+'2.1meta'!K48+'2.1meta'!K66+'2.1meta'!K83+'2.1meta'!K100+'2.1meta'!K117+'2.1meta'!K134+'2.1meta'!K151+'2.1meta'!K168+'2.1meta'!K185+'2.1meta'!K295+'2.1meta'!K312+'2.1meta'!K329 -> 0 | ... P14: ='2.1meta'!Q14+'2.1meta'!Q31+'2.1meta'!Q48+'2.1meta'!Q66+'2.1meta'!Q83+'2.1meta'!Q100+'2.1meta'!Q117+'2.1meta'!Q134+'2.1meta'!Q151+'2.1meta'!Q168+'2.1meta'!Q185+'2.1meta'!Q295+'2.1meta'!Q312+'2.1meta'!Q329 -> 0 | Q14: =SUM(F14:P14) -> 0 | R14: =C14-Q14 -> 0 | S14: ='2.1meta'!T14+'2.1meta'!T31+'2.1meta'!T48+'2.1meta'!T66+'2.1meta'!T83+'2.1meta'!T100+'2.1meta'!T117+'2.1meta'!T134+'2.1meta'!T151+'2.1meta'!T168+'2.1meta'!T185+'2.1meta'!T295+'2.1meta'!T312+'2.1meta'!T329 -> 0 | T14: ='2.1meta'!U14+'2.1meta'!U31+'2.1meta'!U48+'2.1meta'!U66+'2.1meta'!U83+'2.1meta'!U100+'2.1meta'!U117+'2.1meta'!U134+'2.1meta'!U151+'2.1meta'!U168+'2.1meta'!U185+'2.1meta'!U295+'2.1meta'!U312+'2.1meta'!U329 -> 0 | U14: ='2.1meta'!V14+'2.1meta'!V31+'2.1meta'!V48+'2.1meta'!V66+'2.1meta'!V83+'2.1meta'!V100+'2.1meta'!V117+'2.1meta'!V134+'2.1meta'!V151+'2.1meta'!V168+'2.1meta'!V185+'2.1meta'!V295+'2.1meta'!V312+'2.1meta'!V329 -> 0 | V14: ='2.1meta'!W14+'2.1meta'!W31+'2.1meta'!W48+'2.1meta'!W66+'2.1meta'!W83+'2.1meta'!W100+'2.1meta'!W117+'2.1meta'!W134+'2.1meta'!W151+'2.1meta'!W168+'2.1meta'!W185+'2.1meta'!W295+'2.1meta'!W312+'2.1meta'!W329 -> 0 | W14: ='2.1meta'!X14+'2.1meta'!X31+'2.1meta'!X48+'2.1meta'!X66+'2.1meta'!X83+'2.1meta'!X100+'2.1meta'!X117+'2.1meta'!X134+'2.1meta'!X151+'2.1meta'!X168+'2.1meta'!X185+'2.1meta'!X295+'2.1meta'!X312+'2.1meta'!X329 -> 0 | X14: =SUM(S14:W14) -> 0 | Y14: =Q14+X14 -> 0 | Z14: =C14-Y14 -> 0
A15: 2.1.1.9.1.2 | B15: AGUINALDOS | C15: ='2.1meta'!D15+'2.1meta'!D32+'2.1meta'!D49+'2.1meta'!D67+'2.1meta'!D84+'2.1meta'!D101+'2.1meta'!D118+'2.1meta'!D135+'2.1meta'!D152+'2.1meta'!D169+'2.1meta'!D186+'2.1meta'!D296+'2.1meta'!D313+'2.1meta'!D330 -> 0 | D15: ='2.1meta'!E15+'2.1meta'!E32+'2.1meta'!E49+'2.1meta'!E66+'2.1meta'!E84+'2.1meta'!E101+'2.1meta'!E118+'2.1meta'!E135+'2.1meta'!E152+'2.1meta'!E169+'2.1meta'!E186+'2.1meta'!E296+'2.1meta'!E313+'2.1meta'!E330 -> 0 | E15: ='2.1meta'!F15+'2.1meta'!F32+'2.1meta'!F49+'2.1meta'!F66+'2.1meta'!F84+'2.1meta'!F101+'2.1meta'!F118+'2.1meta'!F135+'2.1meta'!F152+'2.1meta'!F169+'2.1meta'!F186+'2.1meta'!F296+'2.1meta'!F313+'2.1meta'!F330 -> 0 | F15: ='2.1meta'!G15+'2.1meta'!G32+'2.1meta'!G49+'2.1meta'!G67+'2.1meta'!G84+'2.1meta'!G101+'2.1meta'!G118+'2.1meta'!G135+'2.1meta'!G152+'2.1meta'!G169+'2.1meta'!G186+'2.1meta'!G296+'2.1meta'!G313+'2.1meta'!G330 -> 0 | G15: ='2.1meta'!H15+'2.1meta'!H32+'2.1meta'!H49+'2.1meta'!H67+'2.1meta'!H84+'2.1meta'!H101+'2.1meta'!H118+'2.1meta'!H135+'2.1meta'!H152+'2.1meta'!H169+'2.1meta'!H186+'2.1meta'!H296+'2.1meta'!H313+'2.1meta'!H330 -> 0 | H15: ='2.1meta'!I15+'2.1meta'!I32+'2.1meta'!I49+'2.1meta'!I67+'2.1meta'!I84+'2.1meta'!I101+'2.1meta'!I118+'2.1meta'!I135+'2.1meta'!I152+'2.1meta'!I169+'2.1meta'!I186+'2.1meta'!I296+'2.1meta'!I313+'2.1meta'!I330 -> 0 | I15: ='2.1meta'!J15+'2.1meta'!J32+'2.1meta'!J49+'2.1meta'!J67+'2.1meta'!J84+'2.1meta'!J101+'2.1meta'!J118+'2.1meta'!J135+'2.1meta'!J152+'2.1meta'!J169+'2.1meta'!J186+'2.1meta'!J296+'2.1meta'!J313+'2.1meta'!J330 -> 0 | J15: ='2.1meta'!K15+'2.1meta'!K32+'2.1meta'!K49+'2.1meta'!K67+'2.1meta'!K84+'2.1meta'!K101+'2.1meta'!K118+'2.1meta'!K135+'2.1meta'!K152+'2.1meta'!K169+'2.1meta'!K186+'2.1meta'!K296+'2.1meta'!K313+'2.1meta'!K330 -> 0 | K15: ='2.1meta'!L15+'2.1meta'!L32+'2.1meta'!L49+'2.1meta'!L67+'2.1meta'!L84+'2.1meta'!L101+'2.1meta'!L118+'2.1meta'!L135+'2.1meta'!L152+'2.1meta'!L169+'2.1meta'!L186+'2.1meta'!L296+'2.1meta'!L313+'2.1meta'!L330 -> 0 | L15: ='2.1meta'!M15+'2.1meta'!M32+'2.1meta'!M49+'2.1meta'!M67+'2.1meta'!M84+'2.1meta'!M101+'2.1meta'!M118+'2.1meta'!M135+'2.1meta'!M152+'2.1meta'!M169+'2.1meta'!M186+'2.1meta'!M296+'2.1meta'!M313+'2.1meta'!M330 -> 0 | M15: ='2.1meta'!N15+'2.1meta'!N32+'2.1meta'!N49+'2.1meta'!N67+'2.1meta'!N84+'2.1meta'!N101+'2.1meta'!N118+'2.1meta'!N135+'2.1meta'!N152+'2.1meta'!N169+'2.1meta'!N186+'2.1meta'!N296+'2.1meta'!N313+'2.1meta'!N330 -> 0 | ... P15: ='2.1meta'!Q15+'2.1meta'!Q32+'2.1meta'!Q49+'2.1meta'!Q67+'2.1meta'!Q84+'2.1meta'!Q101+'2.1meta'!Q118+'2.1meta'!Q135+'2.1meta'!Q152+'2.1meta'!Q169+'2.1meta'!Q186+'2.1meta'!Q296+'2.1meta'!Q313+'2.1meta'!Q330 -> 0 | Q15: =SUM(F15:P15) -> 0 | R15: =C15-Q15 -> 0 | S15: ='2.1meta'!T15+'2.1meta'!T32+'2.1meta'!T49+'2.1meta'!T67+'2.1meta'!T84+'2.1meta'!T101+'2.1meta'!T118+'2.1meta'!T135+'2.1meta'!T152+'2.1meta'!T169+'2.1meta'!T186+'2.1meta'!T296+'2.1meta'!T313+'2.1meta'!T330 -> 0 | T15: ='2.1meta'!U15+'2.1meta'!U32+'2.1meta'!U49+'2.1meta'!U67+'2.1meta'!U84+'2.1meta'!U101+'2.1meta'!U118+'2.1meta'!U135+'2.1meta'!U152+'2.1meta'!U169+'2.1meta'!U186+'2.1meta'!U296+'2.1meta'!U313+'2.1meta'!U330 -> 0 | U15: ='2.1meta'!V15+'2.1meta'!V32+'2.1meta'!V49+'2.1meta'!V67+'2.1meta'!V84+'2.1meta'!V101+'2.1meta'!V118+'2.1meta'!V135+'2.1meta'!V152+'2.1meta'!V169+'2.1meta'!V186+'2.1meta'!V296+'2.1meta'!V313+'2.1meta'!V330 -> 0 | V15: ='2.1meta'!W15+'2.1meta'!W32+'2.1meta'!W49+'2.1meta'!W67+'2.1meta'!W84+'2.1meta'!W101+'2.1meta'!W118+'2.1meta'!W135+'2.1meta'!W152+'2.1meta'!W169+'2.1meta'!W186+'2.1meta'!W296+'2.1meta'!W313+'2.1meta'!W330 -> 0 | W15: ='2.1meta'!X15+'2.1meta'!X32+'2.1meta'!X49+'2.1meta'!X67+'2.1meta'!X84+'2.1meta'!X101+'2.1meta'!X118+'2.1meta'!X135+'2.1meta'!X152+'2.1meta'!X169+'2.1meta'!X186+'2.1meta'!X296+'2.1meta'!X313+'2.1meta'!X330 -> 0 | X15: =SUM(S15:W15) -> 0 | Y15: =Q15+X15 -> 0 | Z15: =C15-Y15 -> 0
A16: 2.1.1.9.1.3 | B16: BONIFICACION POR ESCOLARIDAD | C16: ='2.1meta'!D16+'2.1meta'!D33+'2.1meta'!D50+'2.1meta'!D68+'2.1meta'!D85+'2.1meta'!D102+'2.1meta'!D119+'2.1meta'!D136+'2.1meta'!D153+'2.1meta'!D170+'2.1meta'!D187+'2.1meta'!D297+'2.1meta'!D314+'2.1meta'!D331 -> 0 | D16: ='2.1meta'!E16+'2.1meta'!E33+'2.1meta'!E50+'2.1meta'!E68+'2.1meta'!E85+'2.1meta'!E102+'2.1meta'!E119+'2.1meta'!E136+'2.1meta'!E153+'2.1meta'!E170+'2.1meta'!E187+'2.1meta'!E297+'2.1meta'!E314+'2.1meta'!E331 -> 0 | E16: ='2.1meta'!F16+'2.1meta'!F33+'2.1meta'!F50+'2.1meta'!F68+'2.1meta'!F85+'2.1meta'!F102+'2.1meta'!F119+'2.1meta'!F136+'2.1meta'!F153+'2.1meta'!F170+'2.1meta'!F187+'2.1meta'!F297+'2.1meta'!F314+'2.1meta'!F331 -> 0 | F16: ='2.1meta'!G16+'2.1meta'!G33+'2.1meta'!G50+'2.1meta'!G68+'2.1meta'!G85+'2.1meta'!G102+'2.1meta'!G119+'2.1meta'!G136+'2.1meta'!G153+'2.1meta'!G170+'2.1meta'!G187+'2.1meta'!G297+'2.1meta'!G314+'2.1meta'!G331 -> 0 | G16: ='2.1meta'!H16+'2.1meta'!H33+'2.1meta'!H50+'2.1meta'!H68+'2.1meta'!H85+'2.1meta'!H102+'2.1meta'!H119+'2.1meta'!H136+'2.1meta'!H153+'2.1meta'!H170+'2.1meta'!H187+'2.1meta'!H297+'2.1meta'!H314+'2.1meta'!H331 -> 0 | H16: ='2.1meta'!I16+'2.1meta'!I33+'2.1meta'!I50+'2.1meta'!I68+'2.1meta'!I85+'2.1meta'!I102+'2.1meta'!I119+'2.1meta'!I136+'2.1meta'!I153+'2.1meta'!I170+'2.1meta'!I187+'2.1meta'!I297+'2.1meta'!I314+'2.1meta'!I331 -> 0 | I16: ='2.1meta'!J16+'2.1meta'!J33+'2.1meta'!J50+'2.1meta'!J68+'2.1meta'!J85+'2.1meta'!J102+'2.1meta'!J119+'2.1meta'!J136+'2.1meta'!J153+'2.1meta'!J170+'2.1meta'!J187+'2.1meta'!J297+'2.1meta'!J314+'2.1meta'!J331 -> 0 | J16: ='2.1meta'!K16+'2.1meta'!K33+'2.1meta'!K50+'2.1meta'!K68+'2.1meta'!K85+'2.1meta'!K102+'2.1meta'!K119+'2.1meta'!K136+'2.1meta'!K153+'2.1meta'!K170+'2.1meta'!K187+'2.1meta'!K297+'2.1meta'!K314+'2.1meta'!K331 -> 0 | ... P16: ='2.1meta'!Q16+'2.1meta'!Q33+'2.1meta'!Q50+'2.1meta'!Q68+'2.1meta'!Q85+'2.1meta'!Q102+'2.1meta'!Q119+'2.1meta'!Q136+'2.1meta'!Q153+'2.1meta'!Q170+'2.1meta'!Q187+'2.1meta'!Q297+'2.1meta'!Q314+'2.1meta'!Q331 -> 0 | Q16: =SUM(F16:P16) -> 0 | R16: =C16-Q16 -> 0 | S16: ='2.1meta'!T16+'2.1meta'!T33+'2.1meta'!T50+'2.1meta'!T68+'2.1meta'!T85+'2.1meta'!T102+'2.1meta'!T119+'2.1meta'!T136+'2.1meta'!T153+'2.1meta'!T170+'2.1meta'!T187+'2.1meta'!T297+'2.1meta'!T314+'2.1meta'!T331 -> 0 | T16: ='2.1meta'!U16+'2.1meta'!U33+'2.1meta'!U50+'2.1meta'!U68+'2.1meta'!U85+'2.1meta'!U102+'2.1meta'!U119+'2.1meta'!U136+'2.1meta'!U153+'2.1meta'!U170+'2.1meta'!U187+'2.1meta'!U297+'2.1meta'!U314+'2.1meta'!U331 -> 0 | U16: ='2.1meta'!V16+'2.1meta'!V33+'2.1meta'!V50+'2.1meta'!V68+'2.1meta'!V85+'2.1meta'!V102+'2.1meta'!V119+'2.1meta'!V136+'2.1meta'!V153+'2.1meta'!V170+'2.1meta'!V187+'2.1meta'!V297+'2.1meta'!V314+'2.1meta'!V331 -> 0 | V16: ='2.1meta'!W16+'2.1meta'!W33+'2.1meta'!W50+'2.1meta'!W68+'2.1meta'!W85+'2.1meta'!W102+'2.1meta'!W119+'2.1meta'!W136+'2.1meta'!W153+'2.1meta'!W170+'2.1meta'!W187+'2.1meta'!W297+'2.1meta'!W314+'2.1meta'!W331 -> 0 | W16: ='2.1meta'!X16+'2.1meta'!X33+'2.1meta'!X50+'2.1meta'!X68+'2.1meta'!X85+'2.1meta'!X102+'2.1meta'!X119+'2.1meta'!X136+'2.1meta'!X153+'2.1meta'!X170+'2.1meta'!X187+'2.1meta'!X297+'2.1meta'!X314+'2.1meta'!X331 -> 0 | X16: =SUM(S16:W16) -> 0 | Y16: =Q16+X16 -> 0 | Z16: =C16-Y16 -> 0
A17: 2.1.1.9.2.1 | B17: COMPENSACION POR TIEMPO DE SERVICIOS (CTS) | C17: ='2.1meta'!D17+'2.1meta'!D34+'2.1meta'!D51+'2.1meta'!D69+'2.1meta'!D86+'2.1meta'!D103+'2.1meta'!D120+'2.1meta'!D137+'2.1meta'!D154+'2.1meta'!D171+'2.1meta'!D188+'2.1meta'!D298+'2.1meta'!D315+'2.1meta'!D332 -> 0 | D17: ='2.1meta'!E17+'2.1meta'!E34+'2.1meta'!E51+'2.1meta'!E69+'2.1meta'!E86+'2.1meta'!E103+'2.1meta'!E120+'2.1meta'!E137+'2.1meta'!E154+'2.1meta'!E171+'2.1meta'!E188+'2.1meta'!E298+'2.1meta'!E315+'2.1meta'!E332 -> 0 | E17: ='2.1meta'!F17+'2.1meta'!F34+'2.1meta'!F51+'2.1meta'!F69+'2.1meta'!F86+'2.1meta'!F103+'2.1meta'!F120+'2.1meta'!F137+'2.1meta'!F154+'2.1meta'!F171+'2.1meta'!F188+'2.1meta'!F298+'2.1meta'!F315+'2.1meta'!F332 -> 0 | F17: ='2.1meta'!G17+'2.1meta'!G34+'2.1meta'!G51+'2.1meta'!G69+'2.1meta'!G86+'2.1meta'!G103+'2.1meta'!G120+'2.1meta'!G137+'2.1meta'!G154+'2.1meta'!G171+'2.1meta'!G188+'2.1meta'!G298+'2.1meta'!G315+'2.1meta'!G332 -> 0 | G17: ='2.1meta'!H17+'2.1meta'!H34+'2.1meta'!H51+'2.1meta'!H69+'2.1meta'!H86+'2.1meta'!H103+'2.1meta'!H120+'2.1meta'!H137+'2.1meta'!H154+'2.1meta'!H171+'2.1meta'!H188+'2.1meta'!H298+'2.1meta'!H315+'2.1meta'!H332 -> 0 | H17: ='2.1meta'!I17+'2.1meta'!I34+'2.1meta'!I51+'2.1meta'!I69+'2.1meta'!I86+'2.1meta'!I103+'2.1meta'!I120+'2.1meta'!I137+'2.1meta'!I154+'2.1meta'!I171+'2.1meta'!I188+'2.1meta'!I298+'2.1meta'!I315+'2.1meta'!I332 -> 0 | I17: ='2.1meta'!J17+'2.1meta'!J34+'2.1meta'!J51+'2.1meta'!J69+'2.1meta'!J86+'2.1meta'!J103+'2.1meta'!J120+'2.1meta'!J137+'2.1meta'!J154+'2.1meta'!J171+'2.1meta'!J188+'2.1meta'!J298+'2.1meta'!J315+'2.1meta'!J332 -> 0 | J17: ='2.1meta'!K17+'2.1meta'!K34+'2.1meta'!K51+'2.1meta'!K69+'2.1meta'!K86+'2.1meta'!K103+'2.1meta'!K120+'2.1meta'!K137+'2.1meta'!K154+'2.1meta'!K171+'2.1meta'!K188+'2.1meta'!K298+'2.1meta'!K315+'2.1meta'!K332 -> 0 | ... P17: ='2.1meta'!Q17+'2.1meta'!Q34+'2.1meta'!Q51+'2.1meta'!Q69+'2.1meta'!Q86+'2.1meta'!Q103+'2.1meta'!Q120+'2.1meta'!Q137+'2.1meta'!Q154+'2.1meta'!Q171+'2.1meta'!Q188+'2.1meta'!Q298+'2.1meta'!Q315+'2.1meta'!Q332 -> 0 | Q17: =SUM(F17:P17) -> 0 | R17: =C17-Q17 -> 0 | S17: ='2.1meta'!T17+'2.1meta'!T34+'2.1meta'!T51+'2.1meta'!T69+'2.1meta'!T86+'2.1meta'!T103+'2.1meta'!T120+'2.1meta'!T137+'2.1meta'!T154+'2.1meta'!T171+'2.1meta'!T188+'2.1meta'!T298+'2.1meta'!T315+'2.1meta'!T332 -> 0 | T17: ='2.1meta'!U17+'2.1meta'!U34+'2.1meta'!U51+'2.1meta'!U69+'2.1meta'!U86+'2.1meta'!U103+'2.1meta'!U120+'2.1meta'!U137+'2.1meta'!U154+'2.1meta'!U171+'2.1meta'!U188+'2.1meta'!U298+'2.1meta'!U315+'2.1meta'!U332 -> 0 | U17: ='2.1meta'!V17+'2.1meta'!V34+'2.1meta'!V51+'2.1meta'!V69+'2.1meta'!V86+'2.1meta'!V103+'2.1meta'!V120+'2.1meta'!V137+'2.1meta'!V154+'2.1meta'!V171+'2.1meta'!V188+'2.1meta'!V298+'2.1meta'!V315+'2.1meta'!V332 -> 0 | V17: ='2.1meta'!W17+'2.1meta'!W34+'2.1meta'!W51+'2.1meta'!W69+'2.1meta'!W86+'2.1meta'!W103+'2.1meta'!W120+'2.1meta'!W137+'2.1meta'!W154+'2.1meta'!W171+'2.1meta'!W188+'2.1meta'!W298+'2.1meta'!W315+'2.1meta'!W332 -> 0 | W17: ='2.1meta'!X17+'2.1meta'!X34+'2.1meta'!X51+'2.1meta'!X69+'2.1meta'!X86+'2.1meta'!X103+'2.1meta'!X120+'2.1meta'!X137+'2.1meta'!X154+'2.1meta'!X171+'2.1meta'!X188+'2.1meta'!X298+'2.1meta'!X315+'2.1meta'!X332 -> 0 | X17: =SUM(S17:W17) -> 0 | Y17: =Q17+X17 -> 0 | Z17: =C17-Y17 -> 0
A18: 2.1.1.9.3.3 | B18: COMPENSACION VACACIONAL (VACACIONES TRUNCAS) | C18: ='2.1meta'!D18+'2.1meta'!D35+'2.1meta'!D52+'2.1meta'!D70+'2.1meta'!D87+'2.1meta'!D104+'2.1meta'!D121+'2.1meta'!D138+'2.1meta'!D155+'2.1meta'!D172+'2.1meta'!D189+'2.1meta'!D299+'2.1meta'!D316+'2.1meta'!D333 -> 0 | D18: ='2.1meta'!E18+'2.1meta'!E35+'2.1meta'!E52+'2.1meta'!E70+'2.1meta'!E87+'2.1meta'!E104+'2.1meta'!E121+'2.1meta'!E138+'2.1meta'!E155+'2.1meta'!E172+'2.1meta'!E189+'2.1meta'!E299+'2.1meta'!E316+'2.1meta'!E333 -> 0 | E18: ='2.1meta'!F18+'2.1meta'!F35+'2.1meta'!F52+'2.1meta'!F70+'2.1meta'!F87+'2.1meta'!F104+'2.1meta'!F121+'2.1meta'!F138+'2.1meta'!F155+'2.1meta'!F172+'2.1meta'!F189+'2.1meta'!F299+'2.1meta'!F316+'2.1meta'!F333 -> 0 | F18: ='2.1meta'!G18+'2.1meta'!G35+'2.1meta'!G52+'2.1meta'!G70+'2.1meta'!G87+'2.1meta'!G104+'2.1meta'!G121+'2.1meta'!G138+'2.1meta'!G155+'2.1meta'!G172+'2.1meta'!G189+'2.1meta'!G299+'2.1meta'!G316+'2.1meta'!G333 -> 0 | G18: ='2.1meta'!H18+'2.1meta'!H35+'2.1meta'!H52+'2.1meta'!H70+'2.1meta'!H87+'2.1meta'!H104+'2.1meta'!H121+'2.1meta'!H138+'2.1meta'!H155+'2.1meta'!H172+'2.1meta'!H189+'2.1meta'!H299+'2.1meta'!H316+'2.1meta'!H333 -> 0 | H18: ='2.1meta'!I18+'2.1meta'!I35+'2.1meta'!I52+'2.1meta'!I70+'2.1meta'!I87+'2.1meta'!I104+'2.1meta'!I121+'2.1meta'!I138+'2.1meta'!I155+'2.1meta'!I172+'2.1meta'!I189+'2.1meta'!I299+'2.1meta'!I316+'2.1meta'!I333 -> 0 | I18: ='2.1meta'!J18+'2.1meta'!J35+'2.1meta'!J52+'2.1meta'!J70+'2.1meta'!J87+'2.1meta'!J104+'2.1meta'!J121+'2.1meta'!J138+'2.1meta'!J155+'2.1meta'!J172+'2.1meta'!J189+'2.1meta'!J299+'2.1meta'!J316+'2.1meta'!J333 -> 0 | J18: ='2.1meta'!K18+'2.1meta'!K35+'2.1meta'!K52+'2.1meta'!K70+'2.1meta'!K87+'2.1meta'!K104+'2.1meta'!K121+'2.1meta'!K138+'2.1meta'!K155+'2.1meta'!K172+'2.1meta'!K189+'2.1meta'!K299+'2.1meta'!K316+'2.1meta'!K333 -> 0 | ... P18: ='2.1meta'!Q18+'2.1meta'!Q35+'2.1meta'!Q52+'2.1meta'!Q70+'2.1meta'!Q87+'2.1meta'!Q104+'2.1meta'!Q121+'2.1meta'!Q138+'2.1meta'!Q155+'2.1meta'!Q172+'2.1meta'!Q189+'2.1meta'!Q299+'2.1meta'!Q316+'2.1meta'!Q333 -> 0 | Q18: =SUM(F18:P18) -> 0 | R18: =C18-Q18 -> 0 | S18: ='2.1meta'!T18+'2.1meta'!T35+'2.1meta'!T52+'2.1meta'!T70+'2.1meta'!T87+'2.1meta'!T104+'2.1meta'!T121+'2.1meta'!T138+'2.1meta'!T155+'2.1meta'!T172+'2.1meta'!T189+'2.1meta'!T299+'2.1meta'!T316+'2.1meta'!T333 -> 0 | T18: ='2.1meta'!U18+'2.1meta'!U35+'2.1meta'!U52+'2.1meta'!U70+'2.1meta'!U87+'2.1meta'!U104+'2.1meta'!U121+'2.1meta'!U138+'2.1meta'!U155+'2.1meta'!U172+'2.1meta'!U189+'2.1meta'!U299+'2.1meta'!U316+'2.1meta'!U333 -> 0 | U18: ='2.1meta'!V18+'2.1meta'!V35+'2.1meta'!V52+'2.1meta'!V70+'2.1meta'!V87+'2.1meta'!V104+'2.1meta'!V121+'2.1meta'!V138+'2.1meta'!V155+'2.1meta'!V172+'2.1meta'!V189+'2.1meta'!V299+'2.1meta'!V316+'2.1meta'!V333 -> 0 | V18: ='2.1meta'!W18+'2.1meta'!W35+'2.1meta'!W52+'2.1meta'!W70+'2.1meta'!W87+'2.1meta'!W104+'2.1meta'!W121+'2.1meta'!W138+'2.1meta'!W155+'2.1meta'!W172+'2.1meta'!W189+'2.1meta'!W299+'2.1meta'!W316+'2.1meta'!W333 -> 0 | W18: ='2.1meta'!X18+'2.1meta'!X35+'2.1meta'!X52+'2.1meta'!X70+'2.1meta'!X87+'2.1meta'!X104+'2.1meta'!X121+'2.1meta'!X138+'2.1meta'!X155+'2.1meta'!X172+'2.1meta'!X189+'2.1meta'!X299+'2.1meta'!X316+'2.1meta'!X333 -> 0 | X18: =SUM(S18:W18) -> 0 | Y18: =Q18+X18 -> 0 | Z18: =C18-Y18 -> 0
A19: 2.1.1.9.3.99 | B19: OTRAS OCASIONALES | C19: ='2.1meta'!D19+'2.1meta'!D36+'2.1meta'!D53+'2.1meta'!D71+'2.1meta'!D88+'2.1meta'!D105+'2.1meta'!D122+'2.1meta'!D139+'2.1meta'!D156+'2.1meta'!D173+'2.1meta'!D190+'2.1meta'!D300+'2.1meta'!D317+'2.1meta'!D334 -> 0 | D19: ='2.1meta'!E19+'2.1meta'!E36+'2.1meta'!E53+'2.1meta'!E71+'2.1meta'!E88+'2.1meta'!E105+'2.1meta'!E122+'2.1meta'!E139+'2.1meta'!E156+'2.1meta'!E173+'2.1meta'!E190+'2.1meta'!E300+'2.1meta'!E317+'2.1meta'!E334 -> 0 | E19: ='2.1meta'!F19+'2.1meta'!F36+'2.1meta'!F53+'2.1meta'!F71+'2.1meta'!F88+'2.1meta'!F105+'2.1meta'!F122+'2.1meta'!F139+'2.1meta'!F156+'2.1meta'!F173+'2.1meta'!F190+'2.1meta'!F300+'2.1meta'!F317+'2.1meta'!F334 -> 0 | F19: ='2.1meta'!G19+'2.1meta'!G36+'2.1meta'!G53+'2.1meta'!G71+'2.1meta'!G88+'2.1meta'!G105+'2.1meta'!G122+'2.1meta'!G139+'2.1meta'!G156+'2.1meta'!G173+'2.1meta'!G190+'2.1meta'!G300+'2.1meta'!G317+'2.1meta'!G334 -> 0 | G19: ='2.1meta'!H19+'2.1meta'!H36+'2.1meta'!H53+'2.1meta'!H71+'2.1meta'!H88+'2.1meta'!H105+'2.1meta'!H122+'2.1meta'!H139+'2.1meta'!H156+'2.1meta'!H173+'2.1meta'!H190+'2.1meta'!H300+'2.1meta'!H317+'2.1meta'!H334 -> 0 | H19: ='2.1meta'!I19+'2.1meta'!I36+'2.1meta'!I53+'2.1meta'!I71+'2.1meta'!I88+'2.1meta'!I105+'2.1meta'!I122+'2.1meta'!I139+'2.1meta'!I156+'2.1meta'!I173+'2.1meta'!I190+'2.1meta'!I300+'2.1meta'!I317+'2.1meta'!I334 -> 0 | I19: ='2.1meta'!J19+'2.1meta'!J36+'2.1meta'!J53+'2.1meta'!J71+'2.1meta'!J88+'2.1meta'!J105+'2.1meta'!J122+'2.1meta'!J139+'2.1meta'!J156+'2.1meta'!J173+'2.1meta'!J190+'2.1meta'!J300+'2.1meta'!J317+'2.1meta'!J334 -> 0 | J19: ='2.1meta'!K19+'2.1meta'!K36+'2.1meta'!K53+'2.1meta'!K71+'2.1meta'!K88+'2.1meta'!K105+'2.1meta'!K122+'2.1meta'!K139+'2.1meta'!K156+'2.1meta'!K173+'2.1meta'!K190+'2.1meta'!K300+'2.1meta'!K317+'2.1meta'!K334 -> 0 | ... P19: ='2.1meta'!Q19+'2.1meta'!Q36+'2.1meta'!Q53+'2.1meta'!Q71+'2.1meta'!Q88+'2.1meta'!Q105+'2.1meta'!Q122+'2.1meta'!Q139+'2.1meta'!Q156+'2.1meta'!Q173+'2.1meta'!Q190+'2.1meta'!Q300+'2.1meta'!Q317+'2.1meta'!Q334 -> 0 | Q19: =SUM(F19:P19) -> 0 | R19: =C19-Q19 -> 0 | S19: ='2.1meta'!T19+'2.1meta'!T36+'2.1meta'!T53+'2.1meta'!T71+'2.1meta'!T88+'2.1meta'!T105+'2.1meta'!T122+'2.1meta'!T139+'2.1meta'!T156+'2.1meta'!T173+'2.1meta'!T190+'2.1meta'!T300+'2.1meta'!T317+'2.1meta'!T334 -> 0 | T19: ='2.1meta'!U19+'2.1meta'!U36+'2.1meta'!U53+'2.1meta'!U71+'2.1meta'!U88+'2.1meta'!U105+'2.1meta'!U122+'2.1meta'!U139+'2.1meta'!U156+'2.1meta'!U173+'2.1meta'!U190+'2.1meta'!U300+'2.1meta'!U317+'2.1meta'!U334 -> 0 | U19: ='2.1meta'!V19+'2.1meta'!V36+'2.1meta'!V53+'2.1meta'!V71+'2.1meta'!V88+'2.1meta'!V105+'2.1meta'!V122+'2.1meta'!V139+'2.1meta'!V156+'2.1meta'!V173+'2.1meta'!V190+'2.1meta'!V300+'2.1meta'!V317+'2.1meta'!V334 -> 0 | V19: ='2.1meta'!W19+'2.1meta'!W36+'2.1meta'!W53+'2.1meta'!W71+'2.1meta'!W88+'2.1meta'!W105+'2.1meta'!W122+'2.1meta'!W139+'2.1meta'!W156+'2.1meta'!W173+'2.1meta'!W190+'2.1meta'!W300+'2.1meta'!W317+'2.1meta'!W334 -> 0 | W19: ='2.1meta'!X19+'2.1meta'!X36+'2.1meta'!X53+'2.1meta'!X71+'2.1meta'!X88+'2.1meta'!X105+'2.1meta'!X122+'2.1meta'!X139+'2.1meta'!X156+'2.1meta'!X173+'2.1meta'!X190+'2.1meta'!X300+'2.1meta'!X317+'2.1meta'!X334 -> 0 | X19: =SUM(S19:W19) -> 0 | Y19: =Q19+X19 -> 0 | Z19: =C19-Y19 -> 0
A20: 2.1.3.1.1.1 | B20: APORTES A LOS FONDOS DE SALUD | C20: ='2.1meta'!D20+'2.1meta'!D37+'2.1meta'!D54+'2.1meta'!D72+'2.1meta'!D89+'2.1meta'!D106+'2.1meta'!D123+'2.1meta'!D140+'2.1meta'!D157+'2.1meta'!D174+'2.1meta'!D191+'2.1meta'!D301+'2.1meta'!D318+'2.1meta'!D335 -> 0 | D20: ='2.1meta'!E20+'2.1meta'!E37+'2.1meta'!E54+'2.1meta'!E72+'2.1meta'!E89+'2.1meta'!E106+'2.1meta'!E123+'2.1meta'!E140+'2.1meta'!E157+'2.1meta'!E174+'2.1meta'!E191+'2.1meta'!E301+'2.1meta'!E318+'2.1meta'!E335 -> 0 | E20: ='2.1meta'!F20+'2.1meta'!F37+'2.1meta'!F54+'2.1meta'!F72+'2.1meta'!F89+'2.1meta'!F106+'2.1meta'!F123+'2.1meta'!F140+'2.1meta'!F157+'2.1meta'!F174+'2.1meta'!F191+'2.1meta'!F301+'2.1meta'!F318+'2.1meta'!F335 -> 0 | F20: ='2.1meta'!G20+'2.1meta'!G37+'2.1meta'!G54+'2.1meta'!G72+'2.1meta'!G89+'2.1meta'!G106+'2.1meta'!G123+'2.1meta'!G140+'2.1meta'!G157+'2.1meta'!G174+'2.1meta'!G191+'2.1meta'!G301+'2.1meta'!G318+'2.1meta'!G335 -> 0 | G20: ='2.1meta'!H20+'2.1meta'!H37+'2.1meta'!H54+'2.1meta'!H72+'2.1meta'!H89+'2.1meta'!H106+'2.1meta'!H123+'2.1meta'!H140+'2.1meta'!H157+'2.1meta'!H174+'2.1meta'!H191+'2.1meta'!H301+'2.1meta'!H318+'2.1meta'!H335 -> 0 | H20: ='2.1meta'!I20+'2.1meta'!I37+'2.1meta'!I54+'2.1meta'!I72+'2.1meta'!I89+'2.1meta'!I106+'2.1meta'!I123+'2.1meta'!I140+'2.1meta'!I157+'2.1meta'!I174+'2.1meta'!I191+'2.1meta'!I301+'2.1meta'!I318+'2.1meta'!I335 -> 0 | I20: ='2.1meta'!J20+'2.1meta'!J37+'2.1meta'!J54+'2.1meta'!J72+'2.1meta'!J89+'2.1meta'!J106+'2.1meta'!J123+'2.1meta'!J140+'2.1meta'!J157+'2.1meta'!J174+'2.1meta'!J191+'2.1meta'!J301+'2.1meta'!J318+'2.1meta'!J335 -> 0 | J20: ='2.1meta'!K20+'2.1meta'!K37+'2.1meta'!K54+'2.1meta'!K72+'2.1meta'!K89+'2.1meta'!K106+'2.1meta'!K123+'2.1meta'!K140+'2.1meta'!K157+'2.1meta'!K174+'2.1meta'!K191+'2.1meta'!K301+'2.1meta'!K318+'2.1meta'!K335 -> 0 | ... P20: ='2.1meta'!Q20+'2.1meta'!Q37+'2.1meta'!Q54+'2.1meta'!Q72+'2.1meta'!Q89+'2.1meta'!Q106+'2.1meta'!Q123+'2.1meta'!Q140+'2.1meta'!Q157+'2.1meta'!Q174+'2.1meta'!Q191+'2.1meta'!Q301+'2.1meta'!Q318+'2.1meta'!Q335 -> 0 | Q20: =SUM(F20:P20) -> 0 | R20: =C20-Q20 -> 0 | S20: ='2.1meta'!T20+'2.1meta'!T37+'2.1meta'!T54+'2.1meta'!T72+'2.1meta'!T89+'2.1meta'!T106+'2.1meta'!T123+'2.1meta'!T140+'2.1meta'!T157+'2.1meta'!T174+'2.1meta'!T191+'2.1meta'!T301+'2.1meta'!T318+'2.1meta'!T335 -> 0 | T20: ='2.1meta'!U20+'2.1meta'!U37+'2.1meta'!U54+'2.1meta'!U72+'2.1meta'!U89+'2.1meta'!U106+'2.1meta'!U123+'2.1meta'!U140+'2.1meta'!U157+'2.1meta'!U174+'2.1meta'!U191+'2.1meta'!U301+'2.1meta'!U318+'2.1meta'!U335 -> 0 | U20: ='2.1meta'!V20+'2.1meta'!V37+'2.1meta'!V54+'2.1meta'!V72+'2.1meta'!V89+'2.1meta'!V106+'2.1meta'!V123+'2.1meta'!V140+'2.1meta'!V157+'2.1meta'!V174+'2.1meta'!V191+'2.1meta'!V301+'2.1meta'!V318+'2.1meta'!V335 -> 0 | V20: ='2.1meta'!W20+'2.1meta'!W37+'2.1meta'!W54+'2.1meta'!W72+'2.1meta'!W89+'2.1meta'!W106+'2.1meta'!W123+'2.1meta'!W140+'2.1meta'!W157+'2.1meta'!W174+'2.1meta'!W191+'2.1meta'!W301+'2.1meta'!W318+'2.1meta'!W335 -> 0 | W20: ='2.1meta'!X20+'2.1meta'!X37+'2.1meta'!X54+'2.1meta'!X72+'2.1meta'!X89+'2.1meta'!X106+'2.1meta'!X123+'2.1meta'!X140+'2.1meta'!X157+'2.1meta'!X174+'2.1meta'!X191+'2.1meta'!X301+'2.1meta'!X318+'2.1meta'!X335 -> 0 | X20: =SUM(S20:W20) -> 0 | Y20: =Q20+X20 -> 0 | Z20: =C20-Y20 -> 0
